Workbook

Sheet Resumen
C2: Factores | E2: Proyecto a 5 años Perfil 12 | G2: Proyecto a 5 años Perfil 20 | J2: Deuda | K2: Monto (UF)
C4: Cant. Deptos | E4: 15 | J4: Deuda Actual | K4: 115446
C5: Valor Total Lista Deptos + Est + Bod | E5: ='IVA Dptos'!$F$48 | J5: Deptos MAISA (15) | K5: ='Crédito Comercial 12A'!D4
C6: Valor Financ. Itaú (72%) | E6: ='Crédito Comercial 12A'!$D$3 | J6: Deptos F.Esc/Bco Alzante/Ingreso CBR | K6: 46478
C7: Descuento Inmobiliaria | E7: 0.28 | J7: Saldo | K7: =K4-K5-K6
C8: Cuota de Alzamiento | E8: 8% - Se encuentra en negociación con el stder un crédito paralelo por uf 10.000
C9: Recuperación del IVA | E9: =SUM('Flujo 5 años C12'!F4:F5)
C10: Colocación de los deptos | E10: 1er año, colocación en 6 meses. El resto de los años una vacancia del 10%
C11: Ingreso Total Arriendos | E11: ='Flujo 5 años C12'!N3
C12: Dividendos Totales | E12: ='Flujo 5 años C12'!N13 | G12: ='Flujo 5 años C20'!N13
C13: Prepago de Capital al año 5 | E13: ='Flujo 5 años C12'!J28 | G13: ='Flujo 5 años C20'!J28
C14: Necesidad de nuevo financiamiento | E14: ='Flujo 5 años C12'!N30 | G14: ='Flujo 5 años C20'!N30
C15: Venta al año 5 (90% del Precio de lista actual) | E15: ='Flujo 5 años C12'!J6
C16: Utilidad | E16: ='Flujo 5 años C12'!M38 | G16: ='Flujo 5 años C20'!M38

Sheet IVA Dptos
B1: uf tomada | C1: =39850
B2: iva | C2: 0.18 | H2: VENTA 15 DEPARTAMENTOS (INCLUYE ESTACIONAMIENTOS Y BODEGAS)
B3: Descuento | C3: 0.28
M6: ESTACIONAMIENTO | O6: BODEGA | Q6: UF TOTAL | R6: COMPRADOR
C7: N° | D7: Precio con dcto | E7: IVA (uf) | F7: Construcción | G7: Neto | H7: Avalúo Fiscal | I7: % A. Fiscal | J7: Valor de terreno (uf) | K7: Valor de terreno (pesos) | L7: IVA real | M7: UF | N7: 28% Desc | O7: UF | P7: 28% Desc | Q7: Venta Total con Dcto (D+E+B) | T7: Cuota Alzamiento | V7: Dif. Prrecio con Dcto y Cuota de Alz | X7: Precio Lista Deptos | Y7: Tip | AA7: Roles | AC7: Descuento | AD7: Venta Total Sin descuento
B8: =1 | C8: 702 | D8: =X8-(X8*$C$3) | E8: =(D8/1.18)*0.18 | F8: =E8/0.19 | G8: =(D8/(1+$C$2))*$C$1 | H8: 67066428 | I8: =H8/G8 | J8: =(D8-E8-F8) | K8: =(D8-E8-F8)*$C$1 | L8: =E8*$C$1 | M8: 495 | N8: =+M8-(M8*$C$3) | O8: 91 | P8: =+O8-(O8*$C$3) | Q8: =(D8+N8+P8) | T8: 4546.4 | V8: =+Q8-T8 | X8: 5097 | Y8: 3 | AA8: 04940-00151 | AC8: =+X8*$C$3 | AD8: =X8+M8+O8
B9: =+B8+1 | C9: 803 | D9: =X9-(X9*$C$3) | E9: =(D9/1.18)*0.18 | F9: =E9/0.19 | G9: =(D9/(1+$C$2))*$C$1 | H9: 66118964 | I9: =H9/G9 | J9: =(D9-E9-F9) | K9: =(D9-E9-F9)*$C$1 | L9: =E9*$C$1 | M9: 495 | N9: =+M9-(M9*$C$3) | O9: 91 | P9: =+O9-(O9*$C$3) | Q9: =(D9+N9+P9) | T9: 4572.8 | V9: =+Q9-T9 | X9: 5130 | Y9: 3 | AA9: 04940-00150 | AC9: =+X9*$C$3 | AD9: =X9+M9+O9
B10: =+B9+1 | C10: 903 | D10: =X10-(X10*$C$3) | E10: =(D10/1.18)*0.18 | F10: =E10/0.19 | G10: =(D10/(1+$C$2))*$C$1 | H10: 66118964 | I10: =H10/G10 | J10: =(D10-E10-F10) | K10: =(D10-E10-F10)*$C$1 | L10: =E10*$C$1 | M10: 495 | N10: =+M10-(M10*$C$3) | O10: 91 | P10: =+O10-(O10*$C$3) | Q10: =(D10+N10+P10) | T10: 4733.6 | V10: =+Q10-T10 | X10: 5331 | Y10: 3 | AA10: 04940-00155 | AC10: =+X10*$C$3 | AD10: =X10+M10+O10
B11: =+B10+1 | C11: 1002 | D11: =X11-(X11*$C$3) | E11: =(D11/1.18)*0.18 | F11: =E11/0.19 | G11: =(D11/(1+$C$2))*$C$1 | H11: 67066428 | I11: =H11/G11 | J11: =(D11-E11-F11) | K11: =(D11-E11-F11)*$C$1 | L11: =E11*$C$1 | M11: 495 | N11: =+M11-(M11*$C$3) | O11: 91 | P11: =+O11-(O11*$C$3) | Q11: =(D11+N11+P11) | T11: 4641.6 | V11: =+Q11-T11 | X11: 5216 | Y11: 3 | AA11: 04940-00160 | AC11: =+X11*$C$3 | AD11: =X11+M11+O11
B12: =+B11+1 | C12: 1003 | D12: =X12-(X12*$C$3) | E12: =(D12/1.18)*0.18 | F12: =E12/0.19 | G12: =(D12/(1+$C$2))*$C$1 | H12: 66118964 | I12: =H12/G12 | J12: =(D12-E12-F12) | K12: =(D12-E12-F12)*$C$1 | L12: =E12*$C$1 | M12: 495 | N12: =+M12-(M12*$C$3) | O12: 91 | P12: =+O12-(O12*$C$3) | Q12: =(D12+N12+P12) | T12: 4637.6 | V12: =+Q12-T12 | X12: 5211 | Y12: 3 | AA12: 04940-00164 | AC12: =+X12*$C$3 | AD12: =X12+M12+O12
B13: =+B12+1 | C13: 1301 | D13: =X13-(X13*$C$3) | E13: =(D13/1.18)*0.18 | F13: =E13/0.19 | G13: =(D13/(1+$C$2))*$C$1 | H13: 42776326 | I13: =H13/G13 | J13: =(D13-E13-F13) | K13: =(D13-E13-F13)*$C$1 | L13: =E13*$C$1 | M13: 495 | N13: =+M13-(M13*$C$3) | O13: 91 | P13: =+O13-(O13*$C$3) | Q13: =(D13+N13+P13) | T13: 3912.8 | V13: =+Q13-T13 | X13: 4305 | Y13: 2 | AA13: 04940-00159 | AC13: =+X13*$C$3 | AD13: =X13+M13+O13
B14: =+B13+1 | C14: 1302 | D14: =X14-(X14*$C$3) | E14: =(D14/1.18)*0.18 | F14: =E14/0.19 | G14: =(D14/(1+$C$2))*$C$1 | H14: 67066428 | I14: =H14/G14 | J14: =(D14-E14-F14) | K14: =(D14-E14-F14)*$C$1 | L14: =E14*$C$1 | M14: 495 | N14: =+M14-(M14*$C$3) | O14: 91 | P14: =+O14-(O14*$C$3) | Q14: =(D14+N14+P14) | T14: 4694.4 | V14: =+Q14-T14 | X14: 5282 | Y14: 3 | AA14: 04940-00173 | AC14: =+X14*$C$3 | AD14: =X14+M14+O14
B15: =+B14+1 | C15: 1303 | D15: =X15-(X15*$C$3) | E15: =(D15/1.18)*0.18 | F15: =E15/0.19 | G15: =(D15/(1+$C$2))*$C$1 | H15: 66118964 | I15: =H15/G15 | J15: =(D15-E15-F15) | K15: =(D15-E15-F15)*$C$1 | L15: =E15*$C$1 | M15: 495 | N15: =+M15-(M15*$C$3) | O15: 91 | P15: =+O15-(O15*$C$3) | Q15: =(D15+N15+P15) | T15: 4612 | V15: =+Q15-T15 | X15: 5179 | Y15: 3 | AA15: 04940-00177 | AC15: =+X15*$C$3 | AD15: =X15+M15+O15
B16: =+B15+1 | C16: 1304 | D16: =X16-(X16*$C$3) | E16: =(D16/1.18)*0.18 | F16: =E16/0.19 | G16: =(D16/(1+$C$2))*$C$1 | H16: 49427883 | I16: =H16/G16 | J16: =(D16-E16-F16) | K16: =(D16-E16-F16)*$C$1 | L16: =E16*$C$1 | M16: 495 | N16: =+M16-(M16*$C$3) | O16: 91 | P16: =+O16-(O16*$C$3) | Q16: =(D16+N16+P16) | T16: 3937.6 | V16: =+Q16-T16 | X16: 4336 | Y16: 2 | AA16: 04940-00132 | AC16: =+X16*$C$3 | AD16: =X16+M16+O16
B17: =+B16+1 | C17: 1309 | D17: =X17-(X17*$C$3) | E17: =(D17/1.18)*0.18 | F17: =E17/0.19 | G17: =(D17/(1+$C$2))*$C$1 | H17: 45765170 | I17: =H17/G17 | J17: =(D17-E17-F17) | K17: =(D17-E17-F17)*$C$1 | L17: =E17*$C$1 | M17: 495 | N17: =+M17-(M17*$C$3) | O17: 91 | P17: =+O17-(O17*$C$3) | Q17: =(D17+N17+P17) | T17: 3974.4 | V17: =+Q17-T17 | X17: 4382 | Y17: 2 | AC17: =+X17*$C$3 | AD17: =X17+M17+O17
B18: =+B17+1 | C18: 1007 | D18: =X18-(X18*$C$3) | E18: =(D18/1.18)*0.18 | F18: =E18/0.19 | G18: =(D18/(1+$C$2))*$C$1 | H18: 67066428 | I18: =H18/G18 | J18: =(D18-E18-F18) | K18: =(D18-E18-F18)*$C$1 | L18: =E18*$C$1 | M18: 495 | N18: =+M18-(M18*$C$3) | O18: 91 | P18: =+O18-(O18*$C$3) | Q18: =(D18+N18+P18) | T18: 4763.2 | V18: =+Q18-T18 | X18: 5368 | Y18: 3 | AC18: =+X18*$C$3 | AD18: =X18+M18+O18
B19: =+B18+1 | C19: 1104 | D19: =X19-(X19*$C$3) | E19: =(D19/1.18)*0.18 | F19: =E19/0.19 | G19: =(D19/(1+$C$2))*$C$1 | H19: 49427883 | I19: =H19/G19 | J19: =(D19-E19-F19) | K19: =(D19-E19-F19)*$C$1 | L19: =E19*$C$1 | M19: 495 | N19: =+M19-(M19*$C$3) | O19: 91 | P19: =+O19-(O19*$C$3) | Q19: =(D19+N19+P19) | T19: 3999.2 | V19: =+Q19-T19 | X19: 4413 | Y19: 2 | AC19: =+X19*$C$3 | AD19: =X19+M19+O19
B20: =+B19+1 | C20: 1107 | D20: =X20-(X20*$C$3) | E20: =(D20/1.18)*0.18 | F20: =E20/0.19 | G20: =(D20/(1+$C$2))*$C$1 | H20: 67066428 | I20: =H20/G20 | J20: =(D20-E20-F20) | K20: =(D20-E20-F20)*$C$1 | L20: =E20*$C$1 | M20: 495 | N20: =+M20-(M20*$C$3) | O20: 91 | P20: =+O20-(O20*$C$3) | Q20: =(D20+N20+P20) | T20: 4671.2 | V20: =+Q20-T20 | X20: 5253 | Y20: 3 | AC20: =+X20*$C$3 | AD20: =X20+M20+O20
B21: =+B20+1 | C21: 1204 | D21: =X21-(X21*$C$3) | E21: =(D21/1.18)*0.18 | F21: =E21/0.19 | G21: =(D21/(1+$C$2))*$C$1 | H21: 49427883 | I21: =H21/G21 | J21: =(D21-E21-F21) | K21: =(D21-E21-F21)*$C$1 | L21: =E21*$C$1 | M21: 495 | N21: =+M21-(M21*$C$3) | O21: 91 | P21: =+O21-(O21*$C$3) | Q21: =(D21+N21+P21) | T21: 4078.4 | V21: =+Q21-T21 | X21: 4512 | Y21: 2 | AC21: =+X21*$C$3 | AD21: =X21+M21+O21
B22: =+B21+1 | C22: 1207 | D22: =X22-(X22*$C$3) | E22: =(D22/1.18)*0.18 | F22: =E22/0.19 | G22: =(D22/(1+$C$2))*$C$1 | H22: 67066428 | I22: =H22/G22 | J22: =(D22-E22-F22) | K22: =(D22-E22-F22)*$C$1 | L22: =E22*$C$1 | M22: 495 | N22: =+M22-(M22*$C$3) | O22: 91 | P22: =+O22-(O22*$C$3) | Q22: =(D22+N22+P22) | T22: 4675.2 | V22: =+Q22-T22 | X22: 5258 | Y22: 3 | AA22: 04940-00168 | AC22: =+X22*$C$3 | AD22: =X22+M22+O22
D23: =SUM(D8:D22) | E23: =(D23/1.18)*0.18 | F23: =SUM(F8:F22) | G23: =SUM(G8:G22) | H23: =SUM(H8:H22) | L23: =SUM(L8:L22) | M23: =SUM(M8:M22) | N23: =SUM(N8:N22) | O23: =SUM(O8:O22) | P23: =SUM(P8:P22) | Q23: =SUM(Q8:Q22) | T23: =SUM(T8:T22) | V23: =+Q23-T23 | X23: =SUM(X8:X22) | AC23: =SUM(AC8:AC22) | AD23: =SUM(AD8:AD22)
L24: =L23/C1 | N24: =+M23-N23 | P24: =+O23-P23
C31: N° | D31: Precio Lista Deptos | E31: Est. UF | F31: Bod UF | H31: Precio 28% dcto | I31: 28% Desc | J31: 28% Desc
C32: 702 | D32: 5097 | E32: 495 | F32: 91 | H32: 3669.84 | I32: 356.4 | J32: 65.52
C33: 803 | D33: 5130 | E33: 495 | F33: 91 | H33: 3693.6 | I33: 356.4 | J33: 65.52
C34: 903 | D34: 5331 | E34: 495 | F34: 91 | H34: 3838.32 | I34: 356.4 | J34: 65.52
C35: 1002 | D35: 5216 | E35: 495 | F35: 91 | H35: 3755.52 | I35: 356.4 | J35: 65.52
C36: 1003 | D36: 5211 | E36: 495 | F36: 91 | H36: 3751.92 | I36: 356.4 | J36: 65.52
C37: 1301 | D37: 4305 | E37: 495 | F37: 91 | H37: 3099.6 | I37: 356.4 | J37: 65.52
C38: 1302 | D38: 5282 | E38: 495 | F38: 91 | H38: 3803.04 | I38: 356.4 | J38: 65.52
C39: 1303 | D39: 5179 | E39: 495 | F39: 91 | H39: 3728.88 | I39: 356.4 | J39: 65.52
C40: 1304 | D40: 4336 | E40: 495 | F40: 91 | H40: 3121.92 | I40: 356.4 | J40: 65.52
C41: 1309 | D41: 4382 | E41: 495 | F41: 91 | H41: 3155.04 | I41: 356.4 | J41: 65.52
C42: 1007 | D42: 5368 | E42: 495 | F42: 91 | H42: 3756.96 | I42: 356.4 | J42: 65.52
C43: 1104 | D43: 4413 | E43: 495 | F43: 91 | H43: 3177.36 | I43: 356.4 | J43: 65.52
... C46: 1207 | D46: 5258 | E46: 495 | F46: 91 | H46: 3785.76 | I46: 356.4 | J46: 65.52
D47: =SUM(D32:D46) | E47: =SUM(E32:E46) | F47: =SUM(F32:F46) | H47: =SUM(H32:H46) | I47: =SUM(I32:I46) | J47: =SUM(J32:J46)
F48: =SUM(D47:F47) | J48: =SUM(H47:J47) | L48: =J48/F48
F52: =F48*0.08

Sheet Hoja1
B2: Unidad | D2: Cuota Alzamiento DEPTO | E2: C.EST | F2: C.BOD | G2: DEPTO+E+B | H2: ='IVA Dptos'!Q7 | I2: dif | J2: C.A.DENNIS | M2: Unidad | N2: Cuota Alzamiento
A3: 702 | B3: 702 | C3: =CONCATENATE(B3) | D3: 4312 | E3: ='IVA Dptos'!M8*0.8 | F3: ='IVA Dptos'!O8*0.8 | G3: =D3+E3+F3 | H3: 4091.76 | I3: =H3-G3 | J3: 4546.4 | K3: =J3-E3-F3 | M3: 702 | N3: 3670 | O3: =VLOOKUP(M3,$B$3:$K$17,10,0) | P3: =O3-N3
A4: 803 | B4: 803 | C4: =CONCATENATE(B4) | D4: 4349 | E4: ='IVA Dptos'!M9*0.8 | F4: ='IVA Dptos'!O9*0.8 | G4: =D4+E4+F4 | H4: 4115.52 | I4: =H4-G4 | J4: 4572.8 | K4: =J4-E4-F4 | M4: 803 | N4: 3694 | O4: =VLOOKUP(M4,$B$3:$K$17,10,0) | P4: =O4-N4
A5: 903 | B5: 903 | C5: =CONCATENATE(B5) | D5: 4531 | E5: ='IVA Dptos'!M10*0.8 | F5: ='IVA Dptos'!O10*0.8 | G5: =D5+E5+F5 | H5: 4260.24 | I5: =H5-G5 | J5: 4733.6 | K5: =J5-E5-F5 | M5: 903 | N5: 3838 | O5: =VLOOKUP(M5,$B$3:$K$17,10,0) | P5: =O5-N5
A6: 1002 | B6: 1002 | C6: =CONCATENATE(B6) | D6: 4561 | E6: ='IVA Dptos'!M11*0.8 | F6: ='IVA Dptos'!O11*0.8 | G6: =D6+E6+F6 | H6: 4177.44 | I6: =H6-G6 | J6: 4641.6 | K6: =J6-E6-F6 | M6: 1002 | N6: 3756 | O6: =VLOOKUP(M6,$B$3:$K$17,10,0) | P6: =O6-N6
A7: 1003 | B7: 1003 | C7: =CONCATENATE(B7) | D7: 4557 | E7: ='IVA Dptos'!M12*0.8 | F7: ='IVA Dptos'!O12*0.8 | G7: =D7+E7+F7 | H7: 4173.84 | I7: =H7-G7 | J7: 4637.6 | K7: =J7-E7-F7 | M7: 1003 | N7: 3752 | O7: =VLOOKUP(M7,$B$3:$K$17,10,0) | P7: =O7-N7
A8: 1007 | B8: 1007 | C8: =CONCATENATE(B8) | D8: 4563 | E8: ='IVA Dptos'!M13*0.8 | F8: ='IVA Dptos'!O13*0.8 | G8: =D8+E8+F8 | H8: 4286.88 | I8: =H8-G8 | J8: 3912.8 | K8: =J8-E8-F8 | M8: 1007 | N8: 4831 | O8: =VLOOKUP(M8,$B$3:$K$17,10,0) | P8: =O8-N8
A9: 1104 | B9: 1104 | C9: =CONCATENATE(B9) | D9: 2705 | E9: ='IVA Dptos'!M14*0.8 | F9: ='IVA Dptos'!O14*0.8 | G9: =D9+E9+F9 | H9: 3599.28 | I9: =H9-G9 | J9: 4694.4 | K9: =J9-E9-F9 | M9: 1104 | N9: 3177 | O9: =VLOOKUP(M9,$B$3:$K$17,10,0) | P9: =O9-N9
A10: 1107 | B10: 1107 | C10: =CONCATENATE(B10) | D10: 4450 | E10: ='IVA Dptos'!M15*0.8 | F10: ='IVA Dptos'!O15*0.8 | G10: =D10+E10+F10 | H10: 4204.08 | I10: =H10-G10 | J10: 4612 | K10: =J10-E10-F10 | M10: 1107 | N10: 3782 | O10: =VLOOKUP(M10,$B$3:$K$17,10,0) | P10: =O10-N10
A11: 1204 | B11: 1204 | C11: =CONCATENATE(B11) | D11: 3708 | E11: ='IVA Dptos'!M16*0.8 | F11: ='IVA Dptos'!O16*0.8 | G11: =D11+E11+F11 | H11: 3670.56 | I11: =H11-G11 | J11: 3937.6 | K11: =J11-E11-F11 | M11: 1204 | N11: 3249 | O11: =VLOOKUP(M11,$B$3:$K$17,10,0) | P11: =O11-N11
A12: 1207 | B12: 1207 | C12: =CONCATENATE(B12) | D12: 4597 | E12: ='IVA Dptos'!M17*0.8 | F12: ='IVA Dptos'!O17*0.8 | G12: =D12+E12+F12 | H12: 4207.68 | I12: =H12-G12 | J12: 3974.4 | K12: =J12-E12-F12 | M12: 1207 | N12: 3786 | O12: =VLOOKUP(M12,$B$3:$K$17,10,0) | P12: =O12-N12
A13: 1301 | B13: 1301 | C13: =CONCATENATE(B13) | D13: 3506 | E13: ='IVA Dptos'!M18*0.8 | F13: ='IVA Dptos'!O18*0.8 | G13: =D13+E13+F13 | H13: 3521.52 | I13: =H13-G13 | J13: 4763.2 | K13: =J13-E13-F13 | M13: 1301 | N13: 3100 | O13: =VLOOKUP(M13,$B$3:$K$17,10,0) | P13: =O13-N13
A14: 1302 | B14: 1302 | C14: =CONCATENATE(B14) | D14: 4617 | E14: ='IVA Dptos'!M19*0.8 | F14: ='IVA Dptos'!O19*0.8 | G14: =D14+E14+F14 | H14: 4224.96 | I14: =H14-G14 | J14: 3999.2 | K14: =J14-E14-F14 | M14: 1302 | N14: 3803 | O14: =VLOOKUP(M14,$B$3:$K$17,10,0) | P14: =O14-N14
... A17: 1309 | B17: 1309 | C17: =CONCATENATE(B17) | D17: 3690 | E17: ='IVA Dptos'!M22*0.8 | F17: ='IVA Dptos'!O22*0.8 | G17: =D17+E17+F17 | H17: 3576.96 | I17: =H17-G17 | J17: 4675.2 | K17: =J17-E17-F17 | M17: 1309 | N17: 3155 | O17: =VLOOKUP(M17,$B$3:$K$17,10,0) | P17: =O17-N17
D18: =SUM(D3:D17) | E18: =SUM(E3:E17) | F18: =SUM(F3:F17) | G18: =SUM(G3:G17) | I18: =SUM(I3:I17)

Sheet Arriendo
A1: Valor UF | B1: ='IVA Dptos'!C1 | N1: Valor UF | O1: ='IVA Dptos'!C1
B2: 0.11
D3: Depto | E3: Valor Arriendo | F3: Valor Arriendo | G3: Avalúo fiscal | H3: 11% A.F (año) | I3: 11% A.F (mes) | J3: Arriendo-(11% A.F (mes)) | K3: IVA arriendo | L3: Ingresos arriendo (mes) | N3: TIPOLOGIA | O3: N° | Q3: Arriendo GGCC Incluido | R3: Arriendo U | S3: Total | T3: total uf
C4: =1 | D4: 702 | E4: 715206.36 | F4: =E4/$B$1 | G4: ='IVA Dptos'!H8/$B$1 | H4: =G4*$B$2 | I4: =H4/12 | J4: =F4-I4 | K4: =J4*19% | L4: =F4-K4 | N4: 3 | O4: 15 | Q4: =E4 | R4: =Q4/$O$1 | S4: =Q4*$O$4 | T4: =S4/$O$1
C5: =+C4+1 | D5: 803 | E5: 712738.9 | F5: =E5/$B$1 | G5: ='IVA Dptos'!H9/$B$1 | H5: =G5*$B$2 | I5: =H5/12 | J5: =F5-I5 | K5: =J5*19% | L5: =F5-K5 | N5: 3
C6: =+C5+1 | D6: 903 | E6: 712245.41 | F6: =E6/$B$1 | G6: ='IVA Dptos'!H10/$B$1 | H6: =G6*$B$2 | I6: =H6/12 | J6: =F6-I6 | K6: =J6*19% | L6: =F6-K6 | N6: 3 | Q6: Amoblado | R6: Amoblado U | S6: Total | T6: total uf
C7: =+C6+1 | D7: 1002 | E7: 715370.85 | F7: =E7/$B$1 | G7: ='IVA Dptos'!H11/$B$1 | H7: =G7*$B$2 | I7: =H7/12 | J7: =F7-I7 | K7: =J7*19% | L7: =F7-K7 | N7: 3 | Q7: 2500000 | R7: =Q7/$O$1 | S7: =Q7*$O$4 | T7: =S7/$O$1
C8: =+C7+1 | D8: 1003 | E8: 712245.41 | F8: =E8/$B$1 | G8: ='IVA Dptos'!H12/$B$1 | H8: =G8*$B$2 | I8: =H8/12 | J8: =F8-I8 | K8: =J8*19% | L8: =F8-K8 | N8: 3
C9: =+C8+1 | D9: 1301 | E9: 532954.58 | F9: =E9/$B$1 | G9: ='IVA Dptos'!H13/$B$1 | H9: =G9*$B$2 | I9: =H9/12 | J9: =F9-I9 | K9: =J9*19% | L9: =F9-K9 | N9: 2 | Q9: Contribuciones | R9: Contribuciones U | S9: Total | T9: total uf
C10: =+C9+1 | D10: 1302 | E10: 715535.35 | F10: =E10/$B$1 | G10: ='IVA Dptos'!H14/$B$1 | H10: =G10*$B$2 | I10: =H10/12 | J10: =F10-I10 | K10: =J10*19% | L10: =F10-K10 | N10: 3 | Q10: 20000 | R10: =Q10/$O$1 | S10: =Q10*$O$4 | T10: =S10/$O$1
C11: =+C10+1 | D11: 1303 | E11: 712738.9 | F11: =E11/$B$1 | G11: ='IVA Dptos'!H15/$B$1 | H11: =G11*$B$2 | I11: =H11/12 | J11: =F11-I11 | K11: =J11*19% | L11: =F11-K11 | N11: 3
C12: =+C11+1 | D12: 1304 | E12: 618023.18 | F12: =E12/$B$1 | G12: ='IVA Dptos'!H16/$B$1 | H12: =G12*$B$2 | I12: =H12/12 | J12: =F12-I12 | K12: =J12*19% | L12: =F12-K12 | N12: 2 | Q12: Dividendo | R12: Dividendo total | S12: Total | T12: total uf
C13: =+C12+1 | D13: 1309 | E13: 608050.56 | F13: =E13/$B$1 | G13: ='IVA Dptos'!H17/$B$1 | H13: =G13*$B$2 | I13: =H13/12 | J13: =F13-I13 | K13: =J13*19% | L13: =F13-K13 | N13: 2 | Q13: =R13*O1 | R13: =-'Crédito Comercial 12A'!H8 | S13: =Q13 | T13: =S13/$O$1
C14: =+C13+1 | D14: 1007 | E14: 715535.68 | F14: =E14/$B$1 | G14: ='IVA Dptos'!H18/$B$1 | H14: =G14*$B$2 | I14: =H14/12 | J14: =F14-I14 | K14: =J14*19% | L14: =F14-K14 | N14: 3
C15: =+C14+1 | D15: 1104 | E15: 617694.18 | F15: =E15/$B$1 | G15: ='IVA Dptos'!H19/$B$1 | H15: =G15*$B$2 | I15: =H15/12 | J15: =F15-I15 | K15: =J15*19% | L15: =F15-K15 | N15: 2 | Q15: Gasto Operacional | R15: gasto operc UF | S15: Total | T15: total uf
C16: =+C15+1 | D16: 1107 | E16: 717303.69 | F16: =E16/$B$1 | G16: ='IVA Dptos'!H20/$B$1 | H16: =G16*$B$2 | I16: =H16/12 | J16: =F16-I16 | K16: =J16*19% | L16: =F16-K16 | N16: 3 | Q16: =500000 | R16: =Q16/$O$1 | S16: =Q16*$O$4 | T16: =S16/$O$1
C17: =+C16+1 | D17: 1204 | E17: 616871.7 | F17: =E17/$B$1 | G17: ='IVA Dptos'!H21/$B$1 | H17: =G17*$B$2 | I17: =H17/12 | J17: =F17-I17 | K17: =J17*19% | L17: =F17-K17 | N17: 2
C18: =+C17+1 | D18: 1207 | E18: 715042.19 | F18: =E18/$B$1 | G18: ='IVA Dptos'!H22/$B$1 | H18: =G18*$B$2 | I18: =H18/12 | J18: =F18-I18 | K18: =J18*19% | L18: =F18-K18 | N18: 3 | Q18: Comisión Corredor | R18: Comisión Corredor | S18: Total | T18: total uf
E19: =AVERAGE(E4:E18) | F19: =SUM(F4:F18) | K19: =SUM(K4:K18) | L19: =F19-K19 | O19: =50% | Q19: =Q4*O19 | R19: =Q19/$O$1 | S19: =Q19*$O$4 | T19: =S19/$O$1
F20: =+F19*B1
Q21: Gasto común | R21: ggcc UF | S21: Total | T21: total uf
O22: VER | Q22: 218000 | R22: =Q22/$O$1 | S22: =Q22*$O$4 | T22: =S22/$O$1
Q24: Marketing (Agencia) | R24: Marketing | S24: Total | T24: total uf
Q25: 0 | R25: =Q25/$O$1 | S25: =Q25*$O$4 | T25: =S25/$O$1
Q27: Imprevistos | R27: Imprevistos U | S27: Total | T27: total uf
Q28: 20000 | R28: =Q28/$O$1 | S28: =Q28*$O$4 | T28: =S28/$O$1
Q30: Administración | R30: Admin | S30: Total | T30: total uf
O31: 0.07 | Q31: =Q4*O31 | R31: =Q31/$O$1 | S31: =Q31*$O$4 | T31: =S31/$O$1

Sheet Flujo mensual
E2: 2 | F2: 2 | G2: 2 | H2: 2 | I2: 2
B3: Ingresos | C3: Mes 0 | D3: Mes 1 | E3: Mes 2 | F3: Mes 3 | G3: Mes 4 | H3: Mes 5 | I3: Mes 6 | J3: Mes 7 | K3: Mes 8 | L3: Mes 9 | M3: Mes 10 | N3: Mes 11 | O3: Mes 12 | P3: Total
B4: Arriendos | E4: =SUM(Arriendo!F4:F5) | F4: =SUM(Arriendo!F4:F7) | G4: =SUM(Arriendo!F4:F9) | H4: =SUM(Arriendo!F4:F11) | I4: =SUM(Arriendo!F4:F15) | J4: =SUM(Arriendo!F4:F18) | K4: =J4 | L4: =K4 | M4: =L4 | N4: =M4 | O4: =N4 | P4: =SUM(C4:O4)
B5: C. Fiscal Equip. | G5: =C11*0.19 | P5: =SUM(C5:O5)
B6: C. Fiscal Unidades | G6: ='IVA Dptos'!E23 | P6: =SUM(C6:O6)
B7: Total Ingresos | C7: =SUM(C4:C6) | D7: =SUM(D4:D6) | E7: =SUM(E4:E6) | F7: =SUM(F4:F6) | G7: =SUM(G4:G6) | H7: =SUM(H4:H6) | I7: =SUM(I4:I6) | J7: =SUM(J4:J6) | ... P7: =SUM(P4:P6)
B10: Egresos | C10: Mes 0 | D10: Mes 1 | E10: Mes 2 | F10: Mes 3 | G10: Mes 4 | H10: Mes 5 | I10: Mes 6 | J10: Mes 7 | K10: Mes 8 | L10: Mes 9 | M10: Mes 10 | N10: Mes 11 | O10: Mes 12 | P10: Total
B11: Amoblado | C11: =Arriendo!T7 | P11: =SUM(C11:O11)
B12: Contribuciones | G12: =Arriendo!$T$10 | I12: =Arriendo!$T$10 | L12: =Arriendo!$T$10 | N12: =Arriendo!$T$10 | P12: =SUM(C12:O12)
B13: Dividendo | D13: =-'Crédito Comercial 12A'!$H$8 | E13: =-'Crédito Comercial 12A'!$H$8 | F13: =-'Crédito Comercial 12A'!$H$8 | G13: =-'Crédito Comercial 12A'!$H$8 | H13: =-'Crédito Comercial 12A'!$H$8 | I13: =-'Crédito Comercial 12A'!$H$8 | J13: =-'Crédito Comercial 12A'!$H$8 | K13: =-'Crédito Comercial 12A'!$H$8 | ... O13: =-'Crédito Comercial 12A'!$H$8 | P13: =SUM(C13:O13) | Q13: =+P13-P4
B14: Gasto operacional | C14: =Arriendo!T16 | P14: =SUM(C14:O14)
B15: Comisión corredor | E15: =Arriendo!$R$19*2 | F15: =Arriendo!$R$19*2 | G15: =Arriendo!$R$19*2 | H15: =Arriendo!$R$19*2 | I15: =Arriendo!$R$19*4 | J15: =Arriendo!$R$19*3 | P15: =SUM(C15:O15)
B16: Gasto común | D16: =Arriendo!$T$22 | E16: =Arriendo!$R$22*13 | F16: =Arriendo!$R$22*11 | G16: =Arriendo!$R$22*9 | H16: =Arriendo!$R$22*7 | I16: =Arriendo!$R$22*3 | J16: 0 | K16: 0 | L16: 0 | M16: 0 | N16: 0 | O16: 0 | P16: =SUM(C16:O16)
B17: Administración | D17: 0 | E17: =Arriendo!$R$31*2 | F17: =Arriendo!$R$31*4 | G17: =Arriendo!$R$31*6 | H17: =Arriendo!$R$31*8 | I17: =Arriendo!$R$31*12 | J17: =Arriendo!$R$31*15 | K17: =J17 | L17: =K17 | M17: =L17 | N17: =M17 | O17: =N17 | P17: =SUM(C17:O17)
B18: Marketing | D18: 0 | E18: 0 | F18: 0 | G18: 0 | H18: 0 | I18: 0 | J18: 0 | K18: 0 | L18: 0 | M18: 0 | N18: 0 | O18: 0 | P18: =SUM(C18:O18)
B19: Imprevistos | D19: =Arriendo!$T$28 | E19: =Arriendo!$T$28 | F19: =Arriendo!$T$28 | G19: =Arriendo!$T$28 | H19: =Arriendo!$T$28 | I19: =Arriendo!$T$28 | J19: =Arriendo!$T$28 | K19: =Arriendo!$T$28 | ... O19: =Arriendo!$T$28 | P19: =SUM(C19:O19)
B20: IVA | E20: =SUM(Arriendo!K4:K5) | F20: =SUM(Arriendo!K4:K7) | G20: =SUM(Arriendo!K4:K9) | H20: =SUM(Arriendo!$K$4:$K$11) | I20: =SUM(Arriendo!$K$4:$K$15) | J20: =SUM(Arriendo!$K$4:$K$18) | K20: =+J20 | L20: =+K20 | M20: =+L20 | N20: =+M20 | O20: =+N20 | P20: =SUM(C20:O20)
B21: Total Egresos | C21: =SUM(C11:C20) | D21: =SUM(D11:D20) | E21: =SUM(E11:E20) | F21: =SUM(F11:F20) | G21: =SUM(G11:G20) | H21: =SUM(H11:H20) | I21: =SUM(I11:I20) | J21: =SUM(J11:J20) | ... P21: =SUM(P11:P20)
B23: Flujo | C23: =C7-C21 | D23: =D7-D21 | E23: =E7-E21 | F23: =F7-F21 | G23: =G7-G21 | H23: =H7-H21 | I23: =I7-I21 | J23: =J7-J21 | ... O23: =O7-O21 | P23: =SUM(C23:O23)
B24: Flujo acumulado | C24: =C23 | D24: =C24+D23 | E24: =D24+E23 | F24: =E24+F23 | G24: =F24+G23 | H24: =G24+H23 | I24: =H24+I23 | J24: =I24+J23 | K24: =J24+K23 | ... O24: =N24+O23
E28: 6 | F28: 9 | G28: 13 | H28: 20
E29: 7 | F29: 10 | G29: 15 | H29: 23
E30: 8 | F30: 11 | G30: 17 | H30: 4
E31: 12 | F31: 14 | G31: 18 | H31: 5
E32: 21 | F32: 22 | G32: 19 | H32: 15

Sheet Flujo 5 años C12
D2: Ingresos | E2: Año 0 | F2: Año 1 | G2: Año 2 | H2: Año 3 | I2: Año 4 | J2: Año 5 | K2: Año 6 | L2: Dev. Prest | M2: Dividendo | N2: Total
D3: Arriendos | F3: ='Flujo mensual'!P4 | G3: ='Flujo mensual'!$O$4*12*0.9 | H3: ='Flujo mensual'!$O$4*12*0.9 | I3: ='Flujo mensual'!$O$4*12*0.9 | J3: ='Flujo mensual'!$O$4*12*0.9 | N3: =SUM(F3:M3)
D4: C. Fiscal Equip. | F4: ='Flujo mensual'!G5 | G4: 0 | H4: 0 | I4: 0 | J4: 0 | N4: =SUM(F4:M4)
D5: C. Fiscal Unidades | F5: ='Flujo mensual'!G6 | G5: 0 | H5: 0 | I5: 0 | J5: 0 | N5: =SUM(F5:M5)
D6: Venta propiedades | F6: 0 | G6: 0 | H6: 0 | I6: 0 | J6: ='IVA Dptos'!AD23*0.9 | N6: =SUM(F6:M6)
D7: Total Ingresos | E7: =SUM(E3:E6) | F7: =SUM(F3:F6) | G7: =SUM(G3:G6) | H7: =SUM(H3:H6) | I7: =SUM(I3:I6) | J7: =SUM(J3:J6) | K7: =SUM(K3:K6) | L7: =SUM(L3:L6) | ... N7: =SUM(N3:N6)
D9: Egresos | E9: Año 0 | F9: Año 1 | G9: Año 2 | H9: Año 3 | I9: Año 4 | J9: Año 5 | K9: Año 6 | N9: Total
D10: Amoblado | E10: ='Flujo mensual'!C11 | F10: 0 | G10: 0 | H10: 0 | I10: 0 | J10: 0 | N10: =SUM(E10:M10)
D11: Contribuciones | F11: ='Flujo mensual'!$P$12 | G11: ='Flujo mensual'!$P$12 | H11: ='Flujo mensual'!$P$12 | I11: ='Flujo mensual'!$P$12 | J11: ='Flujo mensual'!$P$12 | N11: =SUM(E11:M11)
D12: Cuota de alzaminto | E12: ='Crédito Comercial 12A'!D10 | N12: =SUM(E12:M12)
D13: Dividendo | F13: ='Flujo mensual'!$P$13 | G13: ='Flujo mensual'!$P$13 | H13: ='Flujo mensual'!$P$13 | I13: ='Flujo mensual'!$P$13 | J13: ='Flujo mensual'!$P$13 | N13: =SUM(E13:M13)
D14: Gasto operacional | E14: ='Flujo mensual'!P14 | F14: 0 | G14: 0 | H14: 0 | I14: 0 | J14: 0 | N14: =SUM(E14:M14)
D15: Comisión corredor | F15: ='Flujo mensual'!P15 | G15: 0 | H15: 0 | I15: 0 | J15: 0 | N15: =SUM(E15:M15)
D16: Gasto común | F16: ='Flujo mensual'!P16 | G16: 0 | H16: 0 | I16: 0 | J16: 0 | N16: =SUM(E16:M16)
D17: Administración | F17: ='Flujo mensual'!P17 | G17: ='Flujo mensual'!$O$17*12*0.9 | H17: ='Flujo mensual'!$O$17*12*0.9 | I17: ='Flujo mensual'!$O$17*12*0.9 | J17: ='Flujo mensual'!$O$17*12*0.9 | N17: =SUM(E17:M17)
D18: Imprevistos | F18: ='Flujo mensual'!$P$19 | G18: ='Flujo mensual'!$P$19 | H18: ='Flujo mensual'!$P$19 | I18: ='Flujo mensual'!$P$19 | J18: ='Flujo mensual'!$P$19 | N18: =SUM(E18:M18)
D19: Costo Financiero Cred. 1 | F19: ='Crédito C12'!O9 | G19: ='Crédito C12'!AA9 | H19: ='Crédito C12'!AM9 | I19: ='Crédito C12'!AY9 | J19: ='Crédito C12'!BK9 | N19: =SUM(E19:M19)
D20: IVA | F20: ='Flujo mensual'!P20 | G20: ='Flujo mensual'!$O$20*12 | H20: ='Flujo mensual'!$O$20*12 | I20: ='Flujo mensual'!$O$20*12 | J20: ='Flujo mensual'!$O$20*12 | N20: =SUM(E20:M20)
D21: Impuesto / Utilidades (se venden al mismo precio) | K21: 0
D22: Total Egresos | E22: =SUM(E10:E21) | F22: =SUM(F10:F21) | G22: =SUM(G10:G21) | H22: =SUM(H10:H21) | I22: =SUM(I10:I21) | J22: =SUM(J10:J21) | K22: =SUM(K10:K21) | L22: =SUM(L10:L20) | M22: =SUM(M10:M20) | N22: =SUM(N10:N20)
D24: Flujo Anual Proy. Puro (+ C.F.) | E24: =E7-E22 | F24: =F7-F22 | G24: =G7-G22 | H24: =H7-H22 | I24: =I7-I22 | J24: =J7-J22 | L24: =L7-L22 | M24: =M7-M22 | N24: =SUM(E24:M24) | P24: =N7-N22-J27-J28
D25: Flujo acumulado | E25: =E24 | F25: =E25+F24 | G25: =F25+G24 | H25: =G25+H24 | I25: =H25+I24 | J25: =I25+J24
D27: Saldo IVA | E27: =E4+E5-E20 | F27: =F4+F5-F20 | G27: =F27-G20 | H27: =G27-H20 | I27: =H27-I20 | J27: =I27-J20
D28: Prepago Crédito | J28: ='Crédito Comercial 12A'!K67
D30: Finaciamiento | E30: 1500 | G30: 2000 | H30: 4500 | I30: 5000 | N30: =SUM(E30:J30)
D31: Dev. Financiamiento | L31: =-N30
D32: Dividendo | M32: =-L36
D33: Flujo Financiamiento | E33: =SUM(E30:E32) | F33: =SUM(F30:F32) | G33: =SUM(G30:G32) | H33: =SUM(H30:H32) | I33: =SUM(I30:I32) | J33: =SUM(J30:J32) | L33: =SUM(L30:L32) | M33: =SUM(M30:M32) | N33: =SUM(N30:N32)
D35: Flujo caja anual | E35: =+E25+E33 | F35: =+F24+F33 | G35: =+G24+G33 | H35: =+H24+H33 | I35: =+I24+I33 | J35: =+J24-J27-J28+J33 | L35: =+L24+L33-L27-L28 | M35: =+M24+M33-M27-M28 | N35: =SUM(E35:M35)
D36: Flujo anual acumulado | E36: =+E35 | F36: =+F35+E36 | G36: =+G35+F36 | H36: =+H35+G36 | I36: =+I35+H36 | J36: =+J35+I36 | L36: =+L35+J36 | M36: =+M35+L36
D38: Saldo final Dividendo | M38: =+J25-J27-J28
D40: =IRR(E25:J25)

Sheet Flujo 5 años C12 (2)
D2: Proyecto a 5 años Perfil 12 | P2: Proyecto a 5 años Perfil 20
D4: Ingresos | E4: Año 0 | F4: Año 1 | G4: Año 2 | H4: Año 3 | I4: Año 4 | J4: Año 5 | K4: Año 6 | L4: Dev. Prest | M4: Dividendo | N4: Total | P4: Ingresos | Q4: Año 0 | R4: Año 1 | S4: Año 2 | T4: Año 3 | U4: Año 4 | V4: Año 5 | W4: Año 6 | X4: Dev. Prest | Y4: Dividendo | Z4: Total
D5: Arriendos | F5: ='Flujo mensual'!P4 | G5: ='Flujo mensual'!$O$4*12*0.9 | H5: ='Flujo mensual'!$O$4*12*0.9 | I5: ='Flujo mensual'!$O$4*12*0.9 | J5: ='Flujo mensual'!$O$4*12*0.9 | N5: =SUM(F5:M5) | P5: Arriendos | R5: ='Flujo 5 años C20'!F3 | S5: ='Flujo 5 años C20'!G3 | T5: ='Flujo 5 años C20'!H3 | U5: ='Flujo 5 años C20'!I3 | V5: ='Flujo 5 años C20'!J3 | Z5: =SUM(R5:Y5)
D6: C. Fiscal Equip. | F6: ='Flujo mensual'!G5 | G6: 0 | H6: 0 | I6: 0 | J6: 0 | N6: =SUM(F6:M6) | P6: C. Fiscal Equip. | R6: ='Flujo 5 años C20'!F4 | S6: 0 | T6: 0 | U6: 0 | V6: 0 | Z6: =SUM(R6:Y6)
D7: C. Fiscal Unidades | F7: ='Flujo mensual'!G6 | G7: 0 | H7: 0 | I7: 0 | J7: 0 | N7: =SUM(F7:M7) | P7: C. Fiscal Unidades | R7: ='Flujo 5 años C20'!F5 | S7: 0 | T7: 0 | U7: 0 | V7: 0 | Z7: =SUM(R7:Y7)
D8: Venta propiedades | F8: 0 | G8: 0 | H8: 0 | I8: 0 | J8: ='IVA Dptos'!AD23 | N8: ='Flujo 5 años C12'!N6 | P8: Venta propiedades | R8: 0 | S8: 0 | T8: 0 | U8: 0 | V8: ='Flujo 5 años C20'!J6 | Z8: =SUM(R8:Y8)
D9: Total Ingresos | E9: =SUM(E5:E8) | F9: =SUM(F5:F8) | G9: =SUM(G5:G8) | H9: =SUM(H5:H8) | I9: =SUM(I5:I8) | J9: =SUM(J5:J8) | K9: =SUM(K5:K8) | L9: =SUM(L5:L8) | ... N9: =SUM(N5:N8) | P9: Total Ingresos | Q9: 0 | R9: =SUM(R5:R8) | S9: =SUM(S5:S8) | T9: =SUM(T5:T8) | U9: =SUM(U5:U8) | V9: =SUM(V5:V8) | W9: 0 | X9: 0 | Y9: 0 | Z9: =SUM(Z5:Z8)
D11: Egresos | E11: Año 0 | F11: Año 1 | G11: Año 2 | H11: Año 3 | I11: Año 4 | J11: Año 5 | K11: Año 6 | N11: Total | P11: Egresos | Q11: Año 0 | R11: Año 1 | S11: Año 2 | T11: Año 3 | U11: Año 4 | V11: Año 5 | W11: Año 6 | Z11: Total
D12: Amoblado | E12: ='Flujo mensual'!C11 | F12: 0 | G12: 0 | H12: 0 | I12: 0 | J12: 0 | N12: =SUM(E12:M12) | P12: ='Flujo 5 años C20'!D10 | Q12: ='Flujo 5 años C20'!E10 | R12: ='Flujo 5 años C20'!F10 | S12: ='Flujo 5 años C20'!G10 | T12: ='Flujo 5 años C20'!H10 | U12: ='Flujo 5 años C20'!I10 | V12: ='Flujo 5 años C20'!J10 | W12: ='Flujo 5 años C20'!K10 | ... Y12: ='Flujo 5 años C20'!M10 | Z12: =SUM(Q12:Y12)
D13: Contribuciones | F13: ='Flujo mensual'!$P$12 | G13: ='Flujo mensual'!$P$12 | H13: ='Flujo mensual'!$P$12 | I13: ='Flujo mensual'!$P$12 | J13: ='Flujo mensual'!$P$12 | N13: =SUM(E13:M13) | P13: ='Flujo 5 años C20'!D11 | Q13: ='Flujo 5 años C20'!E11 | R13: ='Flujo 5 años C20'!F11 | S13: ='Flujo 5 años C20'!G11 | T13: ='Flujo 5 años C20'!H11 | U13: ='Flujo 5 años C20'!I11 | V13: ='Flujo 5 años C20'!J11 | W13: ='Flujo 5 años C20'!K11 | ... Y13: ='Flujo 5 años C20'!M11 | Z13: =SUM(Q13:Y13)
D14: Cuota de alzaminto | E14: ='Crédito Comercial 12A'!D10 | N14: =SUM(E14:M14) | P14: ='Flujo 5 años C20'!D12 | Q14: ='Flujo 5 años C20'!E12 | R14: ='Flujo 5 años C20'!F12 | S14: ='Flujo 5 años C20'!G12 | T14: ='Flujo 5 años C20'!H12 | U14: ='Flujo 5 años C20'!I12 | V14: ='Flujo 5 años C20'!J12 | W14: ='Flujo 5 años C20'!K12 | ... Y14: ='Flujo 5 años C20'!M12 | Z14: =SUM(Q14:Y14)
D15: Dividendo | F15: ='Flujo mensual'!$P$13 | G15: ='Flujo mensual'!$P$13 | H15: ='Flujo mensual'!$P$13 | I15: ='Flujo mensual'!$P$13 | J15: ='Flujo mensual'!$P$13 | N15: =SUM(E15:M15) | P15: ='Flujo 5 años C20'!D13 | Q15: ='Flujo 5 años C20'!E13 | R15: ='Flujo 5 años C20'!F13 | S15: ='Flujo 5 años C20'!G13 | T15: ='Flujo 5 años C20'!H13 | U15: ='Flujo 5 años C20'!I13 | V15: ='Flujo 5 años C20'!J13 | W15: ='Flujo 5 años C20'!K13 | ... Y15: ='Flujo 5 años C20'!M13 | Z15: =SUM(Q15:Y15)
D16: Gasto operacional | E16: ='Flujo mensual'!P14 | F16: 0 | G16: 0 | H16: 0 | I16: 0 | J16: 0 | N16: =SUM(E16:M16) | P16: ='Flujo 5 años C20'!D14 | Q16: ='Flujo 5 años C20'!E14 | R16: ='Flujo 5 años C20'!F14 | S16: ='Flujo 5 años C20'!G14 | T16: ='Flujo 5 años C20'!H14 | U16: ='Flujo 5 años C20'!I14 | V16: ='Flujo 5 años C20'!J14 | W16: ='Flujo 5 años C20'!K14 | ... Y16: ='Flujo 5 años C20'!M14 | Z16: =SUM(Q16:Y16)
D17: Comisión corredor | F17: ='Flujo mensual'!P15 | G17: 0 | H17: 0 | I17: 0 | J17: 0 | N17: =SUM(E17:M17) | P17: ='Flujo 5 años C20'!D15 | Q17: ='Flujo 5 años C20'!E15 | R17: ='Flujo 5 años C20'!F15 | S17: ='Flujo 5 años C20'!G15 | T17: ='Flujo 5 años C20'!H15 | U17: ='Flujo 5 años C20'!I15 | V17: ='Flujo 5 años C20'!J15 | W17: ='Flujo 5 años C20'!K15 | ... Y17: ='Flujo 5 años C20'!M15 | Z17: =SUM(Q17:Y17)
D18: Gasto común | F18: ='Flujo mensual'!P16 | G18: 0 | H18: 0 | I18: 0 | J18: 0 | N18: =SUM(E18:M18) | P18: ='Flujo 5 años C20'!D16 | Q18: ='Flujo 5 años C20'!E16 | R18: ='Flujo 5 años C20'!F16 | S18: ='Flujo 5 años C20'!G16 | T18: ='Flujo 5 años C20'!H16 | U18: ='Flujo 5 años C20'!I16 | V18: ='Flujo 5 años C20'!J16 | W18: ='Flujo 5 años C20'!K16 | ... Y18: ='Flujo 5 años C20'!M16 | Z18: =SUM(Q18:Y18)
D19: Administración | F19: ='Flujo mensual'!P17 | G19: ='Flujo mensual'!$O$17*12*0.9 | H19: ='Flujo mensual'!$O$17*12*0.9 | I19: ='Flujo mensual'!$O$17*12*0.9 | J19: ='Flujo mensual'!$O$17*12*0.9 | N19: =SUM(E19:M19) | P19: ='Flujo 5 años C20'!D17 | Q19: ='Flujo 5 años C20'!E17 | R19: ='Flujo 5 años C20'!F17 | S19: ='Flujo 5 años C20'!G17 | T19: ='Flujo 5 años C20'!H17 | U19: ='Flujo 5 años C20'!I17 | V19: ='Flujo 5 años C20'!J17 | W19: ='Flujo 5 años C20'!K17 | ... Y19: ='Flujo 5 años C20'!M17 | Z19: =SUM(Q19:Y19)
D20: Imprevistos | F20: ='Flujo mensual'!$P$19 | G20: ='Flujo mensual'!$P$19 | H20: ='Flujo mensual'!$P$19 | I20: ='Flujo mensual'!$P$19 | J20: ='Flujo mensual'!$P$19 | N20: =SUM(E20:M20) | P20: ='Flujo 5 años C20'!D18 | Q20: ='Flujo 5 años C20'!E18 | R20: ='Flujo 5 años C20'!F18 | S20: ='Flujo 5 años C20'!G18 | T20: ='Flujo 5 años C20'!H18 | U20: ='Flujo 5 años C20'!I18 | V20: ='Flujo 5 años C20'!J18 | W20: ='Flujo 5 años C20'!K18 | ... Y20: ='Flujo 5 años C20'!M18 | Z20: =SUM(Q20:Y20)
D21: Costo Financiero Cred. 1 | F21: ='Crédito C12'!O9 | G21: ='Crédito C12'!AA9 | H21: ='Crédito C12'!AM9 | I21: ='Crédito C12'!AY9 | J21: ='Crédito C12'!BK9 | N21: =SUM(E21:M21) | P21: ='Flujo 5 años C20'!D19 | Q21: ='Flujo 5 años C20'!E19 | R21: ='Flujo 5 años C20'!F19 | S21: ='Flujo 5 años C20'!G19 | T21: ='Flujo 5 años C20'!H19 | U21: ='Flujo 5 años C20'!I19 | V21: ='Flujo 5 años C20'!J19 | W21: ='Flujo 5 años C20'!K19 | ... Y21: ='Flujo 5 años C20'!M19 | Z21: =SUM(Q21:Y21)
D22: IVA | F22: ='Flujo mensual'!P20 | G22: ='Flujo mensual'!$O$20*12 | H22: ='Flujo mensual'!$O$20*12 | I22: ='Flujo mensual'!$O$20*12 | J22: ='Flujo mensual'!$O$20*12 | N22: =SUM(E22:M22) | P22: ='Flujo 5 años C20'!D20 | Q22: ='Flujo 5 años C20'!E20 | R22: ='Flujo 5 años C20'!F20 | S22: ='Flujo 5 años C20'!G20 | T22: ='Flujo 5 años C20'!H20 | U22: ='Flujo 5 años C20'!I20 | V22: ='Flujo 5 años C20'!J20 | W22: ='Flujo 5 años C20'!K20 | ... Y22: ='Flujo 5 años C20'!M20 | Z22: =SUM(Q22:Y22)
D23: Impuesto | K23: 0 | P23: Impuesto | W23: 0 | Z23: =SUM(Q23:Y23)
D24: Total Egresos | E24: =SUM(E12:E23) | F24: =SUM(F12:F23) | G24: =SUM(G12:G23) | H24: =SUM(H12:H23) | I24: =SUM(I12:I23) | J24: =SUM(J12:J23) | K24: =SUM(K12:K23) | L24: =SUM(L12:L22) | M24: =SUM(M12:M22) | N24: =SUM(N12:N22) | P24: Total Egresos | Q24: =SUM(Q12:Q23) | R24: =SUM(R12:R23) | S24: =SUM(S12:S23) | T24: =SUM(T12:T23) | U24: =SUM(U12:U23) | V24: =SUM(V12:V23) | W24: =SUM(W12:W23) | X24: =SUM(X12:X23) | ... Z24: =SUM(Z12:Z23)
D26: Flujo Proyecto | E26: =E9-E24 | F26: =F9-F24 | G26: =G9-G24 | H26: =H9-H24 | I26: =I9-I24 | J26: =J9-J24 | L26: =L9-L24 | M26: =M9-M24 | N26: =N9-N24 | P26: Flujo Proyecto | Q26: =Q9-Q24 | R26: =R9-R24 | S26: =S9-S24 | T26: =T9-T24 | U26: =U9-U24 | V26: =V9-V24 | X26: =X9-X24 | Y26: =Y9-Y24 | Z26: =SUM(Q26:Y26)
D27: Flujo acumulado | E27: =E26 | F27: =E27+F26 | G27: =F27+G26 | H27: =G27+H26 | I27: =H27+I26 | J27: =I27+J26 | P27: Flujo acumulado | Q27: -755.66751 | R27: 3013.0707 | S27: 1099.429 | T27: -859.21275 | U27: -2877.8545 | V27: 47741.804
D29: Saldo IVA | E29: =E6+E7-E22 | F29: =F6+F7-F22 | G29: =F29-G22 | H29: =G29-H22 | I29: =H29-I22 | N29: =I29-J22 | P29: Saldo IVA | Q29: =Q6+Q7-Q22 | R29: =R6+R7-R22 | S29: =R29-S22 | T29: =S29-T22 | U29: =T29-U22 | Z29: =U29-V22
D30: Prepago Crédito | N30: ='Crédito Comercial 12A'!K67 | P30: Prepago Crédito | Z30: ='Crédito Comercial 20A'!K67
D32: Finaciamiento | E32: 1000 | G32: 3000 | H32: 4500 | I32: 4500 | N32: =SUM(E32:J32) | P32: Finaciamiento | Q32: ='Flujo 5 años C20'!E30 | R32: ='Flujo 5 años C20'!F30 | S32: ='Flujo 5 años C20'!G30 | T32: ='Flujo 5 años C20'!H30 | U32: ='Flujo 5 años C20'!I30 | V32: ='Flujo 5 años C20'!J30 | W32: ='Flujo 5 años C20'!K30 | X32: ='Flujo 5 años C20'!L30 | Y32: ='Flujo 5 años C20'!M30 | Z32: =SUM(Q32:Y32)
D33: Dev. Financiamiento | L33: =-N32 | N33: =-N32 | P33: Dev. Financiamiento | Q33: ='Flujo 5 años C20'!E31 | R33: ='Flujo 5 años C20'!F31 | S33: ='Flujo 5 años C20'!G31 | T33: ='Flujo 5 años C20'!H31 | U33: ='Flujo 5 años C20'!I31 | V33: ='Flujo 5 años C20'!J31 | W33: ='Flujo 5 años C20'!K31 | X33: ='Flujo 5 años C20'!L31 | Y33: ='Flujo 5 años C20'!M31 | Z33: =SUM(Q33:Y33)
D34: Dividendo | M34: =-L38 | P34: Dividendo | Y34: -5386.4309
D35: Flujo Financiamiento | E35: =SUM(E32:E34) | F35: =SUM(F32:F34) | G35: =SUM(G32:G34) | H35: =SUM(H32:H34) | I35: =SUM(I32:I34) | J35: =SUM(J32:J34) | L35: =SUM(L32:L34) | M35: =SUM(M32:M34) | N35: =SUM(N32:N34) | P35: Flujo Financiamiento | Q35: 1000 | R35: 0 | S35: 0 | T35: 1000 | U35: 1000 | V35: 0 | X35: -3000 | Y35: -5386.4309 | Z35: 3000
D37: Flujo caja anual | E37: =+E27+E35 | F37: =+F26+F35 | G37: =+G26+G35 | H37: =+H26+H35 | I37: =+I26+I35 | J37: =+J26-N29-N30+J35 | L37: =+L26+L35-L29-L30 | M37: =+M26+M35-M29-M30 | N37: =SUM(E37:M37) | P37: Flujo caja anual | Q37: 244.33249 | R37: 3768.7382 | S37: -1913.6417 | T37: -958.64171 | U37: -1018.6417 | V37: 8264.2854 | X37: -3000 | Y37: -5386.4309 | Z37: 0
D38: Flujo anual acumulado | E38: =+E37 | F38: =+F37+E38 | G38: =+G37+F38 | H38: =+H37+G38 | I38: =+I37+H38 | J38: =+J37+I38 | L38: =+L37+J38 | M38: =+M37+L38 | P38: Flujo anual acumulado | Q38: 244.33249 | R38: 4013.0707 | S38: 2099.429 | T38: 1140.7872 | U38: 122.14553 | V38: 8386.4309 | X38: 5386.4309 | Y38: 0
D40: Saldo final Dividendo | M40: =+J27-N29-N30 | N40: =N26-N29-N30 | P40: Saldo final Dividendo | Q40: ='Flujo 5 años C20'!E38 | R40: ='Flujo 5 años C20'!F38 | S40: ='Flujo 5 años C20'!G38 | T40: ='Flujo 5 años C20'!H38 | U40: ='Flujo 5 años C20'!I38 | V40: ='Flujo 5 años C20'!J38 | W40: ='Flujo 5 años C20'!K38 | X40: ='Flujo 5 años C20'!L38 | Y40: ='Flujo 5 años C20'!M38 | Z40: =Z26-Z29-Z30

Sheet Crédito Comercial 12A
B2: Venta Total (sin descuento) | D2: ='IVA Dptos'!X23+'IVA Dptos'!M23+'IVA Dptos'!O23
B3: Dcto | C3: 0.28 | D3: =D2-D2*C3 | E3: =118000 | G3: =E3-D3
B4: Crédito UF LTV - 72% | D4: =D3
B5: Tasa anual nomial | D5: 0.05
B6: Tasa mensual | D6: =D5/12 | G6: Período | H6: Cuota | I6: Interés | J6: Capital | K6: S. Insoluto
B7: Períodos | D7: =12*12 | G7: 0 | H7: 0 | I7: 0 | J7: 0 | K7: =D4
D8: =D7/12 | G8: =G7+1 | H8: =PMT($D$6,$D$7,$D$4) | I8: =-K7*$D$6 | J8: =H8-I8 | K8: =K7+J8
G9: =G8+1 | H9: =PMT($D$5/12,$D$7,$D$4) | I9: =-K8*$D$6 | J9: =H9-I9 | K9: =K8+J9
B10: Cuota de alzamiento | D10: 0 | G10: =G9+1 | H10: =PMT($D$5/12,$D$7,$D$4) | I10: =-K9*$D$6 | J10: =H10-I10 | K10: =K9+J10
G11: =G10+1 | H11: =PMT($D$5/12,$D$7,$D$4) | I11: =-K10*$D$6 | J11: =H11-I11 | K11: =K10+J11
G12: =G11+1 | H12: =PMT($D$5/12,$D$7,$D$4) | I12: =-K11*$D$6 | J12: =H12-I12 | K12: =K11+J12
G13: =G12+1 | H13: =PMT($D$5/12,$D$7,$D$4) | I13: =-K12*$D$6 | J13: =H13-I13 | K13: =K12+J13
G14: =G13+1 | H14: =PMT($D$5/12,$D$7,$D$4) | I14: =-K13*$D$6 | J14: =H14-I14 | K14: =K13+J14
G15: =G14+1 | H15: =PMT($D$5/12,$D$7,$D$4) | I15: =-K14*$D$6 | J15: =H15-I15 | K15: =K14+J15
G16: =G15+1 | H16: =PMT($D$5/12,$D$7,$D$4) | I16: =-K15*$D$6 | J16: =H16-I16 | K16: =K15+J16
G17: =G16+1 | H17: =PMT($D$5/12,$D$7,$D$4) | I17: =-K16*$D$6 | J17: =H17-I17 | K17: =K16+J17
G18: =G17+1 | H18: =PMT($D$5/12,$D$7,$D$4) | I18: =-K17*$D$6 | J18: =H18-I18 | K18: =K17+J18
E19: =SUM(H8:H19) | G19: =G18+1 | H19: =PMT($D$5/12,$D$7,$D$4) | I19: =-K18*$D$6 | J19: =H19-I19 | K19: =K18+J19
G20: =G19+1 | H20: =PMT($D$5/12,$D$7,$D$4) | I20: =-K19*$D$6 | J20: =H20-I20 | K20: =K19+J20
G21: =G20+1 | H21: =PMT($D$5/12,$D$7,$D$4) | I21: =-K20*$D$6 | J21: =H21-I21 | K21: =K20+J21
G22: =G21+1 | H22: =PMT($D$5/12,$D$7,$D$4) | I22: =-K21*$D$6 | J22: =H22-I22 | K22: =K21+J22
G23: =G22+1 | H23: =PMT($D$5/12,$D$7,$D$4) | I23: =-K22*$D$6 | J23: =H23-I23 | K23: =K22+J23
G24: =G23+1 | H24: =PMT($D$5/12,$D$7,$D$4) | I24: =-K23*$D$6 | J24: =H24-I24 | K24: =K23+J24
G25: =G24+1 | H25: =PMT($D$5/12,$D$7,$D$4) | I25: =-K24*$D$6 | J25: =H25-I25 | K25: =K24+J25
G26: =G25+1 | H26: =PMT($D$5/12,$D$7,$D$4) | I26: =-K25*$D$6 | J26: =H26-I26 | K26: =K25+J26
G27: =G26+1 | H27: =PMT($D$5/12,$D$7,$D$4) | I27: =-K26*$D$6 | J27: =H27-I27 | K27: =K26+J27
G28: =G27+1 | H28: =PMT($D$5/12,$D$7,$D$4) | I28: =-K27*$D$6 | J28: =H28-I28 | K28: =K27+J28
G29: =G28+1 | H29: =PMT($D$5/12,$D$7,$D$4) | I29: =-K28*$D$6 | J29: =H29-I29 | K29: =K28+J29
G30: =G29+1 | H30: =PMT($D$5/12,$D$7,$D$4) | I30: =-K29*$D$6 | J30: =H30-I30 | K30: =K29+J30
G31: =G30+1 | H31: =PMT($D$5/12,$D$7,$D$4) | I31: =-K30*$D$6 | J31: =H31-I31 | K31: =K30+J31
... G66: =G65+1 | H66: =PMT($D$5/12,$D$7,$D$4) | I66: =-K65*$D$6 | J66: =H66-I66 | K66: =K65+J66
E67: 5 AÑOS | G67: =G66+1 | H67: =PMT($D$5/12,$D$7,$D$4) | I67: =-K66*$D$6 | J67: =H67-I67 | K67: =K66+J67
G68: =G67+1 | H68: =PMT($D$5/12,$D$7,$D$4) | I68: =-K67*$D$6 | J68: =H68-I68 | K68: =K67+J68
G69: =G68+1 | H69: =PMT($D$5/12,$D$7,$D$4) | I69: =-K68*$D$6 | J69: =H69-I69 | K69: =K68+J69
G70: =G69+1 | H70: =PMT($D$5/12,$D$7,$D$4) | I70: =-K69*$D$6 | J70: =H70-I70 | K70: =K69+J70
G71: =G70+1 | H71: =PMT($D$5/12,$D$7,$D$4) | I71: =-K70*$D$6 | J71: =H71-I71 | K71: =K70+J71
G72: =G71+1 | H72: =PMT($D$5/12,$D$7,$D$4) | I72: =-K71*$D$6 | J72: =H72-I72 | K72: =K71+J72
G73: =G72+1 | H73: =PMT($D$5/12,$D$7,$D$4) | I73: =-K72*$D$6 | J73: =H73-I73 | K73: =K72+J73
G74: =G73+1 | H74: =PMT($D$5/12,$D$7,$D$4) | I74: =-K73*$D$6 | J74: =H74-I74 | K74: =K73+J74
G75: =G74+1 | H75: =PMT($D$5/12,$D$7,$D$4) | I75: =-K74*$D$6 | J75: =H75-I75 | K75: =K74+J75
...

Sheet Crédito C12
A1: Tasa | B1: 0.06
A2: Monto | B2: =SUM('Flujo 5 años C12'!E30:I30) | D2: 46023 | E2: 46054 | F2: 46082 | G2: 46113 | H2: 46143 | I2: 46174 | J2: 46204 | K2: 46235 | L2: 46266 | M2: 46296 | N2: 46327 | O2: 46357 | P2: 46388 | Q2: 46419 | R2: 46447 | S2: 46478 | T2: 46508 | U2: 46539 | V2: 46569 | W2: 46600 | X2: 46631 | Y2: 46661 | Z2: 46692 | AA2: 46722 | AB2: 46753 | AC2: 46784 | AD2: 46813 | AE2: 46844 | AF2: 46874 | AG2: 46905 | AH2: 46935 | AI2: 46966 | AJ2: 46997 | AK2: 47027 | AL2: 47058 | AM2: 47088 | AN2: 47119 | AO2: 47150 | AP2: 47178 | AQ2: 47209 | AR2: 47239 | AS2: 47270 | AT2: 47300 | AU2: 47331 | AV2: 47362 | AW2: 47392 | AX2: 47423 | AY2: 47453 | AZ2: 47484 | BA2: 47515 | BB2: 47543 | BC2: 47574 | BD2: 47604 | BE2: 47635 | BF2: 47665 | BG2: 47696 | BH2: 47727 | BI2: 47757 | BJ2: 47788 | BK2: 47818
A3: Cuotas | D3: ='Flujo 5 años C12'!E30 | E3: 0 | F3: 0 | G3: 0 | H3: 0 | I3: 0 | J3: 0 | K3: 0 | L3: 0 | M3: 0 | N3: 0 | O3: 0 | P3: ='Flujo 5 años C12'!G30 | Q3: 0 | R3: 0 | S3: 0 | T3: 0 | U3: 0 | V3: 0 | W3: 0 | X3: 0 | Y3: 0 | Z3: 0 | AA3: 0 | AB3: ='Flujo 5 años C12'!H30 | AC3: 0 | AD3: 0 | AE3: 0 | AF3: 0 | AG3: 0 | AH3: 0 | AI3: 0 | AJ3: 0 | AK3: 0 | AL3: 0 | AM3: 0 | AN3: ='Flujo 5 años C12'!I30 | AO3: 0 | AP3: 0 | AQ3: 0 | AR3: 0 | AS3: 0 | AT3: 0 | AU3: 0 | AV3: 0 | AW3: 0 | AX3: 0 | AY3: 0 | AZ3: ='Flujo 5 años C12'!J30 | BA3: 0 | BB3: 0 | BC3: 0 | BD3: 0 | BE3: 0 | BF3: 0 | BG3: 0 | BH3: 0 | BI3: 0 | BJ3: 0 | BK3: 0
C4: Amortización | D4: 0 | E4: 0 | F4: 0 | G4: 0 | H4: 0 | I4: 0 | J4: 0 | K4: 0 | L4: 0 | M4: 0 | N4: 0 | O4: 0 | P4: 0 | Q4: 0 | R4: 0 | S4: 0 | T4: 0 | U4: 0 | V4: 0 | W4: 0 | X4: 0 | Y4: 0 | Z4: 0 | AA4: 0 | AB4: 0 | AC4: 0 | AD4: 0 | AE4: 0 | AF4: 0 | AG4: 0 | AH4: 0 | AI4: 0 | AJ4: 0 | AK4: 0 | AL4: 0 | AM4: 0 | AN4: 0 | AO4: 0 | AP4: 0 | AQ4: 0 | AR4: 0 | AS4: 0 | AT4: 0 | AU4: 0 | AV4: 0 | AW4: 0 | AX4: 0 | AY4: 0 | AZ4: 0 | BA4: 0 | BB4: 0 | BC4: 0 | BD4: 0 | BE4: 0 | BF4: 0 | BG4: 0 | BH4: 0 | BI4: 0 | BJ4: 0 | BK4: 0
C5: Saldo de Capital | D5: =D3 | E5: =D5+E4+E3 | F5: =E5+F4+F3 | G5: =F5+G4+G3 | H5: =G5+H4+H3 | I5: =H5+I4+I3 | J5: =I5+J4+J3 | K5: =J5+K4+K3 | L5: =K5+L4+L3 | ... BK5: =BJ5+BK4+BK3
E7: =D5*$B$1/12 | F7: =E5*$B$1/12 | G7: =F5*$B$1/12 | H7: =G5*$B$1/12 | I7: =H5*$B$1/12 | J7: =I5*$B$1/12 | K7: =J5*$B$1/12 | L7: =K5*$B$1/12 | ... BK7: =BJ5*$B$1/12 | BL7: =SUM(E7:BK7)
G8: =SUM(E7:G7) | J8: =SUM(H7:J7) | M8: =SUM(K7:M7) | P8: =SUM(N7:P7) | S8: =SUM(Q7:S7) | V8: =SUM(T7:V7) | Y8: =SUM(W7:Y7) | AB8: =SUM(Z7:AB7) | AE8: =SUM(AC7:AE7) | AH8: =SUM(AF7:AH7) | AK8: =SUM(AI7:AK7) | AN8: =SUM(AL7:AN7) | AQ8: =SUM(AO7:AQ7) | AT8: =SUM(AR7:AT7) | AW8: =SUM(AU7:AW7) | AZ8: =SUM(AX7:AZ7) | BC8: =SUM(BA7:BC7) | BF8: =SUM(BD7:BF7) | BI8: =SUM(BG7:BI7) | BK8: =SUM(BJ7:BK7) | BL8: =SUM(E8:BK8)
O9: =SUM(D8:O8) | AA9: =SUM(P8:AA8) | AM9: =SUM(AB8:AM8) | AY9: =SUM(AN8:AY8) | BK9: =SUM(AZ8:BK8) | BL9: =SUM(E9:BK9)

Sheet Flujo 5 años C20
D2: Ingresos | E2: Año 0 | F2: Año 1 | G2: Año 2 | H2: Año 3 | I2: Año 4 | J2: Año 5 | K2: Año 6 | L2: Dev. Prest | M2: Dividendo | N2: Total
D3: Arriendos | F3: ='Flujo mensual'!P4 | G3: ='Flujo mensual'!$O$4*12*0.9 | H3: ='Flujo mensual'!$O$4*12*0.9 | I3: ='Flujo mensual'!$O$4*12*0.9 | J3: ='Flujo mensual'!$O$4*12*0.9 | N3: =SUM(F3:M3)
D4: C. Fiscal Equip. | F4: ='Flujo mensual'!G5 | G4: 0 | H4: 0 | I4: 0 | J4: 0 | N4: =SUM(F4:M4)
D5: C. Fiscal Unidades | F5: ='Flujo mensual'!G6 | G5: 0 | H5: 0 | I5: 0 | J5: 0 | N5: =SUM(F5:M5)
D6: Venta propiedades | F6: 0 | G6: 0 | H6: 0 | I6: 0 | J6: ='IVA Dptos'!AD23*0.9 | N6: =SUM(F6:M6) | P6: Venta sin mayor plusvalía
D7: Total Ingresos | E7: =SUM(E3:E6) | F7: =SUM(F3:F6) | G7: =SUM(G3:G6) | H7: =SUM(H3:H6) | I7: =SUM(I3:I6) | J7: =SUM(J3:J6) | K7: =SUM(K3:K6) | L7: =SUM(L3:L6) | ... N7: =SUM(N3:N6)
D9: Egresos | E9: Año 0 | F9: Año 1 | G9: Año 2 | H9: Año 3 | I9: Año 4 | J9: Año 5 | K9: Año 6 | N9: Total
D10: Amoblado | E10: ='Flujo mensual'!C11 | F10: 0 | G10: 0 | H10: 0 | I10: 0 | J10: 0 | N10: =SUM(E10:M10)
D11: Contribuciones | F11: ='Flujo mensual'!$P$12 | G11: ='Flujo mensual'!$P$12 | H11: ='Flujo mensual'!$P$12 | I11: ='Flujo mensual'!$P$12 | J11: ='Flujo mensual'!$P$12 | N11: =SUM(E11:M11)
D12: Cuota de alzaminto | E12: ='Crédito Comercial 12A'!D10 | N12: =SUM(E12:M12)
D13: Dividendo | F13: =-'Crédito Comercial 20A'!$H$8*12 | G13: =-'Crédito Comercial 20A'!$H$8*12 | H13: =-'Crédito Comercial 20A'!$H$8*12 | I13: =-'Crédito Comercial 20A'!$H$8*12 | J13: =-'Crédito Comercial 20A'!$H$8*12 | N13: =SUM(E13:M13)
D14: Gasto operacional | E14: ='Flujo mensual'!P14 | F14: 0 | G14: 0 | H14: 0 | I14: 0 | J14: 0 | N14: =SUM(E14:M14)
D15: Comisión corredor | F15: ='Flujo mensual'!P15 | G15: 0 | H15: 0 | I15: 0 | J15: 0 | N15: =SUM(E15:M15)
D16: Gasto común | F16: ='Flujo mensual'!P16 | G16: 0 | H16: 0 | I16: 0 | J16: 0 | N16: =SUM(E16:M16)
D17: Administración | F17: ='Flujo mensual'!P17 | G17: ='Flujo mensual'!$O$17*12*0.9 | H17: ='Flujo mensual'!$O$17*12*0.9 | I17: ='Flujo mensual'!$O$17*12*0.9 | J17: ='Flujo mensual'!$O$17*12*0.9 | N17: =SUM(E17:M17)
D18: Imprevistos | F18: ='Flujo mensual'!$P$19 | G18: ='Flujo mensual'!$P$19 | H18: ='Flujo mensual'!$P$19 | I18: ='Flujo mensual'!$P$19 | J18: ='Flujo mensual'!$P$19 | N18: =SUM(E18:M18)
D19: Costo Financiero Cred. 1 | F19: ='Crédito C20'!O9 | G19: ='Crédito C20'!AA9 | H19: ='Crédito C20'!AM9 | I19: ='Crédito C20'!AY9 | J19: ='Crédito C20'!BK9 | N19: =SUM(E19:M19)
D20: IVA | F20: ='Flujo mensual'!P20 | G20: ='Flujo mensual'!$O$20*12 | H20: ='Flujo mensual'!$O$20*12 | I20: ='Flujo mensual'!$O$20*12 | J20: ='Flujo mensual'!$O$20*12 | N20: =SUM(E20:M20)
D21: Impuesto / Utilidades (se venden al mismo precio) | K21: 0
D22: Total Egresos | E22: =SUM(E10:E21) | F22: =SUM(F10:F21) | G22: =SUM(G10:G21) | H22: =SUM(H10:H21) | I22: =SUM(I10:I21) | J22: =SUM(J10:J21) | K22: =SUM(K10:K21) | L22: =SUM(L10:L20) | M22: =SUM(M10:M20) | N22: =SUM(N10:N20)
D24: Flujo Anual Proy. Puro (+ C.F.) | E24: =E7-E22 | F24: =F7-F22 | G24: =G7-G22 | H24: =H7-H22 | I24: =I7-I22 | J24: =J7-J22 | L24: =L7-L22 | M24: =M7-M22 | N24: =SUM(E24:M24)
D25: Flujo acumulado | E25: =E24 | F25: =E25+F24 | G25: =F25+G24 | H25: =G25+H24 | I25: =H25+I24 | J25: =I25+J24
D27: Saldo IVA | E27: =E4+E5-E20 | F27: =F4+F5-F20 | G27: =F27-G20 | H27: =G27-H20 | I27: =H27-I20 | J27: =I27-J20
D28: Prepago Crédito | J28: ='Crédito Comercial 20A'!K67
D30: Finaciamiento | E30: 1500 | G30: 0 | H30: 1000 | I30: 2000 | N30: =SUM(E30:J30)
D31: Dev. Financiamiento | L31: =-N30
D32: Dividendo | M32: =-L36
D33: Flujo Financiamiento | E33: =SUM(E30:E32) | F33: =SUM(F30:F32) | G33: =SUM(G30:G32) | H33: =SUM(H30:H32) | I33: =SUM(I30:I32) | J33: =SUM(J30:J32) | L33: =SUM(L30:L32) | M33: =SUM(M30:M32) | N33: =SUM(N30:N32)
D35: Flujo caja anual | E35: =+E25+E33 | F35: =+F24+F33 | G35: =+G24+G33 | H35: =+H24+H33 | I35: =+I24+I33 | J35: =+J24-J27-J28+J33 | L35: =+L24+L33-L27-L28 | M35: =+M24+M33-M27-M28 | N35: =SUM(E35:M35)
D36: Flujo anual acumulado | E36: =+E35 | F36: =+F35+E36 | G36: =+G35+F36 | H36: =+H35+G36 | I36: =+I35+H36 | J36: =+J35+I36 | L36: =+L35+J36 | M36: =+M35+L36
D38: Saldo final Dividendo | M38: =+J25-J27-J28

Sheet Crédito Comercial 20A
B2: Venta Total (sin descuento) | D2: ='IVA Dptos'!AD23
B3: Dcto | C3: 0.28 | D3: =D2-D2*C3
B4: Crédito UF LTV - 75% | D4: =D3
B5: Tasa anual UF | D5: 0.05
B6: Tasa mensual | D6: =D5/12 | G6: Período | H6: Cuota | I6: Interés | J6: Capital | K6: S. Insoluto
B7: Períodos | D7: =20*12 | G7: 0 | H7: 0 | I7: 0 | J7: 0 | K7: =D4
D8: =D7/12 | G8: =G7+1 | H8: =PMT($D$6,$D$7,$D$4) | I8: =-K7*$D$6 | J8: =H8-I8 | K8: =K7+J8
G9: =G8+1 | H9: =PMT($D$5/12,$D$7,$D$4) | I9: =-K8*$D$6 | J9: =H9-I9 | K9: =K8+J9
B10: Cuota de alzamiento | D10: 0 | G10: =G9+1 | H10: =PMT($D$5/12,$D$7,$D$4) | I10: =-K9*$D$6 | J10: =H10-I10 | K10: =K9+J10
G11: =G10+1 | H11: =PMT($D$5/12,$D$7,$D$4) | I11: =-K10*$D$6 | J11: =H11-I11 | K11: =K10+J11
G12: =G11+1 | H12: =PMT($D$5/12,$D$7,$D$4) | I12: =-K11*$D$6 | J12: =H12-I12 | K12: =K11+J12
G13: =G12+1 | H13: =PMT($D$5/12,$D$7,$D$4) | I13: =-K12*$D$6 | J13: =H13-I13 | K13: =K12+J13
G14: =G13+1 | H14: =PMT($D$5/12,$D$7,$D$4) | I14: =-K13*$D$6 | J14: =H14-I14 | K14: =K13+J14
G15: =G14+1 | H15: =PMT($D$5/12,$D$7,$D$4) | I15: =-K14*$D$6 | J15: =H15-I15 | K15: =K14+J15
G16: =G15+1 | H16: =PMT($D$5/12,$D$7,$D$4) | I16: =-K15*$D$6 | J16: =H16-I16 | K16: =K15+J16
G17: =G16+1 | H17: =PMT($D$5/12,$D$7,$D$4) | I17: =-K16*$D$6 | J17: =H17-I17 | K17: =K16+J17
G18: =G17+1 | H18: =PMT($D$5/12,$D$7,$D$4) | I18: =-K17*$D$6 | J18: =H18-I18 | K18: =K17+J18
G19: =G18+1 | H19: =PMT($D$5/12,$D$7,$D$4) | I19: =-K18*$D$6 | J19: =H19-I19 | K19: =K18+J19
G20: =G19+1 | H20: =PMT($D$5/12,$D$7,$D$4) | I20: =-K19*$D$6 | J20: =H20-I20 | K20: =K19+J20
G21: =G20+1 | H21: =PMT($D$5/12,$D$7,$D$4) | I21: =-K20*$D$6 | J21: =H21-I21 | K21: =K20+J21
G22: =G21+1 | H22: =PMT($D$5/12,$D$7,$D$4) | I22: =-K21*$D$6 | J22: =H22-I22 | K22: =K21+J22
E23: =H17*10 | G23: =G22+1 | H23: =PMT($D$5/12,$D$7,$D$4) | I23: =-K22*$D$6 | J23: =H23-I23 | K23: =K22+J23
G24: =G23+1 | H24: =PMT($D$5/12,$D$7,$D$4) | I24: =-K23*$D$6 | J24: =H24-I24 | K24: =K23+J24
G25: =G24+1 | H25: =PMT($D$5/12,$D$7,$D$4) | I25: =-K24*$D$6 | J25: =H25-I25 | K25: =K24+J25
G26: =G25+1 | H26: =PMT($D$5/12,$D$7,$D$4) | I26: =-K25*$D$6 | J26: =H26-I26 | K26: =K25+J26
G27: =G26+1 | H27: =PMT($D$5/12,$D$7,$D$4) | I27: =-K26*$D$6 | J27: =H27-I27 | K27: =K26+J27
G28: =G27+1 | H28: =PMT($D$5/12,$D$7,$D$4) | I28: =-K27*$D$6 | J28: =H28-I28 | K28: =K27+J28
G29: =G28+1 | H29: =PMT($D$5/12,$D$7,$D$4) | I29: =-K28*$D$6 | J29: =H29-I29 | K29: =K28+J29
G30: =G29+1 | H30: =PMT($D$5/12,$D$7,$D$4) | I30: =-K29*$D$6 | J30: =H30-I30 | K30: =K29+J30
G31: =G30+1 | H31: =PMT($D$5/12,$D$7,$D$4) | I31: =-K30*$D$6 | J31: =H31-I31 | K31: =K30+J31
G32: =G31+1 | H32: =PMT($D$5/12,$D$7,$D$4) | I32: =-K31*$D$6 | J32: =H32-I32 | K32: =K31+J32
G33: =G32+1 | H33: =PMT($D$5/12,$D$7,$D$4) | I33: =-K32*$D$6 | J33: =H33-I33 | K33: =K32+J33
G34: =G33+1 | H34: =PMT($D$5/12,$D$7,$D$4) | I34: =-K33*$D$6 | J34: =H34-I34 | K34: =K33+J34
G35: =G34+1 | H35: =PMT($D$5/12,$D$7,$D$4) | I35: =-K34*$D$6 | J35: =H35-I35 | K35: =K34+J35
... G66: =G65+1 | H66: =PMT($D$5/12,$D$7,$D$4) | I66: =-K65*$D$6 | J66: =H66-I66 | K66: =K65+J66
E67: 5 AÑOS | G67: =G66+1 | H67: =PMT($D$5/12,$D$7,$D$4) | I67: =-K66*$D$6 | J67: =H67-I67 | K67: =K66+J67
G68: =G67+1 | H68: =PMT($D$5/12,$D$7,$D$4) | I68: =-K67*$D$6 | J68: =H68-I68 | K68: =K67+J68
G69: =G68+1 | H69: =PMT($D$5/12,$D$7,$D$4) | I69: =-K68*$D$6 | J69: =H69-I69 | K69: =K68+J69
G70: =G69+1 | H70: =PMT($D$5/12,$D$7,$D$4) | I70: =-K69*$D$6 | J70: =H70-I70 | K70: =K69+J70
G71: =G70+1 | H71: =PMT($D$5/12,$D$7,$D$4) | I71: =-K70*$D$6 | J71: =H71-I71 | K71: =K70+J71
...

Sheet Crédito C20
A1: Tasa | B1: 0.06
A2: Monto | B2: ='Flujo 5 años C20'!N30 | D2: 46023 | E2: 46054 | F2: 46082 | G2: 46113 | H2: 46143 | I2: 46174 | J2: 46204 | K2: 46235 | L2: 46266 | M2: 46296 | N2: 46327 | O2: 46357 | P2: 46388 | Q2: 46419 | R2: 46447 | S2: 46478 | T2: 46508 | U2: 46539 | V2: 46569 | W2: 46600 | X2: 46631 | Y2: 46661 | Z2: 46692 | AA2: 46722 | AB2: 46753 | AC2: 46784 | AD2: 46813 | AE2: 46844 | AF2: 46874 | AG2: 46905 | AH2: 46935 | AI2: 46966 | AJ2: 46997 | AK2: 47027 | AL2: 47058 | AM2: 47088 | AN2: 47119 | AO2: 47150 | AP2: 47178 | AQ2: 47209 | AR2: 47239 | AS2: 47270 | AT2: 47300 | AU2: 47331 | AV2: 47362 | AW2: 47392 | AX2: 47423 | AY2: 47453 | AZ2: 47484 | BA2: 47515 | BB2: 47543 | BC2: 47574 | BD2: 47604 | BE2: 47635 | BF2: 47665 | BG2: 47696 | BH2: 47727 | BI2: 47757 | BJ2: 47788 | BK2: 47818
A3: Cuotas | D3: ='Flujo 5 años C12'!E30 | E3: 0 | F3: 0 | G3: 0 | H3: 0 | I3: 0 | J3: 0 | K3: 0 | L3: 0 | M3: 0 | N3: 0 | O3: 0 | P3: 0 | Q3: 0 | R3: 0 | S3: 0 | T3: 0 | U3: 0 | V3: 0 | W3: 0 | X3: 0 | Y3: 0 | Z3: 0 | AA3: 0 | AB3: ='Flujo 5 años C20'!H30 | AC3: 0 | AD3: 0 | AE3: 0 | AF3: 0 | AG3: 0 | AH3: 0 | AI3: 0 | AJ3: 0 | AK3: 0 | AL3: 0 | AM3: 0 | AN3: ='Flujo 5 años C20'!I30 | AO3: 0 | AP3: 0 | AQ3: 0 | AR3: 0 | AS3: 0 | AT3: 0 | AU3: 0 | AV3: 0 | AW3: 0 | AX3: 0 | AY3: 0 | AZ3: ='Flujo 5 años C12'!J30 | BA3: 0 | BB3: 0 | BC3: 0 | BD3: 0 | BE3: 0 | BF3: 0 | BG3: 0 | BH3: 0 | BI3: 0 | BJ3: 0 | BK3: 0
C4: Amortización | D4: 0 | E4: 0 | F4: 0 | G4: 0 | H4: 0 | I4: 0 | J4: 0 | K4: 0 | L4: 0 | M4: 0 | N4: 0 | O4: 0 | P4: 0 | Q4: 0 | R4: 0 | S4: 0 | T4: 0 | U4: 0 | V4: 0 | W4: 0 | X4: 0 | Y4: 0 | Z4: 0 | AA4: 0 | AB4: 0 | AC4: 0 | AD4: 0 | AE4: 0 | AF4: 0 | AG4: 0 | AH4: 0 | AI4: 0 | AJ4: 0 | AK4: 0 | AL4: 0 | AM4: 0 | AN4: 0 | AO4: 0 | AP4: 0 | AQ4: 0 | AR4: 0 | AS4: 0 | AT4: 0 | AU4: 0 | AV4: 0 | AW4: 0 | AX4: 0 | AY4: 0 | AZ4: 0 | BA4: 0 | BB4: 0 | BC4: 0 | BD4: 0 | BE4: 0 | BF4: 0 | BG4: 0 | BH4: 0 | BI4: 0 | BJ4: 0 | BK4: 0
C5: Saldo de Capital | D5: =D3 | E5: =D5+E4+E3 | F5: =E5+F4+F3 | G5: =F5+G4+G3 | H5: =G5+H4+H3 | I5: =H5+I4+I3 | J5: =I5+J4+J3 | K5: =J5+K4+K3 | L5: =K5+L4+L3 | ... BK5: =BJ5+BK4+BK3
E7: =D5*$B$1/12 | F7: =E5*$B$1/12 | G7: =F5*$B$1/12 | H7: =G5*$B$1/12 | I7: =H5*$B$1/12 | J7: =I5*$B$1/12 | K7: =J5*$B$1/12 | L7: =K5*$B$1/12 | ... BK7: =BJ5*$B$1/12 | BL7: =SUM(E7:BK7)
G8: =SUM(E7:G7) | J8: =SUM(H7:J7) | M8: =SUM(K7:M7) | P8: =SUM(N7:P7) | S8: =SUM(Q7:S7) | V8: =SUM(T7:V7) | Y8: =SUM(W7:Y7) | AB8: =SUM(Z7:AB7) | AE8: =SUM(AC7:AE7) | AH8: =SUM(AF7:AH7) | AK8: =SUM(AI7:AK7) | AN8: =SUM(AL7:AN7) | AQ8: =SUM(AO7:AQ7) | AT8: =SUM(AR7:AT7) | AW8: =SUM(AU7:AW7) | AZ8: =SUM(AX7:AZ7) | BC8: =SUM(BA7:BC7) | BF8: =SUM(BD7:BF7) | BI8: =SUM(BG7:BI7) | BK8: =SUM(BJ7:BK7) | BL8: =SUM(E8:BK8)
O9: =SUM(D8:O8) | AA9: =SUM(P8:AA8) | AM9: =SUM(AB8:AM8) | AY9: =SUM(AN8:AY8) | BK9: =SUM(AZ8:BK8) | BL9: =SUM(E9:BK9)

Sheet Resumen.IA
C2: Factores | E2: Proyecto a 5 años Perfil 12 | G2: Proyecto a 5 años Perfil 20 | J2: Deuda | K2: Monto (UF)
C4: Cant. Deptos | E4: 15 | J4: Deuda Actual | K4: 115446
C5: Valor Total Lista Deptos + Est + Bod | E5: ='IVA Dptos'!$F$48 | J5: Deptos MAISA (15) | K5: ='Crédito Comercial 12A'!D4
C6: Valor Financ. Itaú (72%) | E6: ='Crédito Comercial 12A'!$D$3 | J6: Deptos F.Esc/Bco Alzante/Ingreso CBR | K6: 46478
C7: Descuento Inmobiliaria | E7: 0.28 | J7: Saldo | K7: =K4-K5-K6
C8: Cuota de Alzamiento | E8: 8% - Se encuentra en negociación con el stder un crédito paralelo por uf 10.000
C9: Recuperación del IVA | E9: =SUM('Flujo 5 años C12'!F4:F5)
C10: Colocación de los deptos | E10: 1er año, colocación en 6 meses. El resto de los años una vacancia del 10%
C11: Ingreso Total Arriendos | E11: ='Flujo 5 años C12'!N3
C12: Dividendos Totales | E12: ='Flujo 5 años C12'!N13 | G12: ='Flujo 5 años C20'!N13
C13: Prepago de Capital al año 5 | E13: ='Flujo 5 años C12'!J28 | G13: ='Flujo 5 años C20'!J28
C14: Necesidad de nuevo financiamiento | E14: ='Flujo 5 años C12'!N30 | G14: ='Flujo 5 años C20'!N30
C15: Venta al año 5 (90% del Precio de lista actual) | E15: ='Flujo 5 años C12'!J6
C16: Utilidad | E16: ='Flujo 5 años C12'!M38 | G16: ='Flujo 5 años C20'!M38

Sheet IVA Dptos.IA
B1: uf tomada | C1: =39850
B2: iva | C2: 0.18 | H2: VENTA 15 DEPARTAMENTOS (INCLUYE ESTACIONAMIENTOS Y BODEGAS)
B3: Descuento | C3: 0.28
M6: ESTACIONAMIENTO | O6: BODEGA | Q6: UF TOTAL | R6: COMPRADOR
C7: N° | D7: Precio con dcto | E7: IVA (uf) | F7: Construcción | G7: Neto | H7: Avalúo Fiscal | I7: % A. Fiscal | J7: Valor de terreno (uf) | K7: Valor de terreno (pesos) | L7: IVA real | M7: UF | N7: 28% Desc | O7: UF | P7: 28% Desc | Q7: Venta Total con Dcto (D+E+B) | T7: Cuota Alzamiento | V7: Dif. Prrecio con Dcto y Cuota de Alz | X7: Precio Lista Deptos | Y7: Tip | AA7: Roles | AC7: Descuento | AD7: Venta Total Sin descuento
B8: =1 | C8: 702 | D8: =X8-(X8*$C$3) | E8: =(D8/1.18)*0.18 | F8: =E8/0.19 | G8: =(D8/(1+$C$2))*$C$1 | H8: 67066428 | I8: =H8/G8 | J8: =(D8-E8-F8) | K8: =(D8-E8-F8)*$C$1 | L8: =E8*$C$1 | M8: 495 | N8: =+M8-(M8*$C$3) | O8: 91 | P8: =+O8-(O8*$C$3) | Q8: =(D8+N8+P8) | T8: 4546.4 | V8: =+Q8-T8 | X8: 5097 | Y8: 3 | AA8: 04940-00151 | AC8: =+X8*$C$3 | AD8: =X8+M8+O8
B9: =+B8+1 | C9: 803 | D9: =X9-(X9*$C$3) | E9: =(D9/1.18)*0.18 | F9: =E9/0.19 | G9: =(D9/(1+$C$2))*$C$1 | H9: 66118964 | I9: =H9/G9 | J9: =(D9-E9-F9) | K9: =(D9-E9-F9)*$C$1 | L9: =E9*$C$1 | M9: 495 | N9: =+M9-(M9*$C$3) | O9: 91 | P9: =+O9-(O9*$C$3) | Q9: =(D9+N9+P9) | T9: 4572.8 | V9: =+Q9-T9 | X9: 5130 | Y9: 3 | AA9: 04940-00150 | AC9: =+X9*$C$3 | AD9: =X9+M9+O9
B10: =+B9+1 | C10: 903 | D10: =X10-(X10*$C$3) | E10: =(D10/1.18)*0.18 | F10: =E10/0.19 | G10: =(D10/(1+$C$2))*$C$1 | H10: 66118964 | I10: =H10/G10 | J10: =(D10-E10-F10) | K10: =(D10-E10-F10)*$C$1 | L10: =E10*$C$1 | M10: 495 | N10: =+M10-(M10*$C$3) | O10: 91 | P10: =+O10-(O10*$C$3) | Q10: =(D10+N10+P10) | T10: 4733.6 | V10: =+Q10-T10 | X10: 5331 | Y10: 3 | AA10: 04940-00155 | AC10: =+X10*$C$3 | AD10: =X10+M10+O10
B11: =+B10+1 | C11: 1002 | D11: =X11-(X11*$C$3) | E11: =(D11/1.18)*0.18 | F11: =E11/0.19 | G11: =(D11/(1+$C$2))*$C$1 | H11: 67066428 | I11: =H11/G11 | J11: =(D11-E11-F11) | K11: =(D11-E11-F11)*$C$1 | L11: =E11*$C$1 | M11: 495 | N11: =+M11-(M11*$C$3) | O11: 91 | P11: =+O11-(O11*$C$3) | Q11: =(D11+N11+P11) | T11: 4641.6 | V11: =+Q11-T11 | X11: 5216 | Y11: 3 | AA11: 04940-00160 | AC11: =+X11*$C$3 | AD11: =X11+M11+O11
B12: =+B11+1 | C12: 1003 | D12: =X12-(X12*$C$3) | E12: =(D12/1.18)*0.18 | F12: =E12/0.19 | G12: =(D12/(1+$C$2))*$C$1 | H12: 66118964 | I12: =H12/G12 | J12: =(D12-E12-F12) | K12: =(D12-E12-F12)*$C$1 | L12: =E12*$C$1 | M12: 495 | N12: =+M12-(M12*$C$3) | O12: 91 | P12: =+O12-(O12*$C$3) | Q12: =(D12+N12+P12) | T12: 4637.6 | V12: =+Q12-T12 | X12: 5211 | Y12: 3 | AA12: 04940-00164 | AC12: =+X12*$C$3 | AD12: =X12+M12+O12
B13: =+B12+1 | C13: 1301 | D13: =X13-(X13*$C$3) | E13: =(D13/1.18)*0.18 | F13: =E13/0.19 | G13: =(D13/(1+$C$2))*$C$1 | H13: 42776326 | I13: =H13/G13 | J13: =(D13-E13-F13) | K13: =(D13-E13-F13)*$C$1 | L13: =E13*$C$1 | M13: 495 | N13: =+M13-(M13*$C$3) | O13: 91 | P13: =+O13-(O13*$C$3) | Q13: =(D13+N13+P13) | T13: 3912.8 | V13: =+Q13-T13 | X13: 4305 | Y13: 2 | AA13: 04940-00159 | AC13: =+X13*$C$3 | AD13: =X13+M13+O13
B14: =+B13+1 | C14: 1302 | D14: =X14-(X14*$C$3) | E14: =(D14/1.18)*0.18 | F14: =E14/0.19 | G14: =(D14/(1+$C$2))*$C$1 | H14: 67066428 | I14: =H14/G14 | J14: =(D14-E14-F14) | K14: =(D14-E14-F14)*$C$1 | L14: =E14*$C$1 | M14: 495 | N14: =+M14-(M14*$C$3) | O14: 91 | P14: =+O14-(O14*$C$3) | Q14: =(D14+N14+P14) | T14: 4694.4 | V14: =+Q14-T14 | X14: 5282 | Y14: 3 | AA14: 04940-00173 | AC14: =+X14*$C$3 | AD14: =X14+M14+O14
B15: =+B14+1 | C15: 1303 | D15: =X15-(X15*$C$3) | E15: =(D15/1.18)*0.18 | F15: =E15/0.19 | G15: =(D15/(1+$C$2))*$C$1 | H15: 66118964 | I15: =H15/G15 | J15: =(D15-E15-F15) | K15: =(D15-E15-F15)*$C$1 | L15: =E15*$C$1 | M15: 495 | N15: =+M15-(M15*$C$3) | O15: 91 | P15: =+O15-(O15*$C$3) | Q15: =(D15+N15+P15) | T15: 4612 | V15: =+Q15-T15 | X15: 5179 | Y15: 3 | AA15: 04940-00177 | AC15: =+X15*$C$3 | AD15: =X15+M15+O15
B16: =+B15+1 | C16: 1304 | D16: =X16-(X16*$C$3) | E16: =(D16/1.18)*0.18 | F16: =E16/0.19 | G16: =(D16/(1+$C$2))*$C$1 | H16: 49427883 | I16: =H16/G16 | J16: =(D16-E16-F16) | K16: =(D16-E16-F16)*$C$1 | L16: =E16*$C$1 | M16: 495 | N16: =+M16-(M16*$C$3) | O16: 91 | P16: =+O16-(O16*$C$3) | Q16: =(D16+N16+P16) | T16: 3937.6 | V16: =+Q16-T16 | X16: 4336 | Y16: 2 | AA16: 04940-00132 | AC16: =+X16*$C$3 | AD16: =X16+M16+O16
B17: =+B16+1 | C17: 1309 | D17: =X17-(X17*$C$3) | E17: =(D17/1.18)*0.18 | F17: =E17/0.19 | G17: =(D17/(1+$C$2))*$C$1 | H17: 45765170 | I17: =H17/G17 | J17: =(D17-E17-F17) | K17: =(D17-E17-F17)*$C$1 | L17: =E17*$C$1 | M17: 495 | N17: =+M17-(M17*$C$3) | O17: 91 | P17: =+O17-(O17*$C$3) | Q17: =(D17+N17+P17) | T17: 3974.4 | V17: =+Q17-T17 | X17: 4382 | Y17: 2 | AC17: =+X17*$C$3 | AD17: =X17+M17+O17
