Workbook

Sheet Resumen
C2: Factores | E2: Proyecto a 5 años Perfil 12 | G2: Proyecto a 5 años Perfil 20 | J2: Deuda | K2: Monto (UF)
C4: Cant. Deptos | E4: 15 | J4: Deuda Actual | K4: 115446
C5: Valor Total Lista Deptos + Est + Bod | E5: ='IVA Dptos'!$F$48 -> 83063 | G5: ='IVA Dptos'!$F$48 -> 83063 | J5: Deptos MAISA (15) | K5: ='Crédito Comercial 12A'!D4 -> 59805.36
C6: Valor Financ. Itaú (72%) | E6: ='Crédito Comercial 12A'!$D$3 -> 59805.36 | G6: ='Crédito Comercial 12A'!$D$3 -> 59805.36 | J6: Deptos F.Esc/Bco Alzante/Ingreso CBR | K6: 46478
C7: Descuento Inmobiliaria | E7: 0.28 | G7: 0.25 | J7: Saldo | K7: =K4-K5-K6 -> 9162.64
C8: Cuota de Alzamiento | E8: 8% - Se encuentra en negociación con el stder un crédito paralelo por uf 10.000
C9: Recuperación del IVA | E9: =SUM('Flujo 5 años C12'!F4:F5) -> 8336.2368 | G9: =SUM('Flujo 5 años C20'!F4:F5) -> 8336.2368
C10: Colocación de los deptos | E10: 1er año, colocación en 6 meses. El resto de los años una vacancia del 10%
C11: Ingreso Total Arriendos | E11: ='Flujo 5 años C12'!N3 -> 13068.242
C12: Dividendos Totales | E12: ='Flujo 5 años C12'!N13 -> 33188.042 | G12: ='Flujo 5 años C20'!N13 -> 23681.334
C13: Prepago de Capital al año 5 | E13: ='Flujo 5 años C12'!J28 -> 39135.248 | G13: ='Flujo 5 años C20'!J28 -> 49910.481
C14: Necesidad de nuevo financiamiento | E14: ='Flujo 5 años C12'!N30 -> 13000 | G14: ='Flujo 5 años C20'!N30 -> 4500
C15: Venta al año 5 (90% del Precio de lista actual) | E15: ='Flujo 5 años C12'!J6 -> 74756.7
C16: Utilidad | E16: ='Flujo 5 años C12'!M38 -> 10075.894 | G16: ='Flujo 5 años C20'!M38 -> 10234.869

Sheet IVA Dptos
B1: uf tomada | C1: =39850 -> 39850
B2: iva | C2: 0.18 | H2: VENTA 15 DEPARTAMENTOS (INCLUYE ESTACIONAMIENTOS Y BODEGAS)
B3: Descuento | C3: 0.28
M6: ESTACIONAMIENTO | O6: BODEGA | Q6: UF TOTAL | R6: COMPRADOR
C7: N° | D7: Precio con dcto | E7: IVA (uf) | F7: Construcción | G7: Neto | H7: Avalúo Fiscal | I7: % A. Fiscal | J7: Valor de terreno (uf) | K7: Valor de terreno (pesos) | L7: IVA real | M7: UF | N7: 28% Desc | O7: UF | P7: 28% Desc | Q7: Venta Total con Dcto (D+E+B) | T7: Cuota Alzamiento | V7: Dif. Prrecio con Dcto y Cuota de Alz | X7: Precio Lista Deptos | Y7: Tip | AA7: Roles | AC7: Descuento | AD7: Venta Total Sin descuento
B8: =1 -> 1 | C8: 702 | D8: =X8-(X8*$C$3) -> 3669.84 | E8: =(D8/1.18)*0.18 -> 559.8061 | F8: =E8/0.19 -> 2946.3479 | G8: =(D8/(1+$C$2))*$C$1 -> 1.2393485e+08 | H8: 67066428 | I8: =H8/G8 -> 0.5411426 | J8: =(D8-E8-F8) -> 163.68599 | K8: =(D8-E8-F8)*$C$1 -> 6522886.9 | L8: =E8*$C$1 -> 22308273 | M8: 495 | N8: =+M8-(M8*$C$3) -> 356.4 | O8: 91 | P8: =+O8-(O8*$C$3) -> 65.52 | Q8: =(D8+N8+P8) -> 4091.76 | T8: 4546.4 | V8: =+Q8-T8 -> -454.64 | X8: 5097 | Y8: 3 | AA8: 04940-00151 | AC8: =+X8*$C$3 -> 1427.16 | AD8: =X8+M8+O8 -> 5683
B9: =+B8+1 -> 2 | C9: 803 | D9: =X9-(X9*$C$3) -> 3693.6 | E9: =(D9/1.18)*0.18 -> 563.43051 | F9: =E9/0.19 -> 2965.4237 | G9: =(D9/(1+$C$2))*$C$1 -> 1.2473725e+08 | H9: 66118964 | I9: =H9/G9 -> 0.53006589 | J9: =(D9-E9-F9) -> 164.74576 | K9: =(D9-E9-F9)*$C$1 -> 6565118.6 | L9: =E9*$C$1 -> 22452706 | M9: 495 | N9: =+M9-(M9*$C$3) -> 356.4 | O9: 91 | P9: =+O9-(O9*$C$3) -> 65.52 | Q9: =(D9+N9+P9) -> 4115.52 | T9: 4572.8 | V9: =+Q9-T9 -> -457.28 | X9: 5130 | Y9: 3 | AA9: 04940-00150 | AC9: =+X9*$C$3 -> 1436.4 | AD9: =X9+M9+O9 -> 5716
B10: =+B9+1 -> 3 | C10: 903 | D10: =X10-(X10*$C$3) -> 3838.32 | E10: =(D10/1.18)*0.18 -> 585.50644 | F10: =E10/0.19 -> 3081.6128 | G10: =(D10/(1+$C$2))*$C$1 -> 1.2962462e+08 | H10: 66118964 | I10: =H10/G10 -> 0.51008029 | J10: =(D10-E10-F10) -> 171.20071 | K10: =(D10-E10-F10)*$C$1 -> 6822348.4 | L10: =E10*$C$1 -> 23332432 | M10: 495 | N10: =+M10-(M10*$C$3) -> 356.4 | O10: 91 | P10: =+O10-(O10*$C$3) -> 65.52 | Q10: =(D10+N10+P10) -> 4260.24 | T10: 4733.6 | V10: =+Q10-T10 -> -473.36 | X10: 5331 | Y10: 3 | AA10: 04940-00155 | AC10: =+X10*$C$3 -> 1492.68 | AD10: =X10+M10+O10 -> 5917
B11: =+B10+1 -> 4 | C11: 1002 | D11: =X11-(X11*$C$3) -> 3755.52 | E11: =(D11/1.18)*0.18 -> 572.87593 | F11: =E11/0.19 -> 3015.1365 | G11: =(D11/(1+$C$2))*$C$1 -> 1.2682837e+08 | H11: 67066428 | I11: =H11/G11 -> 0.52879675 | J11: =(D11-E11-F11) -> 167.50758 | K11: =(D11-E11-F11)*$C$1 -> 6675177.2 | L11: =E11*$C$1 -> 22829106 | M11: 495 | N11: =+M11-(M11*$C$3) -> 356.4 | O11: 91 | P11: =+O11-(O11*$C$3) -> 65.52 | Q11: =(D11+N11+P11) -> 4177.44 | T11: 4641.6 | V11: =+Q11-T11 -> -464.16 | X11: 5216 | Y11: 3 | AA11: 04940-00160 | AC11: =+X11*$C$3 -> 1460.48 | AD11: =X11+M11+O11 -> 5802
B12: =+B11+1 -> 5 | C12: 1003 | D12: =X12-(X12*$C$3) -> 3751.92 | E12: =(D12/1.18)*0.18 -> 572.32678 | F12: =E12/0.19 -> 3012.2462 | G12: =(D12/(1+$C$2))*$C$1 -> 1.2670679e+08 | H12: 66118964 | I12: =H12/G12 -> 0.52182653 | J12: =(D12-E12-F12) -> 167.34701 | K12: =(D12-E12-F12)*$C$1 -> 6668778.4 | L12: =E12*$C$1 -> 22807222 | M12: 495 | N12: =+M12-(M12*$C$3) -> 356.4 | O12: 91 | P12: =+O12-(O12*$C$3) -> 65.52 | Q12: =(D12+N12+P12) -> 4173.84 | T12: 4637.6 | V12: =+Q12-T12 -> -463.76 | X12: 5211 | Y12: 3 | AA12: 04940-00164 | AC12: =+X12*$C$3 -> 1459.08 | AD12: =X12+M12+O12 -> 5797
B13: =+B12+1 -> 6 | C13: 1301 | D13: =X13-(X13*$C$3) -> 3099.6 | E13: =(D13/1.18)*0.18 -> 472.82034 | F13: =E13/0.19 -> 2488.5281 | G13: =(D13/(1+$C$2))*$C$1 -> 1.0467717e+08 | H13: 42776326 | I13: =H13/G13 -> 0.40865001 | J13: =(D13-E13-F13) -> 138.25156 | K13: =(D13-E13-F13)*$C$1 -> 5509324.7 | L13: =E13*$C$1 -> 18841891 | M13: 495 | N13: =+M13-(M13*$C$3) -> 356.4 | O13: 91 | P13: =+O13-(O13*$C$3) -> 65.52 | Q13: =(D13+N13+P13) -> 3521.52 | T13: 3912.8 | V13: =+Q13-T13 -> -391.28 | X13: 4305 | Y13: 2 | AA13: 04940-00159 | AC13: =+X13*$C$3 -> 1205.4 | AD13: =X13+M13+O13 -> 4891
B14: =+B13+1 -> 7 | C14: 1302 | D14: =X14-(X14*$C$3) -> 3803.04 | E14: =(D14/1.18)*0.18 -> 580.12475 | F14: =E14/0.19 -> 3053.2881 | G14: =(D14/(1+$C$2))*$C$1 -> 1.2843317e+08 | H14: 67066428 | I14: =H14/G14 -> 0.52218929 | J14: =(D14-E14-F14) -> 169.62712 | K14: =(D14-E14-F14)*$C$1 -> 6759640.7 | L14: =E14*$C$1 -> 23117971 | M14: 495 | N14: =+M14-(M14*$C$3) -> 356.4 | O14: 91 | P14: =+O14-(O14*$C$3) -> 65.52 | Q14: =(D14+N14+P14) -> 4224.96 | T14: 4694.4 | V14: =+Q14-T14 -> -469.44 | X14: 5282 | Y14: 3 | AA14: 04940-00173 | AC14: =+X14*$C$3 -> 1478.96 | AD14: =X14+M14+O14 -> 5868
B15: =+B14+1 -> 8 | C15: 1303 | D15: =X15-(X15*$C$3) -> 3728.88 | E15: =(D15/1.18)*0.18 -> 568.8122 | F15: =E15/0.19 -> 2993.7484 | G15: =(D15/(1+$C$2))*$C$1 -> 1.259287e+08 | H15: 66118964 | I15: =H15/G15 -> 0.52505079 | J15: =(D15-E15-F15) -> 166.31936 | K15: =(D15-E15-F15)*$C$1 -> 6627826.4 | L15: =E15*$C$1 -> 22667166 | M15: 495 | N15: =+M15-(M15*$C$3) -> 356.4 | O15: 91 | P15: =+O15-(O15*$C$3) -> 65.52 | Q15: =(D15+N15+P15) -> 4150.8 | T15: 4612 | V15: =+Q15-T15 -> -461.2 | X15: 5179 | Y15: 3 | AA15: 04940-00177 | AC15: =+X15*$C$3 -> 1450.12 | AD15: =X15+M15+O15 -> 5765
B16: =+B15+1 -> 9 | C16: 1304 | D16: =X16-(X16*$C$3) -> 3121.92 | E16: =(D16/1.18)*0.18 -> 476.22508 | F16: =E16/0.19 -> 2506.4478 | G16: =(D16/(1+$C$2))*$C$1 -> 1.0543094e+08 | H16: 49427883 | I16: =H16/G16 -> 0.46881762 | J16: =(D16-E16-F16) -> 139.2471 | K16: =(D16-E16-F16)*$C$1 -> 5548997 | L16: =E16*$C$1 -> 18977570 | M16: 495 | N16: =+M16-(M16*$C$3) -> 356.4 | O16: 91 | P16: =+O16-(O16*$C$3) -> 65.52 | Q16: =(D16+N16+P16) -> 3543.84 | T16: 3937.6 | V16: =+Q16-T16 -> -393.76 | X16: 4336 | Y16: 2 | AA16: 04940-00132 | AC16: =+X16*$C$3 -> 1214.08 | AD16: =X16+M16+O16 -> 4922
B17: =+B16+1 -> 10 | C17: 1309 | D17: =X17-(X17*$C$3) -> 3155.04 | E17: =(D17/1.18)*0.18 -> 481.27729 | F17: =E17/0.19 -> 2533.0384 | G17: =(D17/(1+$C$2))*$C$1 -> 1.0654944e+08 | H17: 45765170 | I17: =H17/G17 -> 0.4295205 | J17: =(D17-E17-F17) -> 140.72435 | K17: =(D17-E17-F17)*$C$1 -> 5607865.5 | L17: =E17*$C$1 -> 19178900 | M17: 495 | N17: =+M17-(M17*$C$3) -> 356.4 | O17: 91 | P17: =+O17-(O17*$C$3) -> 65.52 | Q17: =(D17+N17+P17) -> 3576.96 | T17: 3974.4 | V17: =+Q17-T17 -> -397.44 | X17: 4382 | Y17: 2 | AC17: =+X17*$C$3 -> 1226.96 | AD17: =X17+M17+O17 -> 4968
B18: =+B17+1 -> 11 | C18: 1007 | D18: =X18-(X18*$C$3) -> 3864.96 | E18: =(D18/1.18)*0.18 -> 589.57017 | F18: =E18/0.19 -> 3103.0009 | G18: =(D18/(1+$C$2))*$C$1 -> 1.3052428e+08 | H18: 67066428 | I18: =H18/G18 -> 0.51382337 | J18: =(D18-E18-F18) -> 172.38894 | K18: =(D18-E18-F18)*$C$1 -> 6869699.2 | L18: =E18*$C$1 -> 23494371 | M18: 495 | N18: =+M18-(M18*$C$3) -> 356.4 | O18: 91 | P18: =+O18-(O18*$C$3) -> 65.52 | Q18: =(D18+N18+P18) -> 4286.88 | T18: 4763.2 | V18: =+Q18-T18 -> -476.32 | X18: 5368 | Y18: 3 | AC18: =+X18*$C$3 -> 1503.04 | AD18: =X18+M18+O18 -> 5954
B19: =+B18+1 -> 12 | C19: 1104 | D19: =X19-(X19*$C$3) -> 3177.36 | E19: =(D19/1.18)*0.18 -> 484.68203 | F19: =E19/0.19 -> 2550.9581 | G19: =(D19/(1+$C$2))*$C$1 -> 1.0730322e+08 | H19: 49427883 | I19: =H19/G19 -> 0.46063748 | J19: =(D19-E19-F19) -> 141.71989 | K19: =(D19-E19-F19)*$C$1 -> 5647537.7 | L19: =E19*$C$1 -> 19314579 | M19: 495 | N19: =+M19-(M19*$C$3) -> 356.4 | O19: 91 | P19: =+O19-(O19*$C$3) -> 65.52 | Q19: =(D19+N19+P19) -> 3599.28 | T19: 3999.2 | V19: =+Q19-T19 -> -399.92 | X19: 4413 | Y19: 2 | AC19: =+X19*$C$3 -> 1235.64 | AD19: =X19+M19+O19 -> 4999
B20: =+B19+1 -> 13 | C20: 1107 | D20: =X20-(X20*$C$3) -> 3782.16 | E20: =(D20/1.18)*0.18 -> 576.93966 | F20: =E20/0.19 -> 3036.5245 | G20: =(D20/(1+$C$2))*$C$1 -> 1.2772803e+08 | H20: 67066428 | I20: =H20/G20 -> 0.52507212 | J20: =(D20-E20-F20) -> 168.69581 | K20: =(D20-E20-F20)*$C$1 -> 6722527.9 | L20: =E20*$C$1 -> 22991045 | M20: 495 | N20: =+M20-(M20*$C$3) -> 356.4 | O20: 91 | P20: =+O20-(O20*$C$3) -> 65.52 | Q20: =(D20+N20+P20) -> 4204.08 | T20: 4671.2 | V20: =+Q20-T20 -> -467.12 | X20: 5253 | Y20: 3 | AC20: =+X20*$C$3 -> 1470.84 | AD20: =X20+M20+O20 -> 5839
B21: =+B20+1 -> 14 | C21: 1204 | D21: =X21-(X21*$C$3) -> 3248.64 | E21: =(D21/1.18)*0.18 -> 495.55525 | F21: =E21/0.19 -> 2608.1855 | G21: =(D21/(1+$C$2))*$C$1 -> 1.0971043e+08 | H21: 49427883 | I21: =H21/G21 -> 0.4505304 | J21: =(D21-E21-F21) -> 144.8992 | K21: =(D21-E21-F21)*$C$1 -> 5774233 | L21: =E21*$C$1 -> 19747877 | M21: 495 | N21: =+M21-(M21*$C$3) -> 356.4 | O21: 91 | P21: =+O21-(O21*$C$3) -> 65.52 | Q21: =(D21+N21+P21) -> 3670.56 | T21: 4078.4 | V21: =+Q21-T21 -> -407.84 | X21: 4512 | Y21: 2 | AC21: =+X21*$C$3 -> 1263.36 | AD21: =X21+M21+O21 -> 5098
B22: =+B21+1 -> 15 | C22: 1207 | D22: =X22-(X22*$C$3) -> 3785.76 | E22: =(D22/1.18)*0.18 -> 577.48881 | F22: =E22/0.19 -> 3039.4148 | G22: =(D22/(1+$C$2))*$C$1 -> 1.2784961e+08 | H22: 67066428 | I22: =H22/G22 -> 0.52457281 | J22: =(D22-E22-F22) -> 168.85638 | K22: =(D22-E22-F22)*$C$1 -> 6728926.7 | L22: =E22*$C$1 -> 23012929 | M22: 495 | N22: =+M22-(M22*$C$3) -> 356.4 | O22: 91 | P22: =+O22-(O22*$C$3) -> 65.52 | Q22: =(D22+N22+P22) -> 4207.68 | T22: 4675.2 | V22: =+Q22-T22 -> -467.52 | X22: 5258 | Y22: 3 | AA22: 04940-00168 | AC22: =+X22*$C$3 -> 1472.24 | AD22: =X22+M22+O22 -> 5844
D23: =SUM(D8:D22) -> 53476.56 | E23: =(D23/1.18)*0.18 -> 8157.4414 | F23: =SUM(F8:F22) -> 42933.902 | G23: =SUM(G8:G22) -> 1.8059669e+09 | H23: =SUM(H8:H22) -> 903699569 | L23: =SUM(L8:L22) -> 3.2507404e+08 | M23: =SUM(M8:M22) -> 7425 | N23: =SUM(N8:N22) -> 5346 | O23: =SUM(O8:O22) -> 1365 | P23: =SUM(P8:P22) -> 982.8 | Q23: =SUM(Q8:Q22) -> 59805.36 | T23: =SUM(T8:T22) -> 66450.4 | V23: =+Q23-T23 -> -6645.04 | X23: =SUM(X8:X22) -> 74273 | AC23: =SUM(AC8:AC22) -> 20796.44 | AD23: =SUM(AD8:AD22) -> 83063
L24: =L23/C1 -> 8157.4414 | N24: =+M23-N23 -> 2079 | P24: =+O23-P23 -> 382.2
C31: N° | D31: Precio Lista Deptos | E31: Est. UF | F31: Bod UF | H31: Precio 28% dcto | I31: 28% Desc | J31: 28% Desc
C32: 702 | D32: 5097 | E32: 495 | F32: 91 | H32: 3669.84 | I32: 356.4 | J32: 65.52
C33: 803 | D33: 5130 | E33: 495 | F33: 91 | H33: 3693.6 | I33: 356.4 | J33: 65.52
C34: 903 | D34: 5331 | E34: 495 | F34: 91 | H34: 3838.32 | I34: 356.4 | J34: 65.52
C35: 1002 | D35: 5216 | E35: 495 | F35: 91 | H35: 3755.52 | I35: 356.4 | J35: 65.52
C36: 1003 | D36: 5211 | E36: 495 | F36: 91 | H36: 3751.92 | I36: 356.4 | J36: 65.52
C37: 1301 | D37: 4305 | E37: 495 | F37: 91 | H37: 3099.6 | I37: 356.4 | J37: 65.52
C38: 1302 | D38: 5282 | E38: 495 | F38: 91 | H38: 3803.04 | I38: 356.4 | J38: 65.52
C39: 1303 | D39: 5179 | E39: 495 | F39: 91 | H39: 3728.88 | I39: 356.4 | J39: 65.52
C40: 1304 | D40: 4336 | E40: 495 | F40: 91 | H40: 3121.92 | I40: 356.4 | J40: 65.52
C41: 1309 | D41: 4382 | E41: 495 | F41: 91 | H41: 3155.04 | I41: 356.4 | J41: 65.52
C42: 1007 | D42: 5368 | E42: 495 | F42: 91 | H42: 3756.96 | I42: 356.4 | J42: 65.52
C43: 1104 | D43: 4413 | E43: 495 | F43: 91 | H43: 3177.36 | I43: 356.4 | J43: 65.52
... C46: 1207 | D46: 5258 | E46: 495 | F46: 91 | H46: 3785.76 | I46: 356.4 | J46: 65.52
D47: =SUM(D32:D46) -> 74273 | E47: =SUM(E32:E46) -> 7425 | F47: =SUM(F32:F46) -> 1365 | H47: =SUM(H32:H46) -> 53368.56 | I47: =SUM(I32:I46) -> 5346 | J47: =SUM(J32:J46) -> 982.8
F48: =SUM(D47:F47) -> 83063 | J48: =SUM(H47:J47) -> 59697.36 | L48: =J48/F48 -> 0.71869978
F52: =F48*0.08 -> 6645.04

Sheet Hoja1
B2: Unidad | D2: Cuota Alzamiento DEPTO | E2: C.EST | F2: C.BOD | G2: DEPTO+E+B | H2: ='IVA Dptos'!Q7 -> Venta Total con Dcto (D+E+B) | I2: dif | J2: C.A.DENNIS | M2: Unidad | N2: Cuota Alzamiento
A3: 702 | B3: 702 | C3: =CONCATENATE(B3) -> 702 | D3: 4312 | E3: ='IVA Dptos'!M8*0.8 -> 396 | F3: ='IVA Dptos'!O8*0.8 -> 72.8 | G3: =D3+E3+F3 -> 4780.8 | H3: 4091.76 | I3: =H3-G3 -> -689.04 | J3: 4546.4 | K3: =J3-E3-F3 -> 4077.6 | M3: 702 | N3: 3670 | O3: =VLOOKUP(M3,$B$3:$K$17,10,0) -> 4077.6 | P3: =O3-N3 -> 407.6
A4: 803 | B4: 803 | C4: =CONCATENATE(B4) -> 803 | D4: 4349 | E4: ='IVA Dptos'!M9*0.8 -> 396 | F4: ='IVA Dptos'!O9*0.8 -> 72.8 | G4: =D4+E4+F4 -> 4817.8 | H4: 4115.52 | I4: =H4-G4 -> -702.28 | J4: 4572.8 | K4: =J4-E4-F4 -> 4104 | M4: 803 | N4: 3694 | O4: =VLOOKUP(M4,$B$3:$K$17,10,0) -> 4104 | P4: =O4-N4 -> 410
A5: 903 | B5: 903 | C5: =CONCATENATE(B5) -> 903 | D5: 4531 | E5: ='IVA Dptos'!M10*0.8 -> 396 | F5: ='IVA Dptos'!O10*0.8 -> 72.8 | G5: =D5+E5+F5 -> 4999.8 | H5: 4260.24 | I5: =H5-G5 -> -739.56 | J5: 4733.6 | K5: =J5-E5-F5 -> 4264.8 | M5: 903 | N5: 3838 | O5: =VLOOKUP(M5,$B$3:$K$17,10,0) -> 4264.8 | P5: =O5-N5 -> 426.8
A6: 1002 | B6: 1002 | C6: =CONCATENATE(B6) -> 1002 | D6: 4561 | E6: ='IVA Dptos'!M11*0.8 -> 396 | F6: ='IVA Dptos'!O11*0.8 -> 72.8 | G6: =D6+E6+F6 -> 5029.8 | H6: 4177.44 | I6: =H6-G6 -> -852.36 | J6: 4641.6 | K6: =J6-E6-F6 -> 4172.8 | M6: 1002 | N6: 3756 | O6: =VLOOKUP(M6,$B$3:$K$17,10,0) -> 4172.8 | P6: =O6-N6 -> 416.8
A7: 1003 | B7: 1003 | C7: =CONCATENATE(B7) -> 1003 | D7: 4557 | E7: ='IVA Dptos'!M12*0.8 -> 396 | F7: ='IVA Dptos'!O12*0.8 -> 72.8 | G7: =D7+E7+F7 -> 5025.8 | H7: 4173.84 | I7: =H7-G7 -> -851.96 | J7: 4637.6 | K7: =J7-E7-F7 -> 4168.8 | M7: 1003 | N7: 3752 | O7: =VLOOKUP(M7,$B$3:$K$17,10,0) -> 4168.8 | P7: =O7-N7 -> 416.8
A8: 1007 | B8: 1007 | C8: =CONCATENATE(B8) -> 1007 | D8: 4563 | E8: ='IVA Dptos'!M13*0.8 -> 396 | F8: ='IVA Dptos'!O13*0.8 -> 72.8 | G8: =D8+E8+F8 -> 5031.8 | H8: 4286.88 | I8: =H8-G8 -> -744.92 | J8: 3912.8 | K8: =J8-E8-F8 -> 3444 | M8: 1007 | N8: 4831 | O8: =VLOOKUP(M8,$B$3:$K$17,10,0) -> 3444 | P8: =O8-N8 -> -1387
A9: 1104 | B9: 1104 | C9: =CONCATENATE(B9) -> 1104 | D9: 2705 | E9: ='IVA Dptos'!M14*0.8 -> 396 | F9: ='IVA Dptos'!O14*0.8 -> 72.8 | G9: =D9+E9+F9 -> 3173.8 | H9: 3599.28 | I9: =H9-G9 -> 425.48 | J9: 4694.4 | K9: =J9-E9-F9 -> 4225.6 | M9: 1104 | N9: 3177 | O9: =VLOOKUP(M9,$B$3:$K$17,10,0) -> 4225.6 | P9: =O9-N9 -> 1048.6
A10: 1107 | B10: 1107 | C10: =CONCATENATE(B10) -> 1107 | D10: 4450 | E10: ='IVA Dptos'!M15*0.8 -> 396 | F10: ='IVA Dptos'!O15*0.8 -> 72.8 | G10: =D10+E10+F10 -> 4918.8 | H10: 4204.08 | I10: =H10-G10 -> -714.72 | J10: 4612 | K10: =J10-E10-F10 -> 4143.2 | M10: 1107 | N10: 3782 | O10: =VLOOKUP(M10,$B$3:$K$17,10,0) -> 4143.2 | P10: =O10-N10 -> 361.2
A11: 1204 | B11: 1204 | C11: =CONCATENATE(B11) -> 1204 | D11: 3708 | E11: ='IVA Dptos'!M16*0.8 -> 396 | F11: ='IVA Dptos'!O16*0.8 -> 72.8 | G11: =D11+E11+F11 -> 4176.8 | H11: 3670.56 | I11: =H11-G11 -> -506.24 | J11: 3937.6 | K11: =J11-E11-F11 -> 3468.8 | M11: 1204 | N11: 3249 | O11: =VLOOKUP(M11,$B$3:$K$17,10,0) -> 3468.8 | P11: =O11-N11 -> 219.8
A12: 1207 | B12: 1207 | C12: =CONCATENATE(B12) -> 1207 | D12: 4597 | E12: ='IVA Dptos'!M17*0.8 -> 396 | F12: ='IVA Dptos'!O17*0.8 -> 72.8 | G12: =D12+E12+F12 -> 5065.8 | H12: 4207.68 | I12: =H12-G12 -> -858.12 | J12: 3974.4 | K12: =J12-E12-F12 -> 3505.6 | M12: 1207 | N12: 3786 | O12: =VLOOKUP(M12,$B$3:$K$17,10,0) -> 3505.6 | P12: =O12-N12 -> -280.4
A13: 1301 | B13: 1301 | C13: =CONCATENATE(B13) -> 1301 | D13: 3506 | E13: ='IVA Dptos'!M18*0.8 -> 396 | F13: ='IVA Dptos'!O18*0.8 -> 72.8 | G13: =D13+E13+F13 -> 3974.8 | H13: 3521.52 | I13: =H13-G13 -> -453.28 | J13: 4763.2 | K13: =J13-E13-F13 -> 4294.4 | M13: 1301 | N13: 3100 | O13: =VLOOKUP(M13,$B$3:$K$17,10,0) -> 4294.4 | P13: =O13-N13 -> 1194.4
A14: 1302 | B14: 1302 | C14: =CONCATENATE(B14) -> 1302 | D14: 4617 | E14: ='IVA Dptos'!M19*0.8 -> 396 | F14: ='IVA Dptos'!O19*0.8 -> 72.8 | G14: =D14+E14+F14 -> 5085.8 | H14: 4224.96 | I14: =H14-G14 -> -860.84 | J14: 3999.2 | K14: =J14-E14-F14 -> 3530.4 | M14: 1302 | N14: 3803 | O14: =VLOOKUP(M14,$B$3:$K$17,10,0) -> 3530.4 | P14: =O14-N14 -> -272.6
... A17: 1309 | B17: 1309 | C17: =CONCATENATE(B17) -> 1309 | D17: 3690 | E17: ='IVA Dptos'!M22*0.8 -> 396 | F17: ='IVA Dptos'!O22*0.8 -> 72.8 | G17: =D17+E17+F17 -> 4158.8 | H17: 3576.96 | I17: =H17-G17 -> -581.84 | J17: 4675.2 | K17: =J17-E17-F17 -> 4206.4 | M17: 1309 | N17: 3155 | O17: =VLOOKUP(M17,$B$3:$K$17,10,0) -> 4206.4 | P17: =O17-N17 -> 1051.4
D18: =SUM(D3:D17) -> 62255 | E18: =SUM(E3:E17) -> 5940 | F18: =SUM(F3:F17) -> 1092 | G18: =SUM(G3:G17) -> 69287 | I18: =SUM(I3:I17) -> -9481.64

Sheet Arriendo
A1: Valor UF | B1: ='IVA Dptos'!C1 -> 39850 | N1: Valor UF | O1: ='IVA Dptos'!C1 -> 39850
B2: 0.11
D3: Depto | E3: Valor Arriendo | F3: Valor Arriendo | G3: Avalúo fiscal | H3: 11% A.F (año) | I3: 11% A.F (mes) | J3: Arriendo-(11% A.F (mes)) | K3: IVA arriendo | L3: Ingresos arriendo (mes) | N3: TIPOLOGIA | O3: N° | Q3: Arriendo GGCC Incluido | R3: Arriendo U | S3: Total | T3: total uf
C4: =1 -> 1 | D4: 702 | E4: 715206.36 | F4: =E4/$B$1 -> 17.947462 | G4: ='IVA Dptos'!H8/$B$1 -> 1682.9718 | H4: =G4*$B$2 -> 185.1269 | I4: =H4/12 -> 15.427242 | J4: =F4-I4 -> 2.52022 | K4: =J4*19% -> 0.47884179 | L4: =F4-K4 -> 17.46862 | N4: 3 | O4: 15 | Q4: =E4 -> 715206.36 | R4: =Q4/$O$1 -> 17.947462 | S4: =Q4*$O$4 -> 10728095 | T4: =S4/$O$1 -> 269.21193
C5: =+C4+1 -> 2 | D5: 803 | E5: 712738.9 | F5: =E5/$B$1 -> 17.885543 | G5: ='IVA Dptos'!H9/$B$1 -> 1659.1961 | H5: =G5*$B$2 -> 182.51157 | I5: =H5/12 -> 15.209297 | J5: =F5-I5 -> 2.676246 | K5: =J5*19% -> 0.50848673 | L5: =F5-K5 -> 17.377057 | N5: 3
C6: =+C5+1 -> 3 | D6: 903 | E6: 712245.41 | F6: =E6/$B$1 -> 17.87316 | G6: ='IVA Dptos'!H10/$B$1 -> 1659.1961 | H6: =G6*$B$2 -> 182.51157 | I6: =H6/12 -> 15.209297 | J6: =F6-I6 -> 2.6638623 | K6: =J6*19% -> 0.50613383 | L6: =F6-K6 -> 17.367026 | N6: 3 | Q6: Amoblado | R6: Amoblado U | S6: Total | T6: total uf
C7: =+C6+1 -> 4 | D7: 1002 | E7: 715370.85 | F7: =E7/$B$1 -> 17.95159 | G7: ='IVA Dptos'!H11/$B$1 -> 1682.9718 | H7: =G7*$B$2 -> 185.1269 | I7: =H7/12 -> 15.427242 | J7: =F7-I7 -> 2.5243479 | K7: =J7*19% -> 0.47962609 | L7: =F7-K7 -> 17.471964 | N7: 3 | Q7: 2500000 | R7: =Q7/$O$1 -> 62.735257 | S7: =Q7*$O$4 -> 37500000 | T7: =S7/$O$1 -> 941.02886
C8: =+C7+1 -> 5 | D8: 1003 | E8: 712245.41 | F8: =E8/$B$1 -> 17.87316 | G8: ='IVA Dptos'!H12/$B$1 -> 1659.1961 | H8: =G8*$B$2 -> 182.51157 | I8: =H8/12 -> 15.209297 | J8: =F8-I8 -> 2.6638623 | K8: =J8*19% -> 0.50613383 | L8: =F8-K8 -> 17.367026 | N8: 3
C9: =+C8+1 -> 6 | D9: 1301 | E9: 532954.58 | F9: =E9/$B$1 -> 13.374017 | G9: ='IVA Dptos'!H13/$B$1 -> 1073.4335 | H9: =G9*$B$2 -> 118.07769 | I9: =H9/12 -> 9.8398073 | J9: =F9-I9 -> 3.5342097 | K9: =J9*19% -> 0.67149984 | L9: =F9-K9 -> 12.702517 | N9: 2 | Q9: Contribuciones | R9: Contribuciones U | S9: Total | T9: total uf
C10: =+C9+1 -> 7 | D10: 1302 | E10: 715535.35 | F10: =E10/$B$1 -> 17.955718 | G10: ='IVA Dptos'!H14/$B$1 -> 1682.9718 | H10: =G10*$B$2 -> 185.1269 | I10: =H10/12 -> 15.427242 | J10: =F10-I10 -> 2.5284758 | K10: =J10*19% -> 0.48041039 | L10: =F10-K10 -> 17.475307 | N10: 3 | Q10: 20000 | R10: =Q10/$O$1 -> 0.50188206 | S10: =Q10*$O$4 -> 300000 | T10: =S10/$O$1 -> 7.5282309
C11: =+C10+1 -> 8 | D11: 1303 | E11: 712738.9 | F11: =E11/$B$1 -> 17.885543 | G11: ='IVA Dptos'!H15/$B$1 -> 1659.1961 | H11: =G11*$B$2 -> 182.51157 | I11: =H11/12 -> 15.209297 | J11: =F11-I11 -> 2.676246 | K11: =J11*19% -> 0.50848673 | L11: =F11-K11 -> 17.377057 | N11: 3
C12: =+C11+1 -> 9 | D12: 1304 | E12: 618023.18 | F12: =E12/$B$1 -> 15.508737 | G12: ='IVA Dptos'!H16/$B$1 -> 1240.3484 | H12: =G12*$B$2 -> 136.43832 | I12: =H12/12 -> 11.36986 | J12: =F12-I12 -> 4.1388771 | K12: =J12*19% -> 0.78638664 | L12: =F12-K12 -> 14.722351 | N12: 2 | Q12: Dividendo | R12: Dividendo total | S12: Total | T12: total uf
C13: =+C12+1 -> 10 | D13: 1309 | E13: 608050.56 | F13: =E13/$B$1 -> 15.258483 | G13: ='IVA Dptos'!H17/$B$1 -> 1148.4359 | H13: =G13*$B$2 -> 126.32795 | I13: =H13/12 -> 10.527329 | J13: =F13-I13 -> 4.7311545 | K13: =J13*19% -> 0.89891935 | L13: =F13-K13 -> 14.359564 | N13: 2 | Q13: =R13*O1 -> 22042392 | R13: =-'Crédito Comercial 12A'!H8 -> 553.13404 | S13: =Q13 -> 22042392 | T13: =S13/$O$1 -> 553.13404
C14: =+C13+1 -> 11 | D14: 1007 | E14: 715535.68 | F14: =E14/$B$1 -> 17.955726 | G14: ='IVA Dptos'!H18/$B$1 -> 1682.9718 | H14: =G14*$B$2 -> 185.1269 | I14: =H14/12 -> 15.427242 | J14: =F14-I14 -> 2.5284841 | K14: =J14*19% -> 0.48041198 | L14: =F14-K14 -> 17.475314 | N14: 3
C15: =+C14+1 -> 12 | D15: 1104 | E15: 617694.18 | F15: =E15/$B$1 -> 15.500481 | G15: ='IVA Dptos'!H19/$B$1 -> 1240.3484 | H15: =G15*$B$2 -> 136.43832 | I15: =H15/12 -> 11.36986 | J15: =F15-I15 -> 4.1306213 | K15: =J15*19% -> 0.78481804 | L15: =F15-K15 -> 14.715663 | N15: 2 | Q15: Gasto Operacional | R15: gasto operc UF | S15: Total | T15: total uf
C16: =+C15+1 -> 13 | D16: 1107 | E16: 717303.69 | F16: =E16/$B$1 -> 18.000093 | G16: ='IVA Dptos'!H20/$B$1 -> 1682.9718 | H16: =G16*$B$2 -> 185.1269 | I16: =H16/12 -> 15.427242 | J16: =F16-I16 -> 2.5728507 | K16: =J16*19% -> 0.48884163 | L16: =F16-K16 -> 17.511251 | N16: 3 | Q16: =500000 -> 500000 | R16: =Q16/$O$1 -> 12.547051 | S16: =Q16*$O$4 -> 7500000 | T16: =S16/$O$1 -> 188.20577
C17: =+C16+1 -> 14 | D17: 1204 | E17: 616871.7 | F17: =E17/$B$1 -> 15.479842 | G17: ='IVA Dptos'!H21/$B$1 -> 1240.3484 | H17: =G17*$B$2 -> 136.43832 | I17: =H17/12 -> 11.36986 | J17: =F17-I17 -> 4.1099818 | K17: =J17*19% -> 0.78089654 | L17: =F17-K17 -> 14.698945 | N17: 2
C18: =+C17+1 -> 15 | D18: 1207 | E18: 715042.19 | F18: =E18/$B$1 -> 17.943342 | G18: ='IVA Dptos'!H22/$B$1 -> 1682.9718 | H18: =G18*$B$2 -> 185.1269 | I18: =H18/12 -> 15.427242 | J18: =F18-I18 -> 2.5161004 | K18: =J18*19% -> 0.47805908 | L18: =F18-K18 -> 17.465283 | N18: 3 | Q18: Comisión Corredor | R18: Comisión Corredor | S18: Total | T18: total uf
E19: =AVERAGE(E4:E18) -> 675837.13 | F19: =SUM(F4:F18) -> 254.3929 | K19: =SUM(K4:K18) -> 8.8379525 | L19: =F19-K19 -> 245.55494 | O19: =50% -> 0.5 | Q19: =Q4*O19 -> 357603.18 | R19: =Q19/$O$1 -> 8.9737309 | S19: =Q19*$O$4 -> 5364047.7 | T19: =S19/$O$1 -> 134.60596
F20: =+F19*B1 -> 10137557
Q21: Gasto común | R21: ggcc UF | S21: Total | T21: total uf
O22: VER | Q22: 218000 | R22: =Q22/$O$1 -> 5.4705144 | S22: =Q22*$O$4 -> 3270000 | T22: =S22/$O$1 -> 82.057716
Q24: Marketing (Agencia) | R24: Marketing | S24: Total | T24: total uf
Q25: 0 | R25: =Q25/$O$1 -> 0 | S25: =Q25*$O$4 -> 0 | T25: =S25/$O$1 -> 0
Q27: Imprevistos | R27: Imprevistos U | S27: Total | T27: total uf
Q28: 20000 | R28: =Q28/$O$1 -> 0.50188206 | S28: =Q28*$O$4 -> 300000 | T28: =S28/$O$1 -> 7.5282309
Q30: Administración | R30: Admin | S30: Total | T30: total uf
O31: 0.07 | Q31: =Q4*O31 -> 50064.445 | R31: =Q31/$O$1 -> 1.2563223 | S31: =Q31*$O$4 -> 750966.67 | T31: =S31/$O$1 -> 18.844835

Sheet Flujo mensual
E2: 2 | F2: 2 | G2: 2 | H2: 2 | I2: 2
B3: Ingresos | C3: Mes 0 | D3: Mes 1 | E3: Mes 2 | F3: Mes 3 | G3: Mes 4 | H3: Mes 5 | I3: Mes 6 | J3: Mes 7 | K3: Mes 8 | L3: Mes 9 | M3: Mes 10 | N3: Mes 11 | O3: Mes 12 | P3: Total
B4: Arriendos | E4: =SUM(Arriendo!F4:F5) -> 35.833005 | F4: =SUM(Arriendo!F4:F7) -> 71.657755 | G4: =SUM(Arriendo!F4:F9) -> 102.90493 | H4: =SUM(Arriendo!F4:F11) -> 138.74619 | I4: =SUM(Arriendo!F4:F15) -> 202.96962 | J4: =SUM(Arriendo!F4:F18) -> 254.3929 | K4: =J4 -> 254.3929 | L4: =K4 -> 254.3929 | M4: =L4 -> 254.3929 | N4: =M4 -> 254.3929 | O4: =N4 -> 254.3929 | P4: =SUM(C4:O4) -> 2078.4689
B5: C. Fiscal Equip. | G5: =C11*0.19 -> 178.79548 | P5: =SUM(C5:O5) -> 178.79548
B6: C. Fiscal Unidades | G6: ='IVA Dptos'!E23 -> 8157.4414 | P6: =SUM(C6:O6) -> 8157.4414
B7: Total Ingresos | C7: =SUM(C4:C6) -> 0 | D7: =SUM(D4:D6) -> 0 | E7: =SUM(E4:E6) -> 35.833005 | F7: =SUM(F4:F6) -> 71.657755 | G7: =SUM(G4:G6) -> 8439.1418 | H7: =SUM(H4:H6) -> 138.74619 | I7: =SUM(I4:I6) -> 202.96962 | J7: =SUM(J4:J6) -> 254.3929 | ... P7: =SUM(P4:P6) -> 10414.706
B10: Egresos | C10: Mes 0 | D10: Mes 1 | E10: Mes 2 | F10: Mes 3 | G10: Mes 4 | H10: Mes 5 | I10: Mes 6 | J10: Mes 7 | K10: Mes 8 | L10: Mes 9 | M10: Mes 10 | N10: Mes 11 | O10: Mes 12 | P10: Total
B11: Amoblado | C11: =Arriendo!T7 -> 941.02886 | P11: =SUM(C11:O11) -> 941.02886
B12: Contribuciones | G12: =Arriendo!$T$10 -> 7.5282309 | I12: =Arriendo!$T$10 -> 7.5282309 | L12: =Arriendo!$T$10 -> 7.5282309 | N12: =Arriendo!$T$10 -> 7.5282309 | P12: =SUM(C12:O12) -> 30.112923
B13: Dividendo | D13: =-'Crédito Comercial 12A'!$H$8 -> 553.13404 | E13: =-'Crédito Comercial 12A'!$H$8 -> 553.13404 | F13: =-'Crédito Comercial 12A'!$H$8 -> 553.13404 | G13: =-'Crédito Comercial 12A'!$H$8 -> 553.13404 | H13: =-'Crédito Comercial 12A'!$H$8 -> 553.13404 | I13: =-'Crédito Comercial 12A'!$H$8 -> 553.13404 | J13: =-'Crédito Comercial 12A'!$H$8 -> 553.13404 | K13: =-'Crédito Comercial 12A'!$H$8 -> 553.13404 | ... O13: =-'Crédito Comercial 12A'!$H$8 -> 553.13404 | P13: =SUM(C13:O13) -> 6637.6085 | Q13: =+P13-P4 -> 4559.1396
B14: Gasto operacional | C14: =Arriendo!T16 -> 188.20577 | P14: =SUM(C14:O14) -> 188.20577
B15: Comisión corredor | E15: =Arriendo!$R$19*2 -> 17.947462 | F15: =Arriendo!$R$19*2 -> 17.947462 | G15: =Arriendo!$R$19*2 -> 17.947462 | H15: =Arriendo!$R$19*2 -> 17.947462 | I15: =Arriendo!$R$19*4 -> 35.894924 | J15: =Arriendo!$R$19*3 -> 26.921193 | P15: =SUM(C15:O15) -> 134.60596
B16: Gasto común | D16: =Arriendo!$T$22 -> 82.057716 | E16: =Arriendo!$R$22*13 -> 71.116688 | F16: =Arriendo!$R$22*11 -> 60.175659 | G16: =Arriendo!$R$22*9 -> 49.23463 | H16: =Arriendo!$R$22*7 -> 38.293601 | I16: =Arriendo!$R$22*3 -> 16.411543 | J16: 0 | K16: 0 | L16: 0 | M16: 0 | N16: 0 | O16: 0 | P16: =SUM(C16:O16) -> 317.28984
B17: Administración | D17: 0 | E17: =Arriendo!$R$31*2 -> 2.5126447 | F17: =Arriendo!$R$31*4 -> 5.0252893 | G17: =Arriendo!$R$31*6 -> 7.537934 | H17: =Arriendo!$R$31*8 -> 10.050579 | I17: =Arriendo!$R$31*12 -> 15.075868 | J17: =Arriendo!$R$31*15 -> 18.844835 | K17: =J17 -> 18.844835 | L17: =K17 -> 18.844835 | M17: =L17 -> 18.844835 | N17: =M17 -> 18.844835 | O17: =N17 -> 18.844835 | P17: =SUM(C17:O17) -> 153.27132
B18: Marketing | D18: 0 | E18: 0 | F18: 0 | G18: 0 | H18: 0 | I18: 0 | J18: 0 | K18: 0 | L18: 0 | M18: 0 | N18: 0 | O18: 0 | P18: =SUM(C18:O18) -> 0
B19: Imprevistos | D19: =Arriendo!$T$28 -> 7.5282309 | E19: =Arriendo!$T$28 -> 7.5282309 | F19: =Arriendo!$T$28 -> 7.5282309 | G19: =Arriendo!$T$28 -> 7.5282309 | H19: =Arriendo!$T$28 -> 7.5282309 | I19: =Arriendo!$T$28 -> 7.5282309 | J19: =Arriendo!$T$28 -> 7.5282309 | K19: =Arriendo!$T$28 -> 7.5282309 | ... O19: =Arriendo!$T$28 -> 7.5282309 | P19: =SUM(C19:O19) -> 90.33877
B20: IVA | E20: =SUM(Arriendo!K4:K5) -> 0.98732852 | F20: =SUM(Arriendo!K4:K7) -> 1.9730884 | G20: =SUM(Arriendo!K4:K9) -> 3.1507221 | H20: =SUM(Arriendo!$K$4:$K$11) -> 4.1396192 | I20: =SUM(Arriendo!$K$4:$K$15) -> 7.0901552 | J20: =SUM(Arriendo!$K$4:$K$18) -> 8.8379525 | K20: =+J20 -> 8.8379525 | L20: =+K20 -> 8.8379525 | M20: =+L20 -> 8.8379525 | N20: =+M20 -> 8.8379525 | O20: =+N20 -> 8.8379525 | P20: =SUM(C20:O20) -> 70.368629
B21: Total Egresos | C21: =SUM(C11:C20) -> 1129.2346 | D21: =SUM(D11:D20) -> 642.71999 | E21: =SUM(E11:E20) -> 653.22639 | F21: =SUM(F11:F20) -> 645.78377 | G21: =SUM(G11:G20) -> 646.06125 | H21: =SUM(H11:H20) -> 631.09353 | I21: =SUM(I11:I20) -> 642.66299 | J21: =SUM(J11:J20) -> 615.26625 | ... P21: =SUM(P11:P20) -> 8562.8306
B23: Flujo | C23: =C7-C21 -> -1129.2346 | D23: =D7-D21 -> -642.71999 | E23: =E7-E21 -> -617.39339 | F23: =F7-F21 -> -574.12602 | G23: =G7-G21 -> 7793.0805 | H23: =H7-H21 -> -492.34734 | I23: =I7-I21 -> -439.69337 | J23: =J7-J21 -> -360.87336 | ... O23: =O7-O21 -> -333.95216 | P23: =SUM(C23:O23) -> 1851.8752
B24: Flujo acumulado | C24: =C23 -> -1129.2346 | D24: =C24+D23 -> -1771.9546 | E24: =D24+E23 -> -2389.348 | F24: =E24+F23 -> -2963.474 | G24: =F24+G23 -> 4829.6065 | H24: =G24+H23 -> 4337.2592 | I24: =H24+I23 -> 3897.5658 | J24: =I24+J23 -> 3536.6924 | K24: =J24+K23 -> 3202.7403 | ... O24: =N24+O23 -> 1851.8752
E28: 6 | F28: 9 | G28: 13 | H28: 20
E29: 7 | F29: 10 | G29: 15 | H29: 23
E30: 8 | F30: 11 | G30: 17 | H30: 4
E31: 12 | F31: 14 | G31: 18 | H31: 5
E32: 21 | F32: 22 | G32: 19 | H32: 15

Sheet Flujo 5 años C12
D2: Ingresos | E2: Año 0 | F2: Año 1 | G2: Año 2 | H2: Año 3 | I2: Año 4 | J2: Año 5 | K2: Año 6 | L2: Dev. Prest | M2: Dividendo | N2: Total
D3: Arriendos | F3: ='Flujo mensual'!P4 -> 2078.4689 | G3: ='Flujo mensual'!$O$4*12*0.9 -> 2747.4433 | H3: ='Flujo mensual'!$O$4*12*0.9 -> 2747.4433 | I3: ='Flujo mensual'!$O$4*12*0.9 -> 2747.4433 | J3: ='Flujo mensual'!$O$4*12*0.9 -> 2747.4433 | N3: =SUM(F3:M3) -> 13068.242
D4: C. Fiscal Equip. | F4: ='Flujo mensual'!G5 -> 178.79548 | G4: 0 | H4: 0 | I4: 0 | J4: 0 | N4: =SUM(F4:M4) -> 178.79548
D5: C. Fiscal Unidades | F5: ='Flujo mensual'!G6 -> 8157.4414 | G5: 0 | H5: 0 | I5: 0 | J5: 0 | N5: =SUM(F5:M5) -> 8157.4414
D6: Venta propiedades | F6: 0 | G6: 0 | H6: 0 | I6: 0 | J6: ='IVA Dptos'!AD23*0.9 -> 74756.7 | N6: =SUM(F6:M6) -> 74756.7
D7: Total Ingresos | E7: =SUM(E3:E6) -> 0 | F7: =SUM(F3:F6) -> 10414.706 | G7: =SUM(G3:G6) -> 2747.4433 | H7: =SUM(H3:H6) -> 2747.4433 | I7: =SUM(I3:I6) -> 2747.4433 | J7: =SUM(J3:J6) -> 77504.143 | K7: =SUM(K3:K6) -> 0 | L7: =SUM(L3:L6) -> 0 | ... N7: =SUM(N3:N6) -> 96161.179
D9: Egresos | E9: Año 0 | F9: Año 1 | G9: Año 2 | H9: Año 3 | I9: Año 4 | J9: Año 5 | K9: Año 6 | N9: Total
D10: Amoblado | E10: ='Flujo mensual'!C11 -> 941.02886 | F10: 0 | G10: 0 | H10: 0 | I10: 0 | J10: 0 | N10: =SUM(E10:M10) -> 941.02886
D11: Contribuciones | F11: ='Flujo mensual'!$P$12 -> 30.112923 | G11: ='Flujo mensual'!$P$12 -> 30.112923 | H11: ='Flujo mensual'!$P$12 -> 30.112923 | I11: ='Flujo mensual'!$P$12 -> 30.112923 | J11: ='Flujo mensual'!$P$12 -> 30.112923 | N11: =SUM(E11:M11) -> 150.56462
D12: Cuota de alzaminto | E12: ='Crédito Comercial 12A'!D10 -> 0 | N12: =SUM(E12:M12) -> 0
D13: Dividendo | F13: ='Flujo mensual'!$P$13 -> 6637.6085 | G13: ='Flujo mensual'!$P$13 -> 6637.6085 | H13: ='Flujo mensual'!$P$13 -> 6637.6085 | I13: ='Flujo mensual'!$P$13 -> 6637.6085 | J13: ='Flujo mensual'!$P$13 -> 6637.6085 | N13: =SUM(E13:M13) -> 33188.042
D14: Gasto operacional | E14: ='Flujo mensual'!P14 -> 188.20577 | F14: 0 | G14: 0 | H14: 0 | I14: 0 | J14: 0 | N14: =SUM(E14:M14) -> 188.20577
D15: Comisión corredor | F15: ='Flujo mensual'!P15 -> 134.60596 | G15: 0 | H15: 0 | I15: 0 | J15: 0 | N15: =SUM(E15:M15) -> 134.60596
D16: Gasto común | F16: ='Flujo mensual'!P16 -> 317.28984 | G16: 0 | H16: 0 | I16: 0 | J16: 0 | N16: =SUM(E16:M16) -> 317.28984
D17: Administración | F17: ='Flujo mensual'!P17 -> 153.27132 | G17: ='Flujo mensual'!$O$17*12*0.9 -> 203.52422 | H17: ='Flujo mensual'!$O$17*12*0.9 -> 203.52422 | I17: ='Flujo mensual'!$O$17*12*0.9 -> 203.52422 | J17: ='Flujo mensual'!$O$17*12*0.9 -> 203.52422 | N17: =SUM(E17:M17) -> 967.36819
D18: Imprevistos | F18: ='Flujo mensual'!$P$19 -> 90.33877 | G18: ='Flujo mensual'!$P$19 -> 90.33877 | H18: ='Flujo mensual'!$P$19 -> 90.33877 | I18: ='Flujo mensual'!$P$19 -> 90.33877 | J18: ='Flujo mensual'!$P$19 -> 90.33877 | N18: =SUM(E18:M18) -> 451.69385
D19: Costo Financiero Cred. 1 | F19: ='Crédito C12'!O9 -> 67.5 | G19: ='Crédito C12'!AA9 -> 180 | H19: ='Crédito C12'!AM9 -> 412.5 | I19: ='Crédito C12'!AY9 -> 705 | J19: ='Crédito C12'!BK9 -> 910 | N19: =SUM(E19:M19) -> 2275
D20: IVA | F20: ='Flujo mensual'!P20 -> 70.368629 | G20: ='Flujo mensual'!$O$20*12 -> 106.05543 | H20: ='Flujo mensual'!$O$20*12 -> 106.05543 | I20: ='Flujo mensual'!$O$20*12 -> 106.05543 | J20: ='Flujo mensual'!$O$20*12 -> 106.05543 | N20: =SUM(E20:M20) -> 494.59035
D21: Impuesto / Utilidades (se venden al mismo precio) | K21: 0
D22: Total Egresos | E22: =SUM(E10:E21) -> 1129.2346 | F22: =SUM(F10:F21) -> 7501.0959 | G22: =SUM(G10:G21) -> 7247.6398 | H22: =SUM(H10:H21) -> 7480.1398 | I22: =SUM(I10:I21) -> 7772.6398 | J22: =SUM(J10:J21) -> 7977.6398 | K22: =SUM(K10:K21) -> 0 | L22: =SUM(L10:L20) -> 0 | M22: =SUM(M10:M20) -> 0 | N22: =SUM(N10:N20) -> 39108.39
D24: Flujo Anual Proy. Puro (+ C.F.) | E24: =E7-E22 -> -1129.2346 | F24: =F7-F22 -> 2913.6098 | G24: =G7-G22 -> -4500.1965 | H24: =H7-H22 -> -4732.6965 | I24: =I7-I22 -> -5025.1965 | J24: =J7-J22 -> 69526.503 | L24: =L7-L22 -> 0 | M24: =M7-M22 -> 0 | N24: =SUM(E24:M24) -> 57052.789 | P24: =N7-N22-J27-J28 -> 10075.894
D25: Flujo acumulado | E25: =E24 -> -1129.2346 | F25: =E25+F24 -> 1784.3752 | G25: =F25+G24 -> -2715.8214 | H25: =G25+H24 -> -7448.5179 | I25: =H25+I24 -> -12473.714 | J25: =I25+J24 -> 57052.789
D27: Saldo IVA | E27: =E4+E5-E20 -> 0 | F27: =F4+F5-F20 -> 8265.8682 | G27: =F27-G20 -> 8159.8128 | H27: =G27-H20 -> 8053.7574 | I27: =H27-I20 -> 7947.7019 | J27: =I27-J20 -> 7841.6465
D28: Prepago Crédito | J28: ='Crédito Comercial 12A'!K67 -> 39135.248
D30: Finaciamiento | E30: 1500 | G30: 2000 | H30: 4500 | I30: 5000 | N30: =SUM(E30:J30) -> 13000
D31: Dev. Financiamiento | L31: =-N30 -> -13000
D32: Dividendo | M32: =-L36 -> -10075.894
D33: Flujo Financiamiento | E33: =SUM(E30:E32) -> 1500 | F33: =SUM(F30:F32) -> 0 | G33: =SUM(G30:G32) -> 2000 | H33: =SUM(H30:H32) -> 4500 | I33: =SUM(I30:I32) -> 5000 | J33: =SUM(J30:J32) -> 0 | L33: =SUM(L30:L32) -> -13000 | M33: =SUM(M30:M32) -> -10075.894 | N33: =SUM(N30:N32) -> 13000
D35: Flujo caja anual | E35: =+E25+E33 -> 370.76537 | F35: =+F24+F33 -> 2913.6098 | G35: =+G24+G33 -> -2500.1965 | H35: =+H24+H33 -> -232.69655 | I35: =+I24+I33 -> -25.196546 | J35: =+J24-J27-J28+J33 -> 22549.609 | L35: =+L24+L33-L27-L28 -> -13000 | M35: =+M24+M33-M27-M28 -> -10075.894 | N35: =SUM(E35:M35) -> 0
D36: Flujo anual acumulado | E36: =+E35 -> 370.76537 | F36: =+F35+E36 -> 3284.3752 | G36: =+G35+F36 -> 784.17861 | H36: =+H35+G36 -> 551.48206 | I36: =+I35+H36 -> 526.28551 | J36: =+J35+I36 -> 23075.894 | L36: =+L35+J36 -> 10075.894 | M36: =+M35+L36 -> 0
D38: Saldo final Dividendo | M38: =+J25-J27-J28 -> 10075.894
D40: =IRR(E25:J25) -> 0.69793007

Sheet Flujo 5 años C12 (2)
D2: Proyecto a 5 años Perfil 12 | P2: Proyecto a 5 años Perfil 20
D4: Ingresos | E4: Año 0 | F4: Año 1 | G4: Año 2 | H4: Año 3 | I4: Año 4 | J4: Año 5 | K4: Año 6 | L4: Dev. Prest | M4: Dividendo | N4: Total | P4: Ingresos | Q4: Año 0 | R4: Año 1 | S4: Año 2 | T4: Año 3 | U4: Año 4 | V4: Año 5 | W4: Año 6 | X4: Dev. Prest | Y4: Dividendo | Z4: Total
D5: Arriendos | F5: ='Flujo mensual'!P4 -> 2078.4689 | G5: ='Flujo mensual'!$O$4*12*0.9 -> 2747.4433 | H5: ='Flujo mensual'!$O$4*12*0.9 -> 2747.4433 | I5: ='Flujo mensual'!$O$4*12*0.9 -> 2747.4433 | J5: ='Flujo mensual'!$O$4*12*0.9 -> 2747.4433 | N5: =SUM(F5:M5) -> 13068.242 | P5: Arriendos | R5: ='Flujo 5 años C20'!F3 -> 2078.4689 | S5: ='Flujo 5 años C20'!G3 -> 2747.4433 | T5: ='Flujo 5 años C20'!H3 -> 2747.4433 | U5: ='Flujo 5 años C20'!I3 -> 2747.4433 | V5: ='Flujo 5 años C20'!J3 -> 2747.4433 | Z5: =SUM(R5:Y5) -> 13068.242
D6: C. Fiscal Equip. | F6: ='Flujo mensual'!G5 -> 178.79548 | G6: 0 | H6: 0 | I6: 0 | J6: 0 | N6: =SUM(F6:M6) -> 178.79548 | P6: C. Fiscal Equip. | R6: ='Flujo 5 años C20'!F4 -> 178.79548 | S6: 0 | T6: 0 | U6: 0 | V6: 0 | Z6: =SUM(R6:Y6) -> 178.79548
D7: C. Fiscal Unidades | F7: ='Flujo mensual'!G6 -> 8157.4414 | G7: 0 | H7: 0 | I7: 0 | J7: 0 | N7: =SUM(F7:M7) -> 8157.4414 | P7: C. Fiscal Unidades | R7: ='Flujo 5 años C20'!F5 -> 8157.4414 | S7: 0 | T7: 0 | U7: 0 | V7: 0 | Z7: =SUM(R7:Y7) -> 8157.4414
D8: Venta propiedades | F8: 0 | G8: 0 | H8: 0 | I8: 0 | J8: ='IVA Dptos'!AD23 -> 83063 | N8: ='Flujo 5 años C12'!N6 -> 74756.7 | P8: Venta propiedades | R8: 0 | S8: 0 | T8: 0 | U8: 0 | V8: ='Flujo 5 años C20'!J6 -> 74756.7 | Z8: =SUM(R8:Y8) -> 74756.7
D9: Total Ingresos | E9: =SUM(E5:E8) -> 0 | F9: =SUM(F5:F8) -> 10414.706 | G9: =SUM(G5:G8) -> 2747.4433 | H9: =SUM(H5:H8) -> 2747.4433 | I9: =SUM(I5:I8) -> 2747.4433 | J9: =SUM(J5:J8) -> 85810.443 | K9: =SUM(K5:K8) -> 0 | L9: =SUM(L5:L8) -> 0 | ... N9: =SUM(N5:N8) -> 96161.179 | P9: Total Ingresos | Q9: 0 | R9: =SUM(R5:R8) -> 10414.706 | S9: =SUM(S5:S8) -> 2747.4433 | T9: =SUM(T5:T8) -> 2747.4433 | U9: =SUM(U5:U8) -> 2747.4433 | V9: =SUM(V5:V8) -> 77504.143 | W9: 0 | X9: 0 | Y9: 0 | Z9: =SUM(Z5:Z8) -> 96161.179
D11: Egresos | E11: Año 0 | F11: Año 1 | G11: Año 2 | H11: Año 3 | I11: Año 4 | J11: Año 5 | K11: Año 6 | N11: Total | P11: Egresos | Q11: Año 0 | R11: Año 1 | S11: Año 2 | T11: Año 3 | U11: Año 4 | V11: Año 5 | W11: Año 6 | Z11: Total
D12: Amoblado | E12: ='Flujo mensual'!C11 -> 941.02886 | F12: 0 | G12: 0 | H12: 0 | I12: 0 | J12: 0 | N12: =SUM(E12:M12) -> 941.02886 | P12: ='Flujo 5 años C20'!D10 -> Amoblado | Q12: ='Flujo 5 años C20'!E10 -> 941.02886 | R12: ='Flujo 5 años C20'!F10 -> 0 | S12: ='Flujo 5 años C20'!G10 -> 0 | T12: ='Flujo 5 años C20'!H10 -> 0 | U12: ='Flujo 5 años C20'!I10 -> 0 | V12: ='Flujo 5 años C20'!J10 -> 0 | W12: ='Flujo 5 años C20'!K10 -> 0 | ... Y12: ='Flujo 5 años C20'!M10 -> 0 | Z12: =SUM(Q12:Y12) -> 941.02886
D13: Contribuciones | F13: ='Flujo mensual'!$P$12 -> 30.112923 | G13: ='Flujo mensual'!$P$12 -> 30.112923 | H13: ='Flujo mensual'!$P$12 -> 30.112923 | I13: ='Flujo mensual'!$P$12 -> 30.112923 | J13: ='Flujo mensual'!$P$12 -> 30.112923 | N13: =SUM(E13:M13) -> 150.56462 | P13: ='Flujo 5 años C20'!D11 -> Contribuciones | Q13: ='Flujo 5 años C20'!E11 -> 0 | R13: ='Flujo 5 años C20'!F11 -> 30.112923 | S13: ='Flujo 5 años C20'!G11 -> 30.112923 | T13: ='Flujo 5 años C20'!H11 -> 30.112923 | U13: ='Flujo 5 años C20'!I11 -> 30.112923 | V13: ='Flujo 5 años C20'!J11 -> 30.112923 | W13: ='Flujo 5 años C20'!K11 -> 0 | ... Y13: ='Flujo 5 años C20'!M11 -> 0 | Z13: =SUM(Q13:Y13) -> 150.56462
D14: Cuota de alzaminto | E14: ='Crédito Comercial 12A'!D10 -> 0 | N14: =SUM(E14:M14) -> 0 | P14: ='Flujo 5 años C20'!D12 -> Cuota de alzaminto | Q14: ='Flujo 5 años C20'!E12 -> 0 | R14: ='Flujo 5 años C20'!F12 -> 0 | S14: ='Flujo 5 años C20'!G12 -> 0 | T14: ='Flujo 5 años C20'!H12 -> 0 | U14: ='Flujo 5 años C20'!I12 -> 0 | V14: ='Flujo 5 años C20'!J12 -> 0 | W14: ='Flujo 5 años C20'!K12 -> 0 | ... Y14: ='Flujo 5 años C20'!M12 -> 0 | Z14: =SUM(Q14:Y14) -> 0
D15: Dividendo | F15: ='Flujo mensual'!$P$13 -> 6637.6085 | G15: ='Flujo mensual'!$P$13 -> 6637.6085 | H15: ='Flujo mensual'!$P$13 -> 6637.6085 | I15: ='Flujo mensual'!$P$13 -> 6637.6085 | J15: ='Flujo mensual'!$P$13 -> 6637.6085 | N15: =SUM(E15:M15) -> 33188.042 | P15: ='Flujo 5 años C20'!D13 -> Dividendo | Q15: ='Flujo 5 años C20'!E13 -> 0 | R15: ='Flujo 5 años C20'!F13 -> 4736.2669 | S15: ='Flujo 5 años C20'!G13 -> 4736.2669 | T15: ='Flujo 5 años C20'!H13 -> 4736.2669 | U15: ='Flujo 5 años C20'!I13 -> 4736.2669 | V15: ='Flujo 5 años C20'!J13 -> 4736.2669 | W15: ='Flujo 5 años C20'!K13 -> 0 | ... Y15: ='Flujo 5 años C20'!M13 -> 0 | Z15: =SUM(Q15:Y15) -> 23681.334
D16: Gasto operacional | E16: ='Flujo mensual'!P14 -> 188.20577 | F16: 0 | G16: 0 | H16: 0 | I16: 0 | J16: 0 | N16: =SUM(E16:M16) -> 188.20577 | P16: ='Flujo 5 años C20'!D14 -> Gasto operacional | Q16: ='Flujo 5 años C20'!E14 -> 188.20577 | R16: ='Flujo 5 años C20'!F14 -> 0 | S16: ='Flujo 5 años C20'!G14 -> 0 | T16: ='Flujo 5 años C20'!H14 -> 0 | U16: ='Flujo 5 años C20'!I14 -> 0 | V16: ='Flujo 5 años C20'!J14 -> 0 | W16: ='Flujo 5 años C20'!K14 -> 0 | ... Y16: ='Flujo 5 años C20'!M14 -> 0 | Z16: =SUM(Q16:Y16) -> 188.20577
D17: Comisión corredor | F17: ='Flujo mensual'!P15 -> 134.60596 | G17: 0 | H17: 0 | I17: 0 | J17: 0 | N17: =SUM(E17:M17) -> 134.60596 | P17: ='Flujo 5 años C20'!D15 -> Comisión corredor | Q17: ='Flujo 5 años C20'!E15 -> 0 | R17: ='Flujo 5 años C20'!F15 -> 134.60596 | S17: ='Flujo 5 años C20'!G15 -> 0 | T17: ='Flujo 5 años C20'!H15 -> 0 | U17: ='Flujo 5 años C20'!I15 -> 0 | V17: ='Flujo 5 años C20'!J15 -> 0 | W17: ='Flujo 5 años C20'!K15 -> 0 | ... Y17: ='Flujo 5 años C20'!M15 -> 0 | Z17: =SUM(Q17:Y17) -> 134.60596
D18: Gasto común | F18: ='Flujo mensual'!P16 -> 317.28984 | G18: 0 | H18: 0 | I18: 0 | J18: 0 | N18: =SUM(E18:M18) -> 317.28984 | P18: ='Flujo 5 años C20'!D16 -> Gasto común | Q18: ='Flujo 5 años C20'!E16 -> 0 | R18: ='Flujo 5 años C20'!F16 -> 317.28984 | S18: ='Flujo 5 años C20'!G16 -> 0 | T18: ='Flujo 5 años C20'!H16 -> 0 | U18: ='Flujo 5 años C20'!I16 -> 0 | V18: ='Flujo 5 años C20'!J16 -> 0 | W18: ='Flujo 5 años C20'!K16 -> 0 | ... Y18: ='Flujo 5 años C20'!M16 -> 0 | Z18: =SUM(Q18:Y18) -> 317.28984
D19: Administración | F19: ='Flujo mensual'!P17 -> 153.27132 | G19: ='Flujo mensual'!$O$17*12*0.9 -> 203.52422 | H19: ='Flujo mensual'!$O$17*12*0.9 -> 203.52422 | I19: ='Flujo mensual'!$O$17*12*0.9 -> 203.52422 | J19: ='Flujo mensual'!$O$17*12*0.9 -> 203.52422 | N19: =SUM(E19:M19) -> 967.36819 | P19: ='Flujo 5 años C20'!D17 -> Administración | Q19: ='Flujo 5 años C20'!E17 -> 0 | R19: ='Flujo 5 años C20'!F17 -> 153.27132 | S19: ='Flujo 5 años C20'!G17 -> 203.52422 | T19: ='Flujo 5 años C20'!H17 -> 203.52422 | U19: ='Flujo 5 años C20'!I17 -> 203.52422 | V19: ='Flujo 5 años C20'!J17 -> 203.52422 | W19: ='Flujo 5 años C20'!K17 -> 0 | ... Y19: ='Flujo 5 años C20'!M17 -> 0 | Z19: =SUM(Q19:Y19) -> 967.36819
D20: Imprevistos | F20: ='Flujo mensual'!$P$19 -> 90.33877 | G20: ='Flujo mensual'!$P$19 -> 90.33877 | H20: ='Flujo mensual'!$P$19 -> 90.33877 | I20: ='Flujo mensual'!$P$19 -> 90.33877 | J20: ='Flujo mensual'!$P$19 -> 90.33877 | N20: =SUM(E20:M20) -> 451.69385 | P20: ='Flujo 5 años C20'!D18 -> Imprevistos | Q20: ='Flujo 5 años C20'!E18 -> 0 | R20: ='Flujo 5 años C20'!F18 -> 90.33877 | S20: ='Flujo 5 años C20'!G18 -> 90.33877 | T20: ='Flujo 5 años C20'!H18 -> 90.33877 | U20: ='Flujo 5 años C20'!I18 -> 90.33877 | V20: ='Flujo 5 años C20'!J18 -> 90.33877 | W20: ='Flujo 5 años C20'!K18 -> 0 | ... Y20: ='Flujo 5 años C20'!M18 -> 0 | Z20: =SUM(Q20:Y20) -> 451.69385
D21: Costo Financiero Cred. 1 | F21: ='Crédito C12'!O9 -> 67.5 | G21: ='Crédito C12'!AA9 -> 180 | H21: ='Crédito C12'!AM9 -> 412.5 | I21: ='Crédito C12'!AY9 -> 705 | J21: ='Crédito C12'!BK9 -> 910 | N21: =SUM(E21:M21) -> 2275 | P21: ='Flujo 5 años C20'!D19 -> Costo Financiero Cred. 1 | Q21: ='Flujo 5 años C20'!E19 -> 0 | R21: ='Flujo 5 años C20'!F19 -> 67.5 | S21: ='Flujo 5 años C20'!G19 -> 90 | T21: ='Flujo 5 años C20'!H19 -> 135 | U21: ='Flujo 5 años C20'!I19 -> 240 | V21: ='Flujo 5 años C20'!J19 -> 315 | W21: ='Flujo 5 años C20'!K19 -> 0 | ... Y21: ='Flujo 5 años C20'!M19 -> 0 | Z21: =SUM(Q21:Y21) -> 847.5
D22: IVA | F22: ='Flujo mensual'!P20 -> 70.368629 | G22: ='Flujo mensual'!$O$20*12 -> 106.05543 | H22: ='Flujo mensual'!$O$20*12 -> 106.05543 | I22: ='Flujo mensual'!$O$20*12 -> 106.05543 | J22: ='Flujo mensual'!$O$20*12 -> 106.05543 | N22: =SUM(E22:M22) -> 494.59035 | P22: ='Flujo 5 años C20'!D20 -> IVA | Q22: ='Flujo 5 años C20'!E20 -> 0 | R22: ='Flujo 5 años C20'!F20 -> 70.368629 | S22: ='Flujo 5 años C20'!G20 -> 106.05543 | T22: ='Flujo 5 años C20'!H20 -> 106.05543 | U22: ='Flujo 5 años C20'!I20 -> 106.05543 | V22: ='Flujo 5 años C20'!J20 -> 106.05543 | W22: ='Flujo 5 años C20'!K20 -> 0 | ... Y22: ='Flujo 5 años C20'!M20 -> 0 | Z22: =SUM(Q22:Y22) -> 494.59035
D23: Impuesto | K23: 0 | P23: Impuesto | W23: 0 | Z23: =SUM(Q23:Y23) -> 0
D24: Total Egresos | E24: =SUM(E12:E23) -> 1129.2346 | F24: =SUM(F12:F23) -> 7501.0959 | G24: =SUM(G12:G23) -> 7247.6398 | H24: =SUM(H12:H23) -> 7480.1398 | I24: =SUM(I12:I23) -> 7772.6398 | J24: =SUM(J12:J23) -> 7977.6398 | K24: =SUM(K12:K23) -> 0 | L24: =SUM(L12:L22) -> 0 | M24: =SUM(M12:M22) -> 0 | N24: =SUM(N12:N22) -> 39108.39 | P24: Total Egresos | Q24: =SUM(Q12:Q23) -> 1129.2346 | R24: =SUM(R12:R23) -> 5599.7543 | S24: =SUM(S12:S23) -> 5256.2982 | T24: =SUM(T12:T23) -> 5301.2982 | U24: =SUM(U12:U23) -> 5406.2982 | V24: =SUM(V12:V23) -> 5481.2982 | W24: =SUM(W12:W23) -> 0 | X24: =SUM(X12:X23) -> 0 | ... Z24: =SUM(Z12:Z23) -> 28174.182
D26: Flujo Proyecto | E26: =E9-E24 -> -1129.2346 | F26: =F9-F24 -> 2913.6098 | G26: =G9-G24 -> -4500.1965 | H26: =H9-H24 -> -4732.6965 | I26: =I9-I24 -> -5025.1965 | J26: =J9-J24 -> 77832.803 | L26: =L9-L24 -> 0 | M26: =M9-M24 -> 0 | N26: =N9-N24 -> 57052.789 | P26: Flujo Proyecto | Q26: =Q9-Q24 -> -1129.2346 | R26: =R9-R24 -> 4814.9514 | S26: =S9-S24 -> -2508.8549 | T26: =T9-T24 -> -2553.8549 | U26: =U9-U24 -> -2658.8549 | V26: =V9-V24 -> 72022.845 | X26: =X9-X24 -> 0 | Y26: =Y9-Y24 -> 0 | Z26: =SUM(Q26:Y26) -> 67986.997
D27: Flujo acumulado | E27: =E26 -> -1129.2346 | F27: =E27+F26 -> 1784.3752 | G27: =F27+G26 -> -2715.8214 | H27: =G27+H26 -> -7448.5179 | I27: =H27+I26 -> -12473.714 | J27: =I27+J26 -> 65359.089 | P27: Flujo acumulado | Q27: -755.66751 | R27: 3013.0707 | S27: 1099.429 | T27: -859.21275 | U27: -2877.8545 | V27: 47741.804
D29: Saldo IVA | E29: =E6+E7-E22 -> 0 | F29: =F6+F7-F22 -> 8265.8682 | G29: =F29-G22 -> 8159.8128 | H29: =G29-H22 -> 8053.7574 | I29: =H29-I22 -> 7947.7019 | N29: =I29-J22 -> 7841.6465 | P29: Saldo IVA | Q29: =Q6+Q7-Q22 -> 0 | R29: =R6+R7-R22 -> 8265.8682 | S29: =R29-S22 -> 8159.8128 | T29: =S29-T22 -> 8053.7574 | U29: =T29-U22 -> 7947.7019 | Z29: =U29-V22 -> 7841.6465
D30: Prepago Crédito | N30: ='Crédito Comercial 12A'!K67 -> 39135.248 | P30: Prepago Crédito | Z30: ='Crédito Comercial 20A'!K67 -> 49910.481
D32: Finaciamiento | E32: 1000 | G32: 3000 | H32: 4500 | I32: 4500 | N32: =SUM(E32:J32) -> 13000 | P32: Finaciamiento | Q32: ='Flujo 5 años C20'!E30 -> 1500 | R32: ='Flujo 5 años C20'!F30 -> 0 | S32: ='Flujo 5 años C20'!G30 -> 0 | T32: ='Flujo 5 años C20'!H30 -> 1000 | U32: ='Flujo 5 años C20'!I30 -> 2000 | V32: ='Flujo 5 años C20'!J30 -> 0 | W32: ='Flujo 5 años C20'!K30 -> 0 | X32: ='Flujo 5 años C20'!L30 -> 0 | Y32: ='Flujo 5 años C20'!M30 -> 0 | Z32: =SUM(Q32:Y32) -> 4500
D33: Dev. Financiamiento | L33: =-N32 -> -13000 | N33: =-N32 -> -13000 | P33: Dev. Financiamiento | Q33: ='Flujo 5 años C20'!E31 -> 0 | R33: ='Flujo 5 años C20'!F31 -> 0 | S33: ='Flujo 5 años C20'!G31 -> 0 | T33: ='Flujo 5 años C20'!H31 -> 0 | U33: ='Flujo 5 años C20'!I31 -> 0 | V33: ='Flujo 5 años C20'!J31 -> 0 | W33: ='Flujo 5 años C20'!K31 -> 0 | X33: ='Flujo 5 años C20'!L31 -> -4500 | Y33: ='Flujo 5 años C20'!M31 -> 0 | Z33: =SUM(Q33:Y33) -> -4500
D34: Dividendo | M34: =-L38 -> -18382.194 | P34: Dividendo | Y34: -5386.4309
D35: Flujo Financiamiento | E35: =SUM(E32:E34) -> 1000 | F35: =SUM(F32:F34) -> 0 | G35: =SUM(G32:G34) -> 3000 | H35: =SUM(H32:H34) -> 4500 | I35: =SUM(I32:I34) -> 4500 | J35: =SUM(J32:J34) -> 0 | L35: =SUM(L32:L34) -> -13000 | M35: =SUM(M32:M34) -> -18382.194 | N35: =SUM(N32:N34) -> 0 | P35: Flujo Financiamiento | Q35: 1000 | R35: 0 | S35: 0 | T35: 1000 | U35: 1000 | V35: 0 | X35: -3000 | Y35: -5386.4309 | Z35: 3000
D37: Flujo caja anual | E37: =+E27+E35 -> -129.23463 | F37: =+F26+F35 -> 2913.6098 | G37: =+G26+G35 -> -1500.1965 | H37: =+H26+H35 -> -232.69655 | I37: =+I26+I35 -> -525.19655 | J37: =+J26-N29-N30+J35 -> 30855.909 | L37: =+L26+L35-L29-L30 -> -13000 | M37: =+M26+M35-M29-M30 -> -18382.194 | N37: =SUM(E37:M37) -> 0 | P37: Flujo caja anual | Q37: 244.33249 | R37: 3768.7382 | S37: -1913.6417 | T37: -958.64171 | U37: -1018.6417 | V37: 8264.2854 | X37: -3000 | Y37: -5386.4309 | Z37: 0
D38: Flujo anual acumulado | E38: =+E37 -> -129.23463 | F38: =+F37+E38 -> 2784.3752 | G38: =+G37+F38 -> 1284.1786 | H38: =+H37+G38 -> 1051.4821 | I38: =+I37+H38 -> 526.28551 | J38: =+J37+I38 -> 31382.194 | L38: =+L37+J38 -> 18382.194 | M38: =+M37+L38 -> 0 | P38: Flujo anual acumulado | Q38: 244.33249 | R38: 4013.0707 | S38: 2099.429 | T38: 1140.7872 | U38: 122.14553 | V38: 8386.4309 | X38: 5386.4309 | Y38: 0
D40: Saldo final Dividendo | M40: =+J27-N29-N30 -> 18382.194 | N40: =N26-N29-N30 -> 10075.894 | P40: Saldo final Dividendo | Q40: ='Flujo 5 años C20'!E38 -> 0 | R40: ='Flujo 5 años C20'!F38 -> 0 | S40: ='Flujo 5 años C20'!G38 -> 0 | T40: ='Flujo 5 años C20'!H38 -> 0 | U40: ='Flujo 5 años C20'!I38 -> 0 | V40: ='Flujo 5 años C20'!J38 -> 0 | W40: ='Flujo 5 años C20'!K38 -> 0 | X40: ='Flujo 5 años C20'!L38 -> 0 | Y40: ='Flujo 5 años C20'!M38 -> 10234.869 | Z40: =Z26-Z29-Z30 -> 10234.869

Sheet Crédito Comercial 12A
B2: Venta Total (sin descuento) | D2: ='IVA Dptos'!X23+'IVA Dptos'!M23+'IVA Dptos'!O23 -> 83063
B3: Dcto | C3: 0.28 | D3: =D2-D2*C3 -> 59805.36 | E3: =118000 -> 118000 | G3: =E3-D3 -> 58194.64
B4: Crédito UF LTV - 72% | D4: =D3 -> 59805.36
B5: Tasa anual nomial | D5: 0.05
B6: Tasa mensual | D6: =D5/12 -> 0.0041666667 | G6: Período | H6: Cuota | I6: Interés | J6: Capital | K6: S. Insoluto
B7: Períodos | D7: =12*12 -> 144 | G7: 0 | H7: 0 | I7: 0 | J7: 0 | K7: =D4 -> 59805.36
D8: =D7/12 -> 12 | G8: =G7+1 -> 1 | H8: =PMT($D$6,$D$7,$D$4) -> -553.13404 | I8: =-K7*$D$6 -> -249.189 | J8: =H8-I8 -> -303.94504 | K8: =K7+J8 -> 59501.415
G9: =G8+1 -> 2 | H9: =PMT($D$5/12,$D$7,$D$4) -> -553.13404 | I9: =-K8*$D$6 -> -247.92256 | J9: =H9-I9 -> -305.21148 | K9: =K8+J9 -> 59196.203
B10: Cuota de alzamiento | D10: 0 | G10: =G9+1 -> 3 | H10: =PMT($D$5/12,$D$7,$D$4) -> -553.13404 | I10: =-K9*$D$6 -> -246.65085 | J10: =H10-I10 -> -306.48319 | K10: =K9+J10 -> 58889.72
G11: =G10+1 -> 4 | H11: =PMT($D$5/12,$D$7,$D$4) -> -553.13404 | I11: =-K10*$D$6 -> -245.37383 | J11: =H11-I11 -> -307.76021 | K11: =K10+J11 -> 58581.96
G12: =G11+1 -> 5 | H12: =PMT($D$5/12,$D$7,$D$4) -> -553.13404 | I12: =-K11*$D$6 -> -244.0915 | J12: =H12-I12 -> -309.04254 | K12: =K11+J12 -> 58272.918
G13: =G12+1 -> 6 | H13: =PMT($D$5/12,$D$7,$D$4) -> -553.13404 | I13: =-K12*$D$6 -> -242.80382 | J13: =H13-I13 -> -310.33022 | K13: =K12+J13 -> 57962.587
G14: =G13+1 -> 7 | H14: =PMT($D$5/12,$D$7,$D$4) -> -553.13404 | I14: =-K13*$D$6 -> -241.51078 | J14: =H14-I14 -> -311.62326 | K14: =K13+J14 -> 57650.964
G15: =G14+1 -> 8 | H15: =PMT($D$5/12,$D$7,$D$4) -> -553.13404 | I15: =-K14*$D$6 -> -240.21235 | J15: =H15-I15 -> -312.92169 | K15: =K14+J15 -> 57338.042
G16: =G15+1 -> 9 | H16: =PMT($D$5/12,$D$7,$D$4) -> -553.13404 | I16: =-K15*$D$6 -> -238.90851 | J16: =H16-I16 -> -314.22553 | K16: =K15+J16 -> 57023.817
G17: =G16+1 -> 10 | H17: =PMT($D$5/12,$D$7,$D$4) -> -553.13404 | I17: =-K16*$D$6 -> -237.59924 | J17: =H17-I17 -> -315.5348 | K17: =K16+J17 -> 56708.282
G18: =G17+1 -> 11 | H18: =PMT($D$5/12,$D$7,$D$4) -> -553.13404 | I18: =-K17*$D$6 -> -236.28451 | J18: =H18-I18 -> -316.84953 | K18: =K17+J18 -> 56391.432
E19: =SUM(H8:H19) -> -6637.6085 | G19: =G18+1 -> 12 | H19: =PMT($D$5/12,$D$7,$D$4) -> -553.13404 | I19: =-K18*$D$6 -> -234.9643 | J19: =H19-I19 -> -318.16974 | K19: =K18+J19 -> 56073.263
G20: =G19+1 -> 13 | H20: =PMT($D$5/12,$D$7,$D$4) -> -553.13404 | I20: =-K19*$D$6 -> -233.63859 | J20: =H20-I20 -> -319.49545 | K20: =K19+J20 -> 55753.767
G21: =G20+1 -> 14 | H21: =PMT($D$5/12,$D$7,$D$4) -> -553.13404 | I21: =-K20*$D$6 -> -232.30736 | J21: =H21-I21 -> -320.82668 | K21: =K20+J21 -> 55432.941
G22: =G21+1 -> 15 | H22: =PMT($D$5/12,$D$7,$D$4) -> -553.13404 | I22: =-K21*$D$6 -> -230.97059 | J22: =H22-I22 -> -322.16346 | K22: =K21+J22 -> 55110.777
G23: =G22+1 -> 16 | H23: =PMT($D$5/12,$D$7,$D$4) -> -553.13404 | I23: =-K22*$D$6 -> -229.62824 | J23: =H23-I23 -> -323.5058 | K23: =K22+J23 -> 54787.271
G24: =G23+1 -> 17 | H24: =PMT($D$5/12,$D$7,$D$4) -> -553.13404 | I24: =-K23*$D$6 -> -228.2803 | J24: =H24-I24 -> -324.85374 | K24: =K23+J24 -> 54462.418
G25: =G24+1 -> 18 | H25: =PMT($D$5/12,$D$7,$D$4) -> -553.13404 | I25: =-K24*$D$6 -> -226.92674 | J25: =H25-I25 -> -326.2073 | K25: =K24+J25 -> 54136.21
G26: =G25+1 -> 19 | H26: =PMT($D$5/12,$D$7,$D$4) -> -553.13404 | I26: =-K25*$D$6 -> -225.56754 | J26: =H26-I26 -> -327.5665 | K26: =K25+J26 -> 53808.644
G27: =G26+1 -> 20 | H27: =PMT($D$5/12,$D$7,$D$4) -> -553.13404 | I27: =-K26*$D$6 -> -224.20268 | J27: =H27-I27 -> -328.93136 | K27: =K26+J27 -> 53479.712
G28: =G27+1 -> 21 | H28: =PMT($D$5/12,$D$7,$D$4) -> -553.13404 | I28: =-K27*$D$6 -> -222.83214 | J28: =H28-I28 -> -330.30191 | K28: =K27+J28 -> 53149.411
G29: =G28+1 -> 22 | H29: =PMT($D$5/12,$D$7,$D$4) -> -553.13404 | I29: =-K28*$D$6 -> -221.45588 | J29: =H29-I29 -> -331.67816 | K29: =K28+J29 -> 52817.732
G30: =G29+1 -> 23 | H30: =PMT($D$5/12,$D$7,$D$4) -> -553.13404 | I30: =-K29*$D$6 -> -220.07389 | J30: =H30-I30 -> -333.06016 | K30: =K29+J30 -> 52484.672
G31: =G30+1 -> 24 | H31: =PMT($D$5/12,$D$7,$D$4) -> -553.13404 | I31: =-K30*$D$6 -> -218.68613 | J31: =H31-I31 -> -334.44791 | K31: =K30+J31 -> 52150.224
... G66: =G65+1 -> 59 | H66: =PMT($D$5/12,$D$7,$D$4) -> -553.13404 | I66: =-K65*$D$6 -> -166.29392 | J66: =H66-I66 -> -386.84012 | K66: =K65+J66 -> 39523.7
E67: 5 AÑOS | G67: =G66+1 -> 60 | H67: =PMT($D$5/12,$D$7,$D$4) -> -553.13404 | I67: =-K66*$D$6 -> -164.68208 | J67: =H67-I67 -> -388.45196 | K67: =K66+J67 -> 39135.248
G68: =G67+1 -> 61 | H68: =PMT($D$5/12,$D$7,$D$4) -> -553.13404 | I68: =-K67*$D$6 -> -163.06353 | J68: =H68-I68 -> -390.07051 | K68: =K67+J68 -> 38745.178
G69: =G68+1 -> 62 | H69: =PMT($D$5/12,$D$7,$D$4) -> -553.13404 | I69: =-K68*$D$6 -> -161.43824 | J69: =H69-I69 -> -391.6958 | K69: =K68+J69 -> 38353.482
G70: =G69+1 -> 63 | H70: =PMT($D$5/12,$D$7,$D$4) -> -553.13404 | I70: =-K69*$D$6 -> -159.80618 | J70: =H70-I70 -> -393.32787 | K70: =K69+J70 -> 37960.154
G71: =G70+1 -> 64 | H71: =PMT($D$5/12,$D$7,$D$4) -> -553.13404 | I71: =-K70*$D$6 -> -158.16731 | J71: =H71-I71 -> -394.96673 | K71: =K70+J71 -> 37565.187
G72: =G71+1 -> 65 | H72: =PMT($D$5/12,$D$7,$D$4) -> -553.13404 | I72: =-K71*$D$6 -> -156.52161 | J72: =H72-I72 -> -396.61243 | K72: =K71+J72 -> 37168.575
G73: =G72+1 -> 66 | H73: =PMT($D$5/12,$D$7,$D$4) -> -553.13404 | I73: =-K72*$D$6 -> -154.86906 | J73: =H73-I73 -> -398.26498 | K73: =K72+J73 -> 36770.31
G74: =G73+1 -> 67 | H74: =PMT($D$5/12,$D$7,$D$4) -> -553.13404 | I74: =-K73*$D$6 -> -153.20963 | J74: =H74-I74 -> -399.92442 | K74: =K73+J74 -> 36370.386
G75: =G74+1 -> 68 | H75: =PMT($D$5/12,$D$7,$D$4) -> -553.13404 | I75: =-K74*$D$6 -> -151.54327 | J75: =H75-I75 -> -401.59077 | K75: =K74+J75 -> 35968.795
...

Sheet Crédito C12
A1: Tasa | B1: 0.06
A2: Monto | B2: =SUM('Flujo 5 años C12'!E30:I30) -> 13000 | D2: 46023 | E2: 46054 | F2: 46082 | G2: 46113 | H2: 46143 | I2: 46174 | J2: 46204 | K2: 46235 | L2: 46266 | M2: 46296 | N2: 46327 | O2: 46357 | P2: 46388 | Q2: 46419 | R2: 46447 | S2: 46478 | T2: 46508 | U2: 46539 | V2: 46569 | W2: 46600 | X2: 46631 | Y2: 46661 | Z2: 46692 | AA2: 46722 | AB2: 46753 | AC2: 46784 | AD2: 46813 | AE2: 46844 | AF2: 46874 | AG2: 46905 | AH2: 46935 | AI2: 46966 | AJ2: 46997 | AK2: 47027 | AL2: 47058 | AM2: 47088 | AN2: 47119 | AO2: 47150 | AP2: 47178 | AQ2: 47209 | AR2: 47239 | AS2: 47270 | AT2: 47300 | AU2: 47331 | AV2: 47362 | AW2: 47392 | AX2: 47423 | AY2: 47453 | AZ2: 47484 | BA2: 47515 | BB2: 47543 | BC2: 47574 | BD2: 47604 | BE2: 47635 | BF2: 47665 | BG2: 47696 | BH2: 47727 | BI2: 47757 | BJ2: 47788 | BK2: 47818
A3: Cuotas | D3: ='Flujo 5 años C12'!E30 -> 1500 | E3: 0 | F3: 0 | G3: 0 | H3: 0 | I3: 0 | J3: 0 | K3: 0 | L3: 0 | M3: 0 | N3: 0 | O3: 0 | P3: ='Flujo 5 años C12'!G30 -> 2000 | Q3: 0 | R3: 0 | S3: 0 | T3: 0 | U3: 0 | V3: 0 | W3: 0 | X3: 0 | Y3: 0 | Z3: 0 | AA3: 0 | AB3: ='Flujo 5 años C12'!H30 -> 4500 | AC3: 0 | AD3: 0 | AE3: 0 | AF3: 0 | AG3: 0 | AH3: 0 | AI3: 0 | AJ3: 0 | AK3: 0 | AL3: 0 | AM3: 0 | AN3: ='Flujo 5 años C12'!I30 -> 5000 | AO3: 0 | AP3: 0 | AQ3: 0 | AR3: 0 | AS3: 0 | AT3: 0 | AU3: 0 | AV3: 0 | AW3: 0 | AX3: 0 | AY3: 0 | AZ3: ='Flujo 5 años C12'!J30 -> 0 | BA3: 0 | BB3: 0 | BC3: 0 | BD3: 0 | BE3: 0 | BF3: 0 | BG3: 0 | BH3: 0 | BI3: 0 | BJ3: 0 | BK3: 0
C4: Amortización | D4: 0 | E4: 0 | F4: 0 | G4: 0 | H4: 0 | I4: 0 | J4: 0 | K4: 0 | L4: 0 | M4: 0 | N4: 0 | O4: 0 | P4: 0 | Q4: 0 | R4: 0 | S4: 0 | T4: 0 | U4: 0 | V4: 0 | W4: 0 | X4: 0 | Y4: 0 | Z4: 0 | AA4: 0 | AB4: 0 | AC4: 0 | AD4: 0 | AE4: 0 | AF4: 0 | AG4: 0 | AH4: 0 | AI4: 0 | AJ4: 0 | AK4: 0 | AL4: 0 | AM4: 0 | AN4: 0 | AO4: 0 | AP4: 0 | AQ4: 0 | AR4: 0 | AS4: 0 | AT4: 0 | AU4: 0 | AV4: 0 | AW4: 0 | AX4: 0 | AY4: 0 | AZ4: 0 | BA4: 0 | BB4: 0 | BC4: 0 | BD4: 0 | BE4: 0 | BF4: 0 | BG4: 0 | BH4: 0 | BI4: 0 | BJ4: 0 | BK4: 0
C5: Saldo de Capital | D5: =D3 -> 1500 | E5: =D5+E4+E3 -> 1500 | F5: =E5+F4+F3 -> 1500 | G5: =F5+G4+G3 -> 1500 | H5: =G5+H4+H3 -> 1500 | I5: =H5+I4+I3 -> 1500 | J5: =I5+J4+J3 -> 1500 | K5: =J5+K4+K3 -> 1500 | L5: =K5+L4+L3 -> 1500 | ... BK5: =BJ5+BK4+BK3 -> 13000
E7: =D5*$B$1/12 -> 7.5 | F7: =E5*$B$1/12 -> 7.5 | G7: =F5*$B$1/12 -> 7.5 | H7: =G5*$B$1/12 -> 7.5 | I7: =H5*$B$1/12 -> 7.5 | J7: =I5*$B$1/12 -> 7.5 | K7: =J5*$B$1/12 -> 7.5 | L7: =K5*$B$1/12 -> 7.5 | ... BK7: =BJ5*$B$1/12 -> 65 | BL7: =SUM(E7:BK7) -> 2275
G8: =SUM(E7:G7) -> 22.5 | J8: =SUM(H7:J7) -> 22.5 | M8: =SUM(K7:M7) -> 22.5 | P8: =SUM(N7:P7) -> 22.5 | S8: =SUM(Q7:S7) -> 52.5 | V8: =SUM(T7:V7) -> 52.5 | Y8: =SUM(W7:Y7) -> 52.5 | AB8: =SUM(Z7:AB7) -> 52.5 | AE8: =SUM(AC7:AE7) -> 120 | AH8: =SUM(AF7:AH7) -> 120 | AK8: =SUM(AI7:AK7) -> 120 | AN8: =SUM(AL7:AN7) -> 120 | AQ8: =SUM(AO7:AQ7) -> 195 | AT8: =SUM(AR7:AT7) -> 195 | AW8: =SUM(AU7:AW7) -> 195 | AZ8: =SUM(AX7:AZ7) -> 195 | BC8: =SUM(BA7:BC7) -> 195 | BF8: =SUM(BD7:BF7) -> 195 | BI8: =SUM(BG7:BI7) -> 195 | BK8: =SUM(BJ7:BK7) -> 130 | BL8: =SUM(E8:BK8) -> 2275
O9: =SUM(D8:O8) -> 67.5 | AA9: =SUM(P8:AA8) -> 180 | AM9: =SUM(AB8:AM8) -> 412.5 | AY9: =SUM(AN8:AY8) -> 705 | BK9: =SUM(AZ8:BK8) -> 910 | BL9: =SUM(E9:BK9) -> 2275

Sheet Flujo 5 años C20
D2: Ingresos | E2: Año 0 | F2: Año 1 | G2: Año 2 | H2: Año 3 | I2: Año 4 | J2: Año 5 | K2: Año 6 | L2: Dev. Prest | M2: Dividendo | N2: Total
D3: Arriendos | F3: ='Flujo mensual'!P4 -> 2078.4689 | G3: ='Flujo mensual'!$O$4*12*0.9 -> 2747.4433 | H3: ='Flujo mensual'!$O$4*12*0.9 -> 2747.4433 | I3: ='Flujo mensual'!$O$4*12*0.9 -> 2747.4433 | J3: ='Flujo mensual'!$O$4*12*0.9 -> 2747.4433 | N3: =SUM(F3:M3) -> 13068.242
D4: C. Fiscal Equip. | F4: ='Flujo mensual'!G5 -> 178.79548 | G4: 0 | H4: 0 | I4: 0 | J4: 0 | N4: =SUM(F4:M4) -> 178.79548
D5: C. Fiscal Unidades | F5: ='Flujo mensual'!G6 -> 8157.4414 | G5: 0 | H5: 0 | I5: 0 | J5: 0 | N5: =SUM(F5:M5) -> 8157.4414
D6: Venta propiedades | F6: 0 | G6: 0 | H6: 0 | I6: 0 | J6: ='IVA Dptos'!AD23*0.9 -> 74756.7 | N6: =SUM(F6:M6) -> 74756.7 | P6: Venta sin mayor plusvalía
D7: Total Ingresos | E7: =SUM(E3:E6) -> 0 | F7: =SUM(F3:F6) -> 10414.706 | G7: =SUM(G3:G6) -> 2747.4433 | H7: =SUM(H3:H6) -> 2747.4433 | I7: =SUM(I3:I6) -> 2747.4433 | J7: =SUM(J3:J6) -> 77504.143 | K7: =SUM(K3:K6) -> 0 | L7: =SUM(L3:L6) -> 0 | ... N7: =SUM(N3:N6) -> 96161.179
D9: Egresos | E9: Año 0 | F9: Año 1 | G9: Año 2 | H9: Año 3 | I9: Año 4 | J9: Año 5 | K9: Año 6 | N9: Total
D10: Amoblado | E10: ='Flujo mensual'!C11 -> 941.02886 | F10: 0 | G10: 0 | H10: 0 | I10: 0 | J10: 0 | N10: =SUM(E10:M10) -> 941.02886
D11: Contribuciones | F11: ='Flujo mensual'!$P$12 -> 30.112923 | G11: ='Flujo mensual'!$P$12 -> 30.112923 | H11: ='Flujo mensual'!$P$12 -> 30.112923 | I11: ='Flujo mensual'!$P$12 -> 30.112923 | J11: ='Flujo mensual'!$P$12 -> 30.112923 | N11: =SUM(E11:M11) -> 150.56462
D12: Cuota de alzaminto | E12: ='Crédito Comercial 12A'!D10 -> 0 | N12: =SUM(E12:M12) -> 0
D13: Dividendo | F13: =-'Crédito Comercial 20A'!$H$8*12 -> 4736.2669 | G13: =-'Crédito Comercial 20A'!$H$8*12 -> 4736.2669 | H13: =-'Crédito Comercial 20A'!$H$8*12 -> 4736.2669 | I13: =-'Crédito Comercial 20A'!$H$8*12 -> 4736.2669 | J13: =-'Crédito Comercial 20A'!$H$8*12 -> 4736.2669 | N13: =SUM(E13:M13) -> 23681.334
